2025-06-09 12:23:43 - INFO - [SERVIDOR INFO]: Servidor escuchando en localhost:8083
2025-06-09 12:23:49 - INFO - [SERVIDOR INFO]: Conexión desde ('127.0.0.1', 62598)
2025-06-09 12:23:54 - WARNING - [SERVIDOR WARNING]: == ESPERA AUTOMÁTICA DE 5 SEGUNDOS ==
2025-06-09 12:23:54 - ERROR - Unhandled exception in client_connected_cb
transport: <_ProactorSocketTransport closed>
Traceback (most recent call last):
  File "C:\Program Files\WindowsApps\PythonSoftwareFoundation.Python.3.13_3.13.1008.0_x64__qbz5n2kfra8p0\Lib\asyncio\windows_events.py", line 463, in finish_socket_func
    return ov.getresult()
           ~~~~~~~~~~~~^^
OSError: [WinError 64] El nombre de red especificado ya no está disponible

During handling of the above exception, another exception occurred:

Traceback (most recent call last):
  File "c:\Users\nzjha\Desktop\Clon_Github\python_serve\SERVER\s_asyncrono_v1.py", line 89, in client_communication_server
    await writer.drain()
  File "C:\Program Files\WindowsApps\PythonSoftwareFoundation.Python.3.13_3.13.1008.0_x64__qbz5n2kfra8p0\Lib\asyncio\streams.py", line 374, in drain
    raise exc
  File "C:\Program Files\WindowsApps\PythonSoftwareFoundation.Python.3.13_3.13.1008.0_x64__qbz5n2kfra8p0\Lib\asyncio\proactor_events.py", line 286, in _loop_reading
    length = fut.result()
  File "C:\Program Files\WindowsApps\PythonSoftwareFoundation.Python.3.13_3.13.1008.0_x64__qbz5n2kfra8p0\Lib\asyncio\windows_events.py", line 804, in _poll
    value = callback(transferred, key, ov)
  File "C:\Program Files\WindowsApps\PythonSoftwareFoundation.Python.3.13_3.13.1008.0_x64__qbz5n2kfra8p0\Lib\asyncio\windows_events.py", line 467, in finish_socket_func
    raise ConnectionResetError(*exc.args)
ConnectionResetError: [WinError 64] El nombre de red especificado ya no está disponible
2025-06-09 12:40:11 - INFO - [SERVIDOR INFO]: Servidor escuchando en localhost:8083
2025-06-09 12:40:14 - INFO - [SERVIDOR INFO]: Conexión desde ('127.0.0.1', 63149)
2025-06-09 12:40:19 - WARNING - [SERVIDOR WARNING]: == ESPERA AUTOMÁTICA DE 5 SEGUNDOS ==
2025-06-09 12:40:25 - ERROR - Unhandled exception in client_connected_cb
transport: <_ProactorSocketTransport closed>
Traceback (most recent call last):
  File "C:\Program Files\WindowsApps\PythonSoftwareFoundation.Python.3.13_3.13.1008.0_x64__qbz5n2kfra8p0\Lib\asyncio\windows_events.py", line 463, in finish_socket_func
    return ov.getresult()
           ~~~~~~~~~~~~^^
OSError: [WinError 64] El nombre de red especificado ya no está disponible

During handling of the above exception, another exception occurred:

Traceback (most recent call last):
  File "c:\Users\nzjha\Desktop\Clon_Github\python_serve\SERVER\s_asyncrono_v1.py", line 114, in client_communication_server
    msg = await reader.read(1024)
          ^^^^^^^^^^^^^^^^^^^^^^^
  File "C:\Program Files\WindowsApps\PythonSoftwareFoundation.Python.3.13_3.13.1008.0_x64__qbz5n2kfra8p0\Lib\asyncio\streams.py", line 730, in read
    await self._wait_for_data('read')
  File "C:\Program Files\WindowsApps\PythonSoftwareFoundation.Python.3.13_3.13.1008.0_x64__qbz5n2kfra8p0\Lib\asyncio\streams.py", line 539, in _wait_for_data
    await self._waiter
  File "C:\Program Files\WindowsApps\PythonSoftwareFoundation.Python.3.13_3.13.1008.0_x64__qbz5n2kfra8p0\Lib\asyncio\proactor_events.py", line 286, in _loop_reading
    length = fut.result()
  File "C:\Program Files\WindowsApps\PythonSoftwareFoundation.Python.3.13_3.13.1008.0_x64__qbz5n2kfra8p0\Lib\asyncio\windows_events.py", line 804, in _poll
    value = callback(transferred, key, ov)
  File "C:\Program Files\WindowsApps\PythonSoftwareFoundation.Python.3.13_3.13.1008.0_x64__qbz5n2kfra8p0\Lib\asyncio\windows_events.py", line 467, in finish_socket_func
    raise ConnectionResetError(*exc.args)
ConnectionResetError: [WinError 64] El nombre de red especificado ya no está disponible
2025-06-09 12:40:28 - INFO - [SERVIDOR INFO]: Conexión desde ('127.0.0.1', 63157)
2025-06-09 12:40:33 - WARNING - [SERVIDOR WARNING]: == ESPERA AUTOMÁTICA DE 5 SEGUNDOS ==
2025-06-09 12:40:44 - INFO - [SERVIDOR INFO]: Consultando datos de MongoDB...
2025-06-09 12:40:50 - WARNING - [SERVIDOR WARNING]: Cliente desconectado.
2025-06-09 12:40:50 - INFO - [SERVIDOR INFO]: Conexión desde ('127.0.0.1', 63165)
2025-06-09 12:40:55 - WARNING - [SERVIDOR WARNING]: == ESPERA AUTOMÁTICA DE 5 SEGUNDOS ==
2025-06-09 12:40:55 - WARNING - [SERVIDOR WARNING]: == ESPERA AUTOMÁTICA DE 5 SEGUNDOS ==
2025-06-09 12:40:55 - ERROR - Unhandled exception in client_connected_cb
transport: <_ProactorSocketTransport closed>
Traceback (most recent call last):
  File "c:\Users\nzjha\Desktop\Clon_Github\python_serve\SERVER\s_asyncrono_v1.py", line 113, in client_communication_server
    await writer.drain()
  File "C:\Program Files\WindowsApps\PythonSoftwareFoundation.Python.3.13_3.13.1008.0_x64__qbz5n2kfra8p0\Lib\asyncio\streams.py", line 386, in drain
    await self._protocol._drain_helper()
  File "C:\Program Files\WindowsApps\PythonSoftwareFoundation.Python.3.13_3.13.1008.0_x64__qbz5n2kfra8p0\Lib\asyncio\streams.py", line 166, in _drain_helper
    raise ConnectionResetError('Connection lost')
ConnectionResetError: Connection lost
2025-06-09 12:40:56 - ERROR - Unhandled exception in client_connected_cb
transport: <_ProactorSocketTransport closed>
Traceback (most recent call last):
  File "C:\Program Files\WindowsApps\PythonSoftwareFoundation.Python.3.13_3.13.1008.0_x64__qbz5n2kfra8p0\Lib\asyncio\windows_events.py", line 463, in finish_socket_func
    return ov.getresult()
           ~~~~~~~~~~~~^^
OSError: [WinError 64] El nombre de red especificado ya no está disponible

During handling of the above exception, another exception occurred:

Traceback (most recent call last):
  File "c:\Users\nzjha\Desktop\Clon_Github\python_serve\SERVER\s_asyncrono_v1.py", line 114, in client_communication_server
    msg = await reader.read(1024)
          ^^^^^^^^^^^^^^^^^^^^^^^
  File "C:\Program Files\WindowsApps\PythonSoftwareFoundation.Python.3.13_3.13.1008.0_x64__qbz5n2kfra8p0\Lib\asyncio\streams.py", line 730, in read
    await self._wait_for_data('read')
  File "C:\Program Files\WindowsApps\PythonSoftwareFoundation.Python.3.13_3.13.1008.0_x64__qbz5n2kfra8p0\Lib\asyncio\streams.py", line 539, in _wait_for_data
    await self._waiter
  File "C:\Program Files\WindowsApps\PythonSoftwareFoundation.Python.3.13_3.13.1008.0_x64__qbz5n2kfra8p0\Lib\asyncio\proactor_events.py", line 286, in _loop_reading
    length = fut.result()
  File "C:\Program Files\WindowsApps\PythonSoftwareFoundation.Python.3.13_3.13.1008.0_x64__qbz5n2kfra8p0\Lib\asyncio\windows_events.py", line 804, in _poll
    value = callback(transferred, key, ov)
  File "C:\Program Files\WindowsApps\PythonSoftwareFoundation.Python.3.13_3.13.1008.0_x64__qbz5n2kfra8p0\Lib\asyncio\windows_events.py", line 467, in finish_socket_func
    raise ConnectionResetError(*exc.args)
ConnectionResetError: [WinError 64] El nombre de red especificado ya no está disponible
