2025-06-09 12:23:43 - INFO - [SERVIDOR INFO]: Servidor escuchando en localhost:8083
2025-06-09 12:23:49 - INFO - [SERVIDOR INFO]: Conexión desde ('127.0.0.1', 62598)
2025-06-09 12:23:54 - WARNING - [SERVIDOR WARNING]: == ESPERA AUTOMÁTICA DE 5 SEGUNDOS ==
2025-06-09 12:23:54 - ERROR - Unhandled exception in client_connected_cb
transport: <_ProactorSocketTransport closed>
Traceback (most recent call last):
  File "C:\Program Files\WindowsApps\PythonSoftwareFoundation.Python.3.13_3.13.1008.0_x64__qbz5n2kfra8p0\Lib\asyncio\windows_events.py", line 463, in finish_socket_func
    return ov.getresult()
           ~~~~~~~~~~~~^^
OSError: [WinError 64] El nombre de red especificado ya no está disponible

During handling of the above exception, another exception occurred:

Traceback (most recent call last):
  File "c:\Users\nzjha\Desktop\Clon_Github\python_serve\SERVER\s_asyncrono_v1.py", line 89, in client_communication_server
    await writer.drain()
  File "C:\Program Files\WindowsApps\PythonSoftwareFoundation.Python.3.13_3.13.1008.0_x64__qbz5n2kfra8p0\Lib\asyncio\streams.py", line 374, in drain
    raise exc
  File "C:\Program Files\WindowsApps\PythonSoftwareFoundation.Python.3.13_3.13.1008.0_x64__qbz5n2kfra8p0\Lib\asyncio\proactor_events.py", line 286, in _loop_reading
    length = fut.result()
  File "C:\Program Files\WindowsApps\PythonSoftwareFoundation.Python.3.13_3.13.1008.0_x64__qbz5n2kfra8p0\Lib\asyncio\windows_events.py", line 804, in _poll
    value = callback(transferred, key, ov)
  File "C:\Program Files\WindowsApps\PythonSoftwareFoundation.Python.3.13_3.13.1008.0_x64__qbz5n2kfra8p0\Lib\asyncio\windows_events.py", line 467, in finish_socket_func
    raise ConnectionResetError(*exc.args)
ConnectionResetError: [WinError 64] El nombre de red especificado ya no está disponible
2025-06-09 12:40:11 - INFO - [SERVIDOR INFO]: Servidor escuchando en localhost:8083
2025-06-09 12:40:14 - INFO - [SERVIDOR INFO]: Conexión desde ('127.0.0.1', 63149)
2025-06-09 12:40:19 - WARNING - [SERVIDOR WARNING]: == ESPERA AUTOMÁTICA DE 5 SEGUNDOS ==
2025-06-09 12:40:25 - ERROR - Unhandled exception in client_connected_cb
transport: <_ProactorSocketTransport closed>
Traceback (most recent call last):
  File "C:\Program Files\WindowsApps\PythonSoftwareFoundation.Python.3.13_3.13.1008.0_x64__qbz5n2kfra8p0\Lib\asyncio\windows_events.py", line 463, in finish_socket_func
    return ov.getresult()
           ~~~~~~~~~~~~^^
OSError: [WinError 64] El nombre de red especificado ya no está disponible

During handling of the above exception, another exception occurred:

Traceback (most recent call last):
  File "c:\Users\nzjha\Desktop\Clon_Github\python_serve\SERVER\s_asyncrono_v1.py", line 114, in client_communication_server
    msg = await reader.read(1024)
          ^^^^^^^^^^^^^^^^^^^^^^^
  File "C:\Program Files\WindowsApps\PythonSoftwareFoundation.Python.3.13_3.13.1008.0_x64__qbz5n2kfra8p0\Lib\asyncio\streams.py", line 730, in read
    await self._wait_for_data('read')
  File "C:\Program Files\WindowsApps\PythonSoftwareFoundation.Python.3.13_3.13.1008.0_x64__qbz5n2kfra8p0\Lib\asyncio\streams.py", line 539, in _wait_for_data
    await self._waiter
  File "C:\Program Files\WindowsApps\PythonSoftwareFoundation.Python.3.13_3.13.1008.0_x64__qbz5n2kfra8p0\Lib\asyncio\proactor_events.py", line 286, in _loop_reading
    length = fut.result()
  File "C:\Program Files\WindowsApps\PythonSoftwareFoundation.Python.3.13_3.13.1008.0_x64__qbz5n2kfra8p0\Lib\asyncio\windows_events.py", line 804, in _poll
    value = callback(transferred, key, ov)
  File "C:\Program Files\WindowsApps\PythonSoftwareFoundation.Python.3.13_3.13.1008.0_x64__qbz5n2kfra8p0\Lib\asyncio\windows_events.py", line 467, in finish_socket_func
    raise ConnectionResetError(*exc.args)
ConnectionResetError: [WinError 64] El nombre de red especificado ya no está disponible
2025-06-09 12:40:28 - INFO - [SERVIDOR INFO]: Conexión desde ('127.0.0.1', 63157)
2025-06-09 12:40:33 - WARNING - [SERVIDOR WARNING]: == ESPERA AUTOMÁTICA DE 5 SEGUNDOS ==
2025-06-09 12:40:44 - INFO - [SERVIDOR INFO]: Consultando datos de MongoDB...
2025-06-09 12:40:50 - WARNING - [SERVIDOR WARNING]: Cliente desconectado.
2025-06-09 12:40:50 - INFO - [SERVIDOR INFO]: Conexión desde ('127.0.0.1', 63165)
2025-06-09 12:40:55 - WARNING - [SERVIDOR WARNING]: == ESPERA AUTOMÁTICA DE 5 SEGUNDOS ==
2025-06-09 12:40:55 - WARNING - [SERVIDOR WARNING]: == ESPERA AUTOMÁTICA DE 5 SEGUNDOS ==
2025-06-09 12:40:55 - ERROR - Unhandled exception in client_connected_cb
transport: <_ProactorSocketTransport closed>
Traceback (most recent call last):
  File "c:\Users\nzjha\Desktop\Clon_Github\python_serve\SERVER\s_asyncrono_v1.py", line 113, in client_communication_server
    await writer.drain()
  File "C:\Program Files\WindowsApps\PythonSoftwareFoundation.Python.3.13_3.13.1008.0_x64__qbz5n2kfra8p0\Lib\asyncio\streams.py", line 386, in drain
    await self._protocol._drain_helper()
  File "C:\Program Files\WindowsApps\PythonSoftwareFoundation.Python.3.13_3.13.1008.0_x64__qbz5n2kfra8p0\Lib\asyncio\streams.py", line 166, in _drain_helper
    raise ConnectionResetError('Connection lost')
ConnectionResetError: Connection lost
2025-06-09 12:40:56 - ERROR - Unhandled exception in client_connected_cb
transport: <_ProactorSocketTransport closed>
Traceback (most recent call last):
  File "C:\Program Files\WindowsApps\PythonSoftwareFoundation.Python.3.13_3.13.1008.0_x64__qbz5n2kfra8p0\Lib\asyncio\windows_events.py", line 463, in finish_socket_func
    return ov.getresult()
           ~~~~~~~~~~~~^^
OSError: [WinError 64] El nombre de red especificado ya no está disponible

During handling of the above exception, another exception occurred:

Traceback (most recent call last):
  File "c:\Users\nzjha\Desktop\Clon_Github\python_serve\SERVER\s_asyncrono_v1.py", line 114, in client_communication_server
    msg = await reader.read(1024)
          ^^^^^^^^^^^^^^^^^^^^^^^
  File "C:\Program Files\WindowsApps\PythonSoftwareFoundation.Python.3.13_3.13.1008.0_x64__qbz5n2kfra8p0\Lib\asyncio\streams.py", line 730, in read
    await self._wait_for_data('read')
  File "C:\Program Files\WindowsApps\PythonSoftwareFoundation.Python.3.13_3.13.1008.0_x64__qbz5n2kfra8p0\Lib\asyncio\streams.py", line 539, in _wait_for_data
    await self._waiter
  File "C:\Program Files\WindowsApps\PythonSoftwareFoundation.Python.3.13_3.13.1008.0_x64__qbz5n2kfra8p0\Lib\asyncio\proactor_events.py", line 286, in _loop_reading
    length = fut.result()
  File "C:\Program Files\WindowsApps\PythonSoftwareFoundation.Python.3.13_3.13.1008.0_x64__qbz5n2kfra8p0\Lib\asyncio\windows_events.py", line 804, in _poll
    value = callback(transferred, key, ov)
  File "C:\Program Files\WindowsApps\PythonSoftwareFoundation.Python.3.13_3.13.1008.0_x64__qbz5n2kfra8p0\Lib\asyncio\windows_events.py", line 467, in finish_socket_func
    raise ConnectionResetError(*exc.args)
ConnectionResetError: [WinError 64] El nombre de red especificado ya no está disponible
2025-06-09 12:48:20 - INFO - [SERVIDOR INFO]: Servidor escuchando en localhost:8083
2025-06-09 12:48:21 - INFO - [SERVIDOR INFO]: Conexión desde ('127.0.0.1', 63391)
2025-06-09 12:48:26 - WARNING - [SERVIDOR WARNING]: == ESPERA AUTOMÁTICA DE 5 SEGUNDOS ==
2025-06-09 12:48:35 - INFO - [SERVIDOR INFO]: Consultando datos de MongoDB...
2025-06-09 12:48:42 - INFO - [SERVIDOR INFO]: Consultando datos de la colección 'Personajes' en MongoDB...
2025-06-09 12:48:47 - WARNING - [SERVIDOR WARNING]: == ESPERA AUTOMÁTICA DE 5 SEGUNDOS ==
2025-06-09 12:48:47 - ERROR - Unhandled exception in client_connected_cb
transport: <_ProactorSocketTransport closed>
Traceback (most recent call last):
  File "C:\Program Files\WindowsApps\PythonSoftwareFoundation.Python.3.13_3.13.1008.0_x64__qbz5n2kfra8p0\Lib\asyncio\windows_events.py", line 463, in finish_socket_func
    return ov.getresult()
           ~~~~~~~~~~~~^^
OSError: [WinError 64] El nombre de red especificado ya no está disponible

During handling of the above exception, another exception occurred:

Traceback (most recent call last):
  File "c:\Users\nzjha\Desktop\Clon_Github\python_serve\SERVER\s_asyncrono_v1.py", line 111, in client_communication_server
    await writer.drain()
  File "C:\Program Files\WindowsApps\PythonSoftwareFoundation.Python.3.13_3.13.1008.0_x64__qbz5n2kfra8p0\Lib\asyncio\streams.py", line 374, in drain
    raise exc
  File "C:\Program Files\WindowsApps\PythonSoftwareFoundation.Python.3.13_3.13.1008.0_x64__qbz5n2kfra8p0\Lib\asyncio\proactor_events.py", line 286, in _loop_reading
    length = fut.result()
  File "C:\Program Files\WindowsApps\PythonSoftwareFoundation.Python.3.13_3.13.1008.0_x64__qbz5n2kfra8p0\Lib\asyncio\windows_events.py", line 804, in _poll
    value = callback(transferred, key, ov)
  File "C:\Program Files\WindowsApps\PythonSoftwareFoundation.Python.3.13_3.13.1008.0_x64__qbz5n2kfra8p0\Lib\asyncio\windows_events.py", line 467, in finish_socket_func
    raise ConnectionResetError(*exc.args)
ConnectionResetError: [WinError 64] El nombre de red especificado ya no está disponible
2025-06-09 12:56:19 - INFO - [SERVIDOR INFO]: Servidor escuchando en localhost:8083
2025-06-09 12:56:54 - INFO - [SERVIDOR INFO]: Conexión desde ('127.0.0.1', 63646)
2025-06-09 12:56:59 - WARNING - [SERVIDOR WARNING]: == ESPERA AUTOMÁTICA DE 5 SEGUNDOS ==
2025-06-09 12:57:02 - INFO - [SERVIDOR INFO]: Consultando datos de MongoDB...
2025-06-09 12:57:07 - INFO - [SERVIDOR INFO]: Consultando datos de la colección 'Personajes' en MongoDB...
2025-06-09 12:57:14 - INFO - [SERVIDOR INFO]: Conexión desde ('127.0.0.1', 63652)
2025-06-09 12:57:14 - ERROR - Unhandled exception in client_connected_cb
transport: <_ProactorSocketTransport closed>
Traceback (most recent call last):
  File "c:\Users\nzjha\Desktop\Clon_Github\python_serve\SERVER\s_asyncrono_v1.py", line 130, in client_communication_server
    await consultas_MDB(writer, reader)
  File "c:\Users\nzjha\Desktop\Clon_Github\python_serve\SERVER\s_asyncrono_v1.py", line 92, in consultas_MDB
    await collection_MDB_4(writer, reader)
  File "c:\Users\nzjha\Desktop\Clon_Github\python_serve\SERVER\s_asyncrono_v1.py", line 62, in collection_MDB_4
    await writer.drain()
  File "C:\Program Files\WindowsApps\PythonSoftwareFoundation.Python.3.13_3.13.1008.0_x64__qbz5n2kfra8p0\Lib\asyncio\streams.py", line 386, in drain
    await self._protocol._drain_helper()
  File "C:\Program Files\WindowsApps\PythonSoftwareFoundation.Python.3.13_3.13.1008.0_x64__qbz5n2kfra8p0\Lib\asyncio\streams.py", line 172, in _drain_helper
    await waiter
  File "C:\Program Files\WindowsApps\PythonSoftwareFoundation.Python.3.13_3.13.1008.0_x64__qbz5n2kfra8p0\Lib\asyncio\proactor_events.py", line 402, in _loop_writing
    self._write_fut = self._loop._proactor.send(self._sock, data)
                      ~~~~~~~~~~~~~~~~~~~~~~~~~^^^^^^^^^^^^^^^^^^
  File "C:\Program Files\WindowsApps\PythonSoftwareFoundation.Python.3.13_3.13.1008.0_x64__qbz5n2kfra8p0\Lib\asyncio\windows_events.py", line 543, in send
    ov.WSASend(conn.fileno(), buf, flags)
    ~~~~~~~~~~^^^^^^^^^^^^^^^^^^^^^^^^^^^
ConnectionAbortedError: [WinError 10053] Se ha anulado una conexión establecida por el software en su equipo host
2025-06-09 12:57:19 - WARNING - [SERVIDOR WARNING]: == ESPERA AUTOMÁTICA DE 5 SEGUNDOS ==
2025-06-09 12:57:23 - ERROR - Unhandled exception in client_connected_cb
transport: <_ProactorSocketTransport closed>
Traceback (most recent call last):
  File "C:\Program Files\WindowsApps\PythonSoftwareFoundation.Python.3.13_3.13.1008.0_x64__qbz5n2kfra8p0\Lib\asyncio\windows_events.py", line 463, in finish_socket_func
    return ov.getresult()
           ~~~~~~~~~~~~^^
OSError: [WinError 64] El nombre de red especificado ya no está disponible

During handling of the above exception, another exception occurred:

Traceback (most recent call last):
  File "c:\Users\nzjha\Desktop\Clon_Github\python_serve\SERVER\s_asyncrono_v1.py", line 118, in client_communication_server
    msg = await reader.read(1024)
          ^^^^^^^^^^^^^^^^^^^^^^^
  File "C:\Program Files\WindowsApps\PythonSoftwareFoundation.Python.3.13_3.13.1008.0_x64__qbz5n2kfra8p0\Lib\asyncio\streams.py", line 730, in read
    await self._wait_for_data('read')
  File "C:\Program Files\WindowsApps\PythonSoftwareFoundation.Python.3.13_3.13.1008.0_x64__qbz5n2kfra8p0\Lib\asyncio\streams.py", line 539, in _wait_for_data
    await self._waiter
  File "C:\Program Files\WindowsApps\PythonSoftwareFoundation.Python.3.13_3.13.1008.0_x64__qbz5n2kfra8p0\Lib\asyncio\proactor_events.py", line 286, in _loop_reading
    length = fut.result()
  File "C:\Program Files\WindowsApps\PythonSoftwareFoundation.Python.3.13_3.13.1008.0_x64__qbz5n2kfra8p0\Lib\asyncio\windows_events.py", line 804, in _poll
    value = callback(transferred, key, ov)
  File "C:\Program Files\WindowsApps\PythonSoftwareFoundation.Python.3.13_3.13.1008.0_x64__qbz5n2kfra8p0\Lib\asyncio\windows_events.py", line 467, in finish_socket_func
    raise ConnectionResetError(*exc.args)
ConnectionResetError: [WinError 64] El nombre de red especificado ya no está disponible
