2025-06-11 11:22:46 - ERROR - [SERVIDOR ERROR]: Error al iniciar el servidor: cannot access local variable 'server' where it is not associated with a value
2025-06-11 11:22:46 - CRITICAL - [SERVIDOR CRITICAL]: Servidor cerrado.
2025-06-11 11:23:09 - INFO - [SERVIDOR INFO]: Servidor escuchando en localhost:8083
2025-06-11 11:23:13 - INFO - [SERVIDOR INFO]: Conexión establecida desde ('127.0.0.1', 58155)
2025-06-11 11:23:14 - WARNING - [SERVIDOR WARNING]: == ESPERA AUTOMÁTICA DE O.1 SEGUNDOS ==
2025-06-11 11:23:55 - ERROR - Unhandled exception in client_connected_cb
transport: <_ProactorSocketTransport closed>
Traceback (most recent call last):
  File "C:\Program Files\WindowsApps\PythonSoftwareFoundation.Python.3.13_3.13.1008.0_x64__qbz5n2kfra8p0\Lib\asyncio\windows_events.py", line 463, in finish_socket_func
    return ov.getresult()
           ~~~~~~~~~~~~^^
OSError: [WinError 64] El nombre de red especificado ya no está disponible

During handling of the above exception, another exception occurred:

Traceback (most recent call last):
  File "c:\Users\nzjha\Desktop\Clon_Github\python_serve\Async\Server.py", line 210, in server
    data = await reader.readline()
           ^^^^^^^^^^^^^^^^^^^^^^^
  File "C:\Program Files\WindowsApps\PythonSoftwareFoundation.Python.3.13_3.13.1008.0_x64__qbz5n2kfra8p0\Lib\asyncio\streams.py", line 562, in readline
    line = await self.readuntil(sep)
           ^^^^^^^^^^^^^^^^^^^^^^^^^
  File "C:\Program Files\WindowsApps\PythonSoftwareFoundation.Python.3.13_3.13.1008.0_x64__qbz5n2kfra8p0\Lib\asyncio\streams.py", line 677, in readuntil
    await self._wait_for_data('readuntil')
  File "C:\Program Files\WindowsApps\PythonSoftwareFoundation.Python.3.13_3.13.1008.0_x64__qbz5n2kfra8p0\Lib\asyncio\streams.py", line 539, in _wait_for_data
    await self._waiter
  File "C:\Program Files\WindowsApps\PythonSoftwareFoundation.Python.3.13_3.13.1008.0_x64__qbz5n2kfra8p0\Lib\asyncio\proactor_events.py", line 286, in _loop_reading
    length = fut.result()
  File "C:\Program Files\WindowsApps\PythonSoftwareFoundation.Python.3.13_3.13.1008.0_x64__qbz5n2kfra8p0\Lib\asyncio\windows_events.py", line 804, in _poll
    value = callback(transferred, key, ov)
  File "C:\Program Files\WindowsApps\PythonSoftwareFoundation.Python.3.13_3.13.1008.0_x64__qbz5n2kfra8p0\Lib\asyncio\windows_events.py", line 467, in finish_socket_func
    raise ConnectionResetError(*exc.args)
ConnectionResetError: [WinError 64] El nombre de red especificado ya no está disponible
2025-06-11 11:24:10 - INFO - [SERVIDOR INFO]: Servidor escuchando en localhost:8083
2025-06-11 11:24:10 - INFO - [SERVIDOR INFO]: Conexión establecida desde ('127.0.0.1', 58172)
2025-06-11 11:24:16 - WARNING - [SERVIDOR WARNING]: == ESPERA AUTOMÁTICA DE 5 SEGUNDOS ==
2025-06-11 11:25:41 - INFO - [SERVIDOR INFO]: Servidor escuchando en localhost:8083
2025-06-11 11:25:42 - INFO - [SERVIDOR INFO]: Conexión establecida desde ('127.0.0.1', 58210)
2025-06-11 11:25:47 - WARNING - [SERVIDOR WARNING]: == ESPERA AUTOMÁTICA DE 5 SEGUNDOS ==
2025-06-11 11:27:48 - ERROR - Unhandled exception in client_connected_cb
transport: <_ProactorSocketTransport closed>
Traceback (most recent call last):
  File "C:\Program Files\WindowsApps\PythonSoftwareFoundation.Python.3.13_3.13.1008.0_x64__qbz5n2kfra8p0\Lib\asyncio\windows_events.py", line 463, in finish_socket_func
    return ov.getresult()
           ~~~~~~~~~~~~^^
OSError: [WinError 64] El nombre de red especificado ya no está disponible

During handling of the above exception, another exception occurred:

Traceback (most recent call last):
  File "c:\Users\nzjha\Desktop\Clon_Github\python_serve\Async\Server.py", line 210, in server
    message = (await reader.readline()).decode().strip()
               ^^^^^^^^^^^^^^^^^^^^^^^
  File "C:\Program Files\WindowsApps\PythonSoftwareFoundation.Python.3.13_3.13.1008.0_x64__qbz5n2kfra8p0\Lib\asyncio\streams.py", line 562, in readline
    line = await self.readuntil(sep)
           ^^^^^^^^^^^^^^^^^^^^^^^^^
  File "C:\Program Files\WindowsApps\PythonSoftwareFoundation.Python.3.13_3.13.1008.0_x64__qbz5n2kfra8p0\Lib\asyncio\streams.py", line 677, in readuntil
    await self._wait_for_data('readuntil')
  File "C:\Program Files\WindowsApps\PythonSoftwareFoundation.Python.3.13_3.13.1008.0_x64__qbz5n2kfra8p0\Lib\asyncio\streams.py", line 539, in _wait_for_data
    await self._waiter
  File "C:\Program Files\WindowsApps\PythonSoftwareFoundation.Python.3.13_3.13.1008.0_x64__qbz5n2kfra8p0\Lib\asyncio\proactor_events.py", line 286, in _loop_reading
    length = fut.result()
  File "C:\Program Files\WindowsApps\PythonSoftwareFoundation.Python.3.13_3.13.1008.0_x64__qbz5n2kfra8p0\Lib\asyncio\windows_events.py", line 804, in _poll
    value = callback(transferred, key, ov)
  File "C:\Program Files\WindowsApps\PythonSoftwareFoundation.Python.3.13_3.13.1008.0_x64__qbz5n2kfra8p0\Lib\asyncio\windows_events.py", line 467, in finish_socket_func
    raise ConnectionResetError(*exc.args)
ConnectionResetError: [WinError 64] El nombre de red especificado ya no está disponible
2025-06-11 11:30:41 - INFO - [SERVIDOR INFO]: Servidor escuchando en localhost:8083
2025-06-11 11:30:42 - INFO - [SERVIDOR INFO]: Conexión establecida desde ('127.0.0.1', 58293)
2025-06-11 11:30:47 - WARNING - [SERVIDOR WARNING]: == ESPERA AUTOMÁTICA DE 5 SEGUNDOS ==
2025-06-11 11:31:46 - ERROR - Unhandled exception in client_connected_cb
transport: <_ProactorSocketTransport closed>
Traceback (most recent call last):
  File "C:\Program Files\WindowsApps\PythonSoftwareFoundation.Python.3.13_3.13.1008.0_x64__qbz5n2kfra8p0\Lib\asyncio\windows_events.py", line 463, in finish_socket_func
    return ov.getresult()
           ~~~~~~~~~~~~^^
OSError: [WinError 64] El nombre de red especificado ya no está disponible

During handling of the above exception, another exception occurred:

Traceback (most recent call last):
  File "c:\Users\nzjha\Desktop\Clon_Github\python_serve\Async\Server.py", line 210, in server
    message = (await reader.readline()).decode().strip()
               ^^^^^^^^^^^^^^^^^^^^^^^
  File "C:\Program Files\WindowsApps\PythonSoftwareFoundation.Python.3.13_3.13.1008.0_x64__qbz5n2kfra8p0\Lib\asyncio\streams.py", line 562, in readline
    line = await self.readuntil(sep)
           ^^^^^^^^^^^^^^^^^^^^^^^^^
  File "C:\Program Files\WindowsApps\PythonSoftwareFoundation.Python.3.13_3.13.1008.0_x64__qbz5n2kfra8p0\Lib\asyncio\streams.py", line 677, in readuntil
    await self._wait_for_data('readuntil')
  File "C:\Program Files\WindowsApps\PythonSoftwareFoundation.Python.3.13_3.13.1008.0_x64__qbz5n2kfra8p0\Lib\asyncio\streams.py", line 539, in _wait_for_data
    await self._waiter
  File "C:\Program Files\WindowsApps\PythonSoftwareFoundation.Python.3.13_3.13.1008.0_x64__qbz5n2kfra8p0\Lib\asyncio\proactor_events.py", line 286, in _loop_reading
    length = fut.result()
  File "C:\Program Files\WindowsApps\PythonSoftwareFoundation.Python.3.13_3.13.1008.0_x64__qbz5n2kfra8p0\Lib\asyncio\windows_events.py", line 804, in _poll
    value = callback(transferred, key, ov)
  File "C:\Program Files\WindowsApps\PythonSoftwareFoundation.Python.3.13_3.13.1008.0_x64__qbz5n2kfra8p0\Lib\asyncio\windows_events.py", line 467, in finish_socket_func
    raise ConnectionResetError(*exc.args)
ConnectionResetError: [WinError 64] El nombre de red especificado ya no está disponible
2025-06-11 11:33:24 - INFO - [SERVIDOR INFO]: Servidor escuchando en localhost:8083
2025-06-11 11:33:32 - INFO - [SERVIDOR INFO]: Conexión establecida desde ('127.0.0.1', 58331)
2025-06-11 11:33:37 - WARNING - [SERVIDOR WARNING]: == ESPERA AUTOMÁTICA DE 5 SEGUNDOS ==
2025-06-11 11:34:32 - ERROR - Unhandled exception in client_connected_cb
transport: <_ProactorSocketTransport closed>
Traceback (most recent call last):
  File "C:\Program Files\WindowsApps\PythonSoftwareFoundation.Python.3.13_3.13.1008.0_x64__qbz5n2kfra8p0\Lib\asyncio\windows_events.py", line 463, in finish_socket_func
    return ov.getresult()
           ~~~~~~~~~~~~^^
OSError: [WinError 64] El nombre de red especificado ya no está disponible

During handling of the above exception, another exception occurred:

Traceback (most recent call last):
  File "c:\Users\nzjha\Desktop\Clon_Github\python_serve\Async\Server.py", line 210, in server
    message = (await reader.readline()).decode().strip()
               ^^^^^^^^^^^^^^^^^^^^^^^
  File "C:\Program Files\WindowsApps\PythonSoftwareFoundation.Python.3.13_3.13.1008.0_x64__qbz5n2kfra8p0\Lib\asyncio\streams.py", line 562, in readline
    line = await self.readuntil(sep)
           ^^^^^^^^^^^^^^^^^^^^^^^^^
  File "C:\Program Files\WindowsApps\PythonSoftwareFoundation.Python.3.13_3.13.1008.0_x64__qbz5n2kfra8p0\Lib\asyncio\streams.py", line 677, in readuntil
    await self._wait_for_data('readuntil')
  File "C:\Program Files\WindowsApps\PythonSoftwareFoundation.Python.3.13_3.13.1008.0_x64__qbz5n2kfra8p0\Lib\asyncio\streams.py", line 539, in _wait_for_data
    await self._waiter
  File "C:\Program Files\WindowsApps\PythonSoftwareFoundation.Python.3.13_3.13.1008.0_x64__qbz5n2kfra8p0\Lib\asyncio\proactor_events.py", line 286, in _loop_reading
    length = fut.result()
  File "C:\Program Files\WindowsApps\PythonSoftwareFoundation.Python.3.13_3.13.1008.0_x64__qbz5n2kfra8p0\Lib\asyncio\windows_events.py", line 804, in _poll
    value = callback(transferred, key, ov)
  File "C:\Program Files\WindowsApps\PythonSoftwareFoundation.Python.3.13_3.13.1008.0_x64__qbz5n2kfra8p0\Lib\asyncio\windows_events.py", line 467, in finish_socket_func
    raise ConnectionResetError(*exc.args)
ConnectionResetError: [WinError 64] El nombre de red especificado ya no está disponible
2025-06-11 11:35:15 - INFO - [SERVIDOR INFO]: Servidor escuchando en localhost:8083
2025-06-11 11:35:16 - INFO - [SERVIDOR INFO]: Conexión establecida desde ('127.0.0.1', 58360)
2025-06-11 11:35:51 - ERROR - Unhandled exception in client_connected_cb
transport: <_ProactorSocketTransport closed>
Traceback (most recent call last):
  File "C:\Program Files\WindowsApps\PythonSoftwareFoundation.Python.3.13_3.13.1008.0_x64__qbz5n2kfra8p0\Lib\asyncio\windows_events.py", line 463, in finish_socket_func
    return ov.getresult()
           ~~~~~~~~~~~~^^
OSError: [WinError 64] El nombre de red especificado ya no está disponible

During handling of the above exception, another exception occurred:

Traceback (most recent call last):
  File "c:\Users\nzjha\Desktop\Clon_Github\python_serve\Async\d.py", line 127, in server
    (await reader.readline())  # Espera ENTER
     ^^^^^^^^^^^^^^^^^^^^^^^
  File "C:\Program Files\WindowsApps\PythonSoftwareFoundation.Python.3.13_3.13.1008.0_x64__qbz5n2kfra8p0\Lib\asyncio\streams.py", line 562, in readline
    line = await self.readuntil(sep)
           ^^^^^^^^^^^^^^^^^^^^^^^^^
  File "C:\Program Files\WindowsApps\PythonSoftwareFoundation.Python.3.13_3.13.1008.0_x64__qbz5n2kfra8p0\Lib\asyncio\streams.py", line 677, in readuntil
    await self._wait_for_data('readuntil')
  File "C:\Program Files\WindowsApps\PythonSoftwareFoundation.Python.3.13_3.13.1008.0_x64__qbz5n2kfra8p0\Lib\asyncio\streams.py", line 539, in _wait_for_data
    await self._waiter
  File "C:\Program Files\WindowsApps\PythonSoftwareFoundation.Python.3.13_3.13.1008.0_x64__qbz5n2kfra8p0\Lib\asyncio\proactor_events.py", line 286, in _loop_reading
    length = fut.result()
  File "C:\Program Files\WindowsApps\PythonSoftwareFoundation.Python.3.13_3.13.1008.0_x64__qbz5n2kfra8p0\Lib\asyncio\windows_events.py", line 804, in _poll
    value = callback(transferred, key, ov)
  File "C:\Program Files\WindowsApps\PythonSoftwareFoundation.Python.3.13_3.13.1008.0_x64__qbz5n2kfra8p0\Lib\asyncio\windows_events.py", line 467, in finish_socket_func
    raise ConnectionResetError(*exc.args)
ConnectionResetError: [WinError 64] El nombre de red especificado ya no está disponible
2025-06-11 11:36:02 - INFO - [SERVIDOR INFO]: Servidor escuchando en localhost:8083
2025-06-11 11:36:12 - INFO - [SERVIDOR INFO]: Conexión establecida desde ('127.0.0.1', 58422)
2025-06-11 11:36:34 - ERROR - Unhandled exception in client_connected_cb
transport: <_ProactorSocketTransport closed>
Traceback (most recent call last):
  File "C:\Program Files\WindowsApps\PythonSoftwareFoundation.Python.3.13_3.13.1008.0_x64__qbz5n2kfra8p0\Lib\asyncio\windows_events.py", line 463, in finish_socket_func
    return ov.getresult()
           ~~~~~~~~~~~~^^
OSError: [WinError 64] El nombre de red especificado ya no está disponible

During handling of the above exception, another exception occurred:

Traceback (most recent call last):
  File "c:\Users\nzjha\Desktop\Clon_Github\python_serve\Async\d.py", line 127, in server
    (await reader.readline())  # Espera ENTER
     ^^^^^^^^^^^^^^^^^^^^^^^
  File "C:\Program Files\WindowsApps\PythonSoftwareFoundation.Python.3.13_3.13.1008.0_x64__qbz5n2kfra8p0\Lib\asyncio\streams.py", line 562, in readline
    line = await self.readuntil(sep)
           ^^^^^^^^^^^^^^^^^^^^^^^^^
  File "C:\Program Files\WindowsApps\PythonSoftwareFoundation.Python.3.13_3.13.1008.0_x64__qbz5n2kfra8p0\Lib\asyncio\streams.py", line 677, in readuntil
    await self._wait_for_data('readuntil')
  File "C:\Program Files\WindowsApps\PythonSoftwareFoundation.Python.3.13_3.13.1008.0_x64__qbz5n2kfra8p0\Lib\asyncio\streams.py", line 539, in _wait_for_data
    await self._waiter
  File "C:\Program Files\WindowsApps\PythonSoftwareFoundation.Python.3.13_3.13.1008.0_x64__qbz5n2kfra8p0\Lib\asyncio\proactor_events.py", line 286, in _loop_reading
    length = fut.result()
  File "C:\Program Files\WindowsApps\PythonSoftwareFoundation.Python.3.13_3.13.1008.0_x64__qbz5n2kfra8p0\Lib\asyncio\windows_events.py", line 804, in _poll
    value = callback(transferred, key, ov)
  File "C:\Program Files\WindowsApps\PythonSoftwareFoundation.Python.3.13_3.13.1008.0_x64__qbz5n2kfra8p0\Lib\asyncio\windows_events.py", line 467, in finish_socket_func
    raise ConnectionResetError(*exc.args)
ConnectionResetError: [WinError 64] El nombre de red especificado ya no está disponible
2025-06-11 11:36:54 - INFO - [SERVIDOR INFO]: Servidor escuchando en localhost:8083
2025-06-11 11:36:58 - INFO - [SERVIDOR INFO]: Conexión establecida desde ('127.0.0.1', 58437)
2025-06-11 11:38:17 - ERROR - Unhandled exception in client_connected_cb
transport: <_ProactorSocketTransport closed>
Traceback (most recent call last):
  File "C:\Program Files\WindowsApps\PythonSoftwareFoundation.Python.3.13_3.13.1008.0_x64__qbz5n2kfra8p0\Lib\asyncio\windows_events.py", line 463, in finish_socket_func
    return ov.getresult()
           ~~~~~~~~~~~~^^
OSError: [WinError 64] El nombre de red especificado ya no está disponible

During handling of the above exception, another exception occurred:

Traceback (most recent call last):
  File "c:\Users\nzjha\Desktop\Clon_Github\python_serve\Async\d.py", line 133, in server
    message = (await reader.readline()).decode().strip()
               ^^^^^^^^^^^^^^^^^^^^^^^
  File "C:\Program Files\WindowsApps\PythonSoftwareFoundation.Python.3.13_3.13.1008.0_x64__qbz5n2kfra8p0\Lib\asyncio\streams.py", line 562, in readline
    line = await self.readuntil(sep)
           ^^^^^^^^^^^^^^^^^^^^^^^^^
  File "C:\Program Files\WindowsApps\PythonSoftwareFoundation.Python.3.13_3.13.1008.0_x64__qbz5n2kfra8p0\Lib\asyncio\streams.py", line 677, in readuntil
    await self._wait_for_data('readuntil')
  File "C:\Program Files\WindowsApps\PythonSoftwareFoundation.Python.3.13_3.13.1008.0_x64__qbz5n2kfra8p0\Lib\asyncio\streams.py", line 539, in _wait_for_data
    await self._waiter
  File "C:\Program Files\WindowsApps\PythonSoftwareFoundation.Python.3.13_3.13.1008.0_x64__qbz5n2kfra8p0\Lib\asyncio\proactor_events.py", line 286, in _loop_reading
    length = fut.result()
  File "C:\Program Files\WindowsApps\PythonSoftwareFoundation.Python.3.13_3.13.1008.0_x64__qbz5n2kfra8p0\Lib\asyncio\windows_events.py", line 804, in _poll
    value = callback(transferred, key, ov)
  File "C:\Program Files\WindowsApps\PythonSoftwareFoundation.Python.3.13_3.13.1008.0_x64__qbz5n2kfra8p0\Lib\asyncio\windows_events.py", line 467, in finish_socket_func
    raise ConnectionResetError(*exc.args)
ConnectionResetError: [WinError 64] El nombre de red especificado ya no está disponible
2025-06-11 11:38:21 - INFO - [SERVIDOR INFO]: Conexión establecida desde ('127.0.0.1', 58459)
2025-06-11 11:38:25 - INFO - [SERVIDOR INFO]: Servidor escuchando en localhost:8083
2025-06-11 11:38:26 - INFO - [SERVIDOR INFO]: Conexión establecida desde ('127.0.0.1', 58463)
2025-06-11 11:38:43 - ERROR - Unhandled exception in client_connected_cb
transport: <_ProactorSocketTransport closed>
Traceback (most recent call last):
  File "C:\Program Files\WindowsApps\PythonSoftwareFoundation.Python.3.13_3.13.1008.0_x64__qbz5n2kfra8p0\Lib\asyncio\windows_events.py", line 463, in finish_socket_func
    return ov.getresult()
           ~~~~~~~~~~~~^^
OSError: [WinError 64] El nombre de red especificado ya no está disponible

During handling of the above exception, another exception occurred:

Traceback (most recent call last):
  File "c:\Users\nzjha\Desktop\Clon_Github\python_serve\Async\d.py", line 133, in server
    message = (await reader.readline()).decode().strip()
               ^^^^^^^^^^^^^^^^^^^^^^^
  File "C:\Program Files\WindowsApps\PythonSoftwareFoundation.Python.3.13_3.13.1008.0_x64__qbz5n2kfra8p0\Lib\asyncio\streams.py", line 562, in readline
    line = await self.readuntil(sep)
           ^^^^^^^^^^^^^^^^^^^^^^^^^
  File "C:\Program Files\WindowsApps\PythonSoftwareFoundation.Python.3.13_3.13.1008.0_x64__qbz5n2kfra8p0\Lib\asyncio\streams.py", line 677, in readuntil
    await self._wait_for_data('readuntil')
  File "C:\Program Files\WindowsApps\PythonSoftwareFoundation.Python.3.13_3.13.1008.0_x64__qbz5n2kfra8p0\Lib\asyncio\streams.py", line 539, in _wait_for_data
    await self._waiter
  File "C:\Program Files\WindowsApps\PythonSoftwareFoundation.Python.3.13_3.13.1008.0_x64__qbz5n2kfra8p0\Lib\asyncio\proactor_events.py", line 286, in _loop_reading
    length = fut.result()
  File "C:\Program Files\WindowsApps\PythonSoftwareFoundation.Python.3.13_3.13.1008.0_x64__qbz5n2kfra8p0\Lib\asyncio\windows_events.py", line 804, in _poll
    value = callback(transferred, key, ov)
  File "C:\Program Files\WindowsApps\PythonSoftwareFoundation.Python.3.13_3.13.1008.0_x64__qbz5n2kfra8p0\Lib\asyncio\windows_events.py", line 467, in finish_socket_func
    raise ConnectionResetError(*exc.args)
ConnectionResetError: [WinError 64] El nombre de red especificado ya no está disponible
2025-06-11 11:51:06 - INFO - [SERVIDOR INFO]: Servidor escuchando en localhost:8083
2025-06-11 11:51:11 - INFO - [SERVIDOR INFO]: Conexión desde ('127.0.0.1', 58694)
2025-06-11 11:51:16 - WARNING - [SERVIDOR WARNING]: == ESPERA AUTOMÁTICA DE 5 SEGUNDOS ==
2025-06-11 11:51:20 - INFO - [SERVIDOR INFO]: Consultando datos de teleoperador...
2025-06-11 11:51:20 - ERROR - Unhandled exception in client_connected_cb
transport: <_ProactorSocketTransport fd=1088 read=<_OverlappedFuture pending cb=[_ProactorReadPipeTransport._loop_reading()]>>
Traceback (most recent call last):
  File "c:\Users\nzjha\Desktop\Clon_Github\python_serve\Async\sv.py", line 170, in server_on
    await teleoperador_MySQL(writer, reader)
  File "c:\Users\nzjha\Desktop\Clon_Github\python_serve\Async\sv.py", line 100, in teleoperador_MySQL
    writer("Has seleccionado la opción de TELEOPERADOR con MySQL. Selecciona la consulta que quieras hacer: "\
    ~~~~~~^^^^^^^^^^^^^^^^^^^^^^^^^^^^^^^^^^^^^^^^^^^^^^^^^^^^^^^^^^^^^^^^^^^^^^^^^^^^^^^^^^^^^^^^^^^^^^^^^^^^
    "\n"\
    ^^^^^
    ...<2 lines>...
    "3. Eliminar un teleoperador \n"\
    ^^^^^^^^^^^^^^^^^^^^^^^^^^^^^^^^^
    "4. Consultar teleoperadores y sus horarios \n".encode())
    ^^^^^^^^^^^^^^^^^^^^^^^^^^^^^^^^^^^^^^^^^^^^^^^^^^^^^^^^^
TypeError: 'StreamWriter' object is not callable
2025-06-11 11:53:13 - INFO - [SERVIDOR INFO]: Servidor escuchando en localhost:8083
2025-06-11 11:53:16 - INFO - [SERVIDOR INFO]: Conexión desde ('127.0.0.1', 58746)
2025-06-11 11:53:21 - WARNING - [SERVIDOR WARNING]: == ESPERA AUTOMÁTICA DE 5 SEGUNDOS ==
2025-06-11 11:53:23 - INFO - [SERVIDOR INFO]: Consultando datos de teleoperador...
2025-06-11 11:53:23 - ERROR - Unhandled exception in client_connected_cb
transport: <_ProactorSocketTransport fd=1088 read=<_OverlappedFuture pending cb=[_ProactorReadPipeTransport._loop_reading()]>>
Traceback (most recent call last):
  File "c:\Users\nzjha\Desktop\Clon_Github\python_serve\Async\sv.py", line 171, in server_on
    await teleoperador_MySQL(writer, reader)
  File "c:\Users\nzjha\Desktop\Clon_Github\python_serve\Async\sv.py", line 106, in teleoperador_MySQL
    writer.write(menu.endcode())
                 ^^^^^^^^^^^^
AttributeError: 'bytes' object has no attribute 'endcode'
2025-06-11 11:54:35 - INFO - [SERVIDOR INFO]: Servidor escuchando en localhost:8083
2025-06-11 11:54:36 - INFO - [SERVIDOR INFO]: Conexión desde ('127.0.0.1', 58776)
2025-06-11 11:54:41 - WARNING - [SERVIDOR WARNING]: == ESPERA AUTOMÁTICA DE 5 SEGUNDOS ==
2025-06-11 11:54:44 - INFO - [SERVIDOR INFO]: Consultando datos de teleoperador...
2025-06-11 11:54:47 - INFO - package: mysql.connector.plugins
2025-06-11 11:54:47 - INFO - plugin_name: caching_sha2_password
2025-06-11 11:54:47 - INFO - AUTHENTICATION_PLUGIN_CLASS: MySQLCachingSHA2PasswordAuthPlugin
2025-06-11 11:55:13 - INFO - [SERVIDOR INFO]: Nombre recibido: Rina
2025-06-11 11:55:20 - INFO - [SERVIDOR INFO]: Apellido recibido: Psicopata
2025-06-11 11:55:24 - INFO - [SERVIDOR INFO]: Telefono recibido: 09876545678932
2025-06-11 11:55:31 - INFO - [SERVIDOR INFO]: Email recibido: rina@zzz.com
2025-06-11 11:55:41 - ERROR - Unhandled exception in client_connected_cb
transport: <_ProactorSocketTransport closed>
Traceback (most recent call last):
  File "C:\Program Files\WindowsApps\PythonSoftwareFoundation.Python.3.13_3.13.1008.0_x64__qbz5n2kfra8p0\Lib\asyncio\windows_events.py", line 463, in finish_socket_func
    return ov.getresult()
           ~~~~~~~~~~~~^^
OSError: [WinError 64] El nombre de red especificado ya no está disponible

During handling of the above exception, another exception occurred:

Traceback (most recent call last):
  File "c:\Users\nzjha\Desktop\Clon_Github\python_serve\Async\sv.py", line 171, in server_on
    await teleoperador_MySQL(writer, reader)
  File "c:\Users\nzjha\Desktop\Clon_Github\python_serve\Async\sv.py", line 112, in teleoperador_MySQL
    await add_teleoperador(writer, reader)
  File "c:\Users\nzjha\Desktop\Clon_Github\python_serve\Async\sv.py", line 73, in add_teleoperador
    ub_id = (await reader.read(1024)).decode().strip()
             ^^^^^^^^^^^^^^^^^^^^^^^
  File "C:\Program Files\WindowsApps\PythonSoftwareFoundation.Python.3.13_3.13.1008.0_x64__qbz5n2kfra8p0\Lib\asyncio\streams.py", line 730, in read
    await self._wait_for_data('read')
  File "C:\Program Files\WindowsApps\PythonSoftwareFoundation.Python.3.13_3.13.1008.0_x64__qbz5n2kfra8p0\Lib\asyncio\streams.py", line 539, in _wait_for_data
    await self._waiter
  File "C:\Program Files\WindowsApps\PythonSoftwareFoundation.Python.3.13_3.13.1008.0_x64__qbz5n2kfra8p0\Lib\asyncio\proactor_events.py", line 286, in _loop_reading
    length = fut.result()
  File "C:\Program Files\WindowsApps\PythonSoftwareFoundation.Python.3.13_3.13.1008.0_x64__qbz5n2kfra8p0\Lib\asyncio\windows_events.py", line 804, in _poll
    value = callback(transferred, key, ov)
  File "C:\Program Files\WindowsApps\PythonSoftwareFoundation.Python.3.13_3.13.1008.0_x64__qbz5n2kfra8p0\Lib\asyncio\windows_events.py", line 467, in finish_socket_func
    raise ConnectionResetError(*exc.args)
ConnectionResetError: [WinError 64] El nombre de red especificado ya no está disponible
2025-06-11 12:00:17 - INFO - [SERVIDOR INFO]: Servidor escuchando en localhost:8083
2025-06-11 12:00:17 - INFO - [SERVIDOR INFO]: Conexión desde ('127.0.0.1', 58906)
2025-06-11 12:00:22 - WARNING - [SERVIDOR WARNING]: == ESPERA AUTOMÁTICA DE 5 SEGUNDOS ==
2025-06-11 12:00:36 - INFO - [SERVIDOR INFO]: Consultando datos de teleoperador...
2025-06-11 12:00:41 - INFO - package: mysql.connector.plugins
2025-06-11 12:00:41 - INFO - plugin_name: caching_sha2_password
2025-06-11 12:00:41 - INFO - AUTHENTICATION_PLUGIN_CLASS: MySQLCachingSHA2PasswordAuthPlugin
2025-06-11 12:00:44 - INFO - [SERVIDOR INFO]: Nombre recibido: Ei
2025-06-11 12:00:52 - INFO - [SERVIDOR INFO]: Apellido recibido: Eternidad
2025-06-11 12:00:57 - INFO - [SERVIDOR INFO]: Telefono recibido: 764796707898
2025-06-11 12:01:06 - INFO - [SERVIDOR INFO]: Email recibido: ei@inazuma.com
2025-06-11 12:01:13 - INFO - [SERVIDOR INFO]: Ubicacion recibida: 17
2025-06-11 12:01:14 - INFO - [SERVIDOR INFO]: Teleoperador Ei Eternidad insertado correctamente en la base de datos.
2025-06-11 12:01:23 - ERROR - Unhandled exception in client_connected_cb
transport: <_ProactorSocketTransport closed>
Traceback (most recent call last):
  File "C:\Program Files\WindowsApps\PythonSoftwareFoundation.Python.3.13_3.13.1008.0_x64__qbz5n2kfra8p0\Lib\asyncio\windows_events.py", line 463, in finish_socket_func
    return ov.getresult()
           ~~~~~~~~~~~~^^
OSError: [WinError 64] El nombre de red especificado ya no está disponible

During handling of the above exception, another exception occurred:

Traceback (most recent call last):
  File "c:\Users\nzjha\Desktop\Clon_Github\python_serve\Async\sv.py", line 171, in server_on
    await teleoperador_MySQL(writer, reader)
  File "c:\Users\nzjha\Desktop\Clon_Github\python_serve\Async\sv.py", line 112, in teleoperador_MySQL
    await add_teleoperador(writer, reader)
  File "c:\Users\nzjha\Desktop\Clon_Github\python_serve\Async\sv.py", line 44, in add_teleoperador
    nombre = (await reader.read(1024)).decode().strip()
              ^^^^^^^^^^^^^^^^^^^^^^^
  File "C:\Program Files\WindowsApps\PythonSoftwareFoundation.Python.3.13_3.13.1008.0_x64__qbz5n2kfra8p0\Lib\asyncio\streams.py", line 730, in read
    await self._wait_for_data('read')
  File "C:\Program Files\WindowsApps\PythonSoftwareFoundation.Python.3.13_3.13.1008.0_x64__qbz5n2kfra8p0\Lib\asyncio\streams.py", line 539, in _wait_for_data
    await self._waiter
  File "C:\Program Files\WindowsApps\PythonSoftwareFoundation.Python.3.13_3.13.1008.0_x64__qbz5n2kfra8p0\Lib\asyncio\proactor_events.py", line 286, in _loop_reading
    length = fut.result()
  File "C:\Program Files\WindowsApps\PythonSoftwareFoundation.Python.3.13_3.13.1008.0_x64__qbz5n2kfra8p0\Lib\asyncio\windows_events.py", line 804, in _poll
    value = callback(transferred, key, ov)
  File "C:\Program Files\WindowsApps\PythonSoftwareFoundation.Python.3.13_3.13.1008.0_x64__qbz5n2kfra8p0\Lib\asyncio\windows_events.py", line 467, in finish_socket_func
    raise ConnectionResetError(*exc.args)
ConnectionResetError: [WinError 64] El nombre de red especificado ya no está disponible
2025-06-11 12:05:28 - INFO - [SERVIDOR INFO]: Servidor escuchando en localhost:8083
2025-06-11 12:05:28 - INFO - [SERVIDOR INFO]: Conexión desde ('127.0.0.1', 58979)
2025-06-11 12:05:33 - WARNING - [SERVIDOR WARNING]: == ESPERA AUTOMÁTICA DE 5 SEGUNDOS ==
2025-06-11 12:05:37 - INFO - [SERVIDOR INFO]: Consultando datos de teleoperador...
2025-06-11 12:05:40 - INFO - package: mysql.connector.plugins
2025-06-11 12:05:40 - INFO - plugin_name: caching_sha2_password
2025-06-11 12:05:40 - INFO - AUTHENTICATION_PLUGIN_CLASS: MySQLCachingSHA2PasswordAuthPlugin
2025-06-11 12:05:45 - INFO - [SERVIDOR INFO]: Nombre recibido: Kiara
2025-06-11 12:05:48 - INFO - [SERVIDOR INFO]: Apellido recibido: Gata
2025-06-11 12:05:51 - INFO - [SERVIDOR INFO]: Telefono recibido: 3123nya
2025-06-11 12:06:00 - INFO - [SERVIDOR INFO]: Email recibido: nya@inazuma.com
2025-06-11 12:06:04 - INFO - [SERVIDOR INFO]: Ubicacion recibida: 17
2025-06-11 12:06:04 - INFO - [SERVIDOR INFO]: Teleoperador Kiara Gata insertado correctamente en la base de datos.
2025-06-11 12:07:33 - INFO - [SERVIDOR INFO]: Servidor escuchando en localhost:8083
2025-06-11 12:07:33 - INFO - [SERVIDOR INFO]: Conexión desde ('127.0.0.1', 59046)
2025-06-11 12:07:38 - WARNING - [SERVIDOR WARNING]: == ESPERA AUTOMÁTICA DE 5 SEGUNDOS ==
2025-06-11 12:07:46 - INFO - [SERVIDOR INFO]: Consultando datos de teleoperador...
2025-06-11 12:07:48 - INFO - package: mysql.connector.plugins
2025-06-11 12:07:48 - INFO - plugin_name: caching_sha2_password
2025-06-11 12:07:48 - INFO - AUTHENTICATION_PLUGIN_CLASS: MySQLCachingSHA2PasswordAuthPlugin
2025-06-11 12:08:26 - INFO - [SERVIDOR INFO]: Nombre recibido: No se
2025-06-11 12:08:29 - INFO - [SERVIDOR INFO]: Apellido recibido: Ni idea
2025-06-11 12:08:34 - INFO - [SERVIDOR INFO]: Telefono recibido: Niideadadi9732
2025-06-11 12:08:41 - INFO - [SERVIDOR INFO]: Email recibido: ni@idea.com
2025-06-11 12:09:15 - ERROR - Unhandled exception in client_connected_cb
transport: <_ProactorSocketTransport closed>
Traceback (most recent call last):
  File "C:\Program Files\WindowsApps\PythonSoftwareFoundation.Python.3.13_3.13.1008.0_x64__qbz5n2kfra8p0\Lib\asyncio\windows_events.py", line 463, in finish_socket_func
    return ov.getresult()
           ~~~~~~~~~~~~^^
OSError: [WinError 64] El nombre de red especificado ya no está disponible

During handling of the above exception, another exception occurred:

Traceback (most recent call last):
  File "c:\Users\nzjha\Desktop\Clon_Github\python_serve\Async\sv.py", line 171, in server_on
    await teleoperador_MySQL(writer, reader)
  File "c:\Users\nzjha\Desktop\Clon_Github\python_serve\Async\sv.py", line 112, in teleoperador_MySQL
    await add_teleoperador(writer, reader)
  File "c:\Users\nzjha\Desktop\Clon_Github\python_serve\Async\sv.py", line 73, in add_teleoperador
    ub_id = (await reader.read(1024)).decode().strip()
             ^^^^^^^^^^^^^^^^^^^^^^^
  File "C:\Program Files\WindowsApps\PythonSoftwareFoundation.Python.3.13_3.13.1008.0_x64__qbz5n2kfra8p0\Lib\asyncio\streams.py", line 730, in read
    await self._wait_for_data('read')
  File "C:\Program Files\WindowsApps\PythonSoftwareFoundation.Python.3.13_3.13.1008.0_x64__qbz5n2kfra8p0\Lib\asyncio\streams.py", line 539, in _wait_for_data
    await self._waiter
  File "C:\Program Files\WindowsApps\PythonSoftwareFoundation.Python.3.13_3.13.1008.0_x64__qbz5n2kfra8p0\Lib\asyncio\proactor_events.py", line 286, in _loop_reading
    length = fut.result()
  File "C:\Program Files\WindowsApps\PythonSoftwareFoundation.Python.3.13_3.13.1008.0_x64__qbz5n2kfra8p0\Lib\asyncio\windows_events.py", line 804, in _poll
    value = callback(transferred, key, ov)
  File "C:\Program Files\WindowsApps\PythonSoftwareFoundation.Python.3.13_3.13.1008.0_x64__qbz5n2kfra8p0\Lib\asyncio\windows_events.py", line 467, in finish_socket_func
    raise ConnectionResetError(*exc.args)
ConnectionResetError: [WinError 64] El nombre de red especificado ya no está disponible
2025-06-11 12:26:18 - INFO - [SERVIDOR INFO]: Servidor escuchando en localhost:8083
2025-06-11 12:26:18 - INFO - [SERVIDOR INFO]: Conexión desde ('127.0.0.1', 59374)
2025-06-11 12:26:24 - WARNING - [SERVIDOR WARNING]: == ESPERA AUTOMÁTICA DE 5 SEGUNDOS ==
2025-06-11 12:26:26 - INFO - [SERVIDOR INFO]: Consultando datos de teleoperador...
2025-06-11 12:26:29 - INFO - package: mysql.connector.plugins
2025-06-11 12:26:29 - INFO - plugin_name: caching_sha2_password
2025-06-11 12:26:29 - INFO - AUTHENTICATION_PLUGIN_CLASS: MySQLCachingSHA2PasswordAuthPlugin
2025-06-11 12:26:31 - INFO - [SERVIDOR INFO]: Nombre recibido: l
2025-06-11 12:26:32 - INFO - [SERVIDOR INFO]: Apellido recibido: L
2025-06-11 12:26:32 - INFO - [SERVIDOR INFO]: Telefono recibido: L
2025-06-11 12:26:34 - INFO - [SERVIDOR INFO]: Email recibido: l
2025-06-11 12:26:40 - INFO - [SERVIDOR INFO]: Ubicacion recibida: 7
2025-06-11 12:26:40 - INFO - [SERVIDOR INFO]: Teleoperador l L insertado correctamente en la base de datos.
2025-06-11 12:48:25 - INFO - [SERVIDOR INFO]: Servidor escuchando en localhost:8083
2025-06-11 12:48:30 - INFO - [SERVIDOR INFO]: Conexión desde ('127.0.0.1', 59898)
2025-06-11 12:48:35 - WARNING - [SERVIDOR WARNING]: == ESPERA AUTOMÁTICA DE 5 SEGUNDOS ==
2025-06-11 12:48:38 - INFO - [SERVIDOR INFO]: Consultando datos de teleoperador...
2025-06-11 12:48:43 - INFO - package: mysql.connector.plugins
2025-06-11 12:48:43 - INFO - plugin_name: caching_sha2_password
2025-06-11 12:48:43 - INFO - AUTHENTICATION_PLUGIN_CLASS: MySQLCachingSHA2PasswordAuthPlugin
2025-06-11 12:48:59 - INFO - [SERVIDOR INFO]: Teleoperador recibido: 6
2025-06-11 12:49:15 - INFO - [SERVIDOR INFO]: Semana recibida: semana 5 de septiembre
2025-06-11 12:49:34 - INFO - [SERVIDOR INFO]: Inicio de jornada recibido: 05:00:00
2025-06-11 12:49:43 - INFO - [SERVIDOR INFO]: Fin de jornada recibido: 13:00:00
2025-06-11 12:49:43 - ERROR - Unhandled exception in client_connected_cb
transport: <_ProactorSocketTransport fd=1092 read=<_OverlappedFuture pending cb=[_ProactorReadPipeTransport._loop_reading()]>>
Traceback (most recent call last):
  File "c:\Users\nzjha\Desktop\Clon_Github\python_serve\Async\sv.py", line 238, in server_on
    await teleoperador_MySQL(writer, reader)
  File "c:\Users\nzjha\Desktop\Clon_Github\python_serve\Async\sv.py", line 182, in teleoperador_MySQL
    await add_horario_teleoperador(writer, reader)
  File "c:\Users\nzjha\Desktop\Clon_Github\python_serve\Async\sv.py", line 83, in add_horario_teleoperador
    crs.execute(query, values)
    ~~~~~~~~~~~^^^^^^^^^^^^^^^
  File "C:\Users\nzjha\AppData\Local\Packages\PythonSoftwareFoundation.Python.3.13_qbz5n2kfra8p0\LocalCache\local-packages\Python313\site-packages\mysql\connector\cursor.py", line 418, in execute
    self._connection.cmd_query(
    ~~~~~~~~~~~~~~~~~~~~~~~~~~^
        self._stmt_partition["mappable_stmt"],
        ^^^^^^^^^^^^^^^^^^^^^^^^^^^^^^^^^^^^^^
        read_timeout=self._read_timeout,
        ^^^^^^^^^^^^^^^^^^^^^^^^^^^^^^^^
        write_timeout=self._write_timeout,
        ^^^^^^^^^^^^^^^^^^^^^^^^^^^^^^^^^^
    )
    ^
  File "C:\Users\nzjha\AppData\Local\Packages\PythonSoftwareFoundation.Python.3.13_qbz5n2kfra8p0\LocalCache\local-packages\Python313\site-packages\mysql\connector\opentelemetry\context_propagation.py", line 97, in wrapper
    return method(cnx, *args, **kwargs)
  File "C:\Users\nzjha\AppData\Local\Packages\PythonSoftwareFoundation.Python.3.13_qbz5n2kfra8p0\LocalCache\local-packages\Python313\site-packages\mysql\connector\_decorating.py", line 89, in handle_cnx_method
    raise err
  File "C:\Users\nzjha\AppData\Local\Packages\PythonSoftwareFoundation.Python.3.13_qbz5n2kfra8p0\LocalCache\local-packages\Python313\site-packages\mysql\connector\_decorating.py", line 85, in handle_cnx_method
    return cnx_method(cnx, *args, **kwargs)
  File "C:\Users\nzjha\AppData\Local\Packages\PythonSoftwareFoundation.Python.3.13_qbz5n2kfra8p0\LocalCache\local-packages\Python313\site-packages\mysql\connector\connection.py", line 984, in cmd_query
    result = self._handle_result(
        self._send_cmd(
    ...<6 lines>...
        write_timeout,
    )
  File "C:\Users\nzjha\AppData\Local\Packages\PythonSoftwareFoundation.Python.3.13_qbz5n2kfra8p0\LocalCache\local-packages\Python313\site-packages\mysql\connector\_decorating.py", line 89, in handle_cnx_method
    raise err
  File "C:\Users\nzjha\AppData\Local\Packages\PythonSoftwareFoundation.Python.3.13_qbz5n2kfra8p0\LocalCache\local-packages\Python313\site-packages\mysql\connector\_decorating.py", line 85, in handle_cnx_method
    return cnx_method(cnx, *args, **kwargs)
  File "C:\Users\nzjha\AppData\Local\Packages\PythonSoftwareFoundation.Python.3.13_qbz5n2kfra8p0\LocalCache\local-packages\Python313\site-packages\mysql\connector\connection.py", line 745, in _handle_result
    raise get_exception(packet)
mysql.connector.errors.ProgrammingError: 1054 (42S22): Unknown column 'inicio_jornada' in 'field list'
2025-06-11 12:53:10 - INFO - [SERVIDOR INFO]: Servidor escuchando en localhost:8083
2025-06-11 12:53:10 - INFO - [SERVIDOR INFO]: Conexión desde ('127.0.0.1', 60008)
2025-06-11 12:53:15 - WARNING - [SERVIDOR WARNING]: == ESPERA AUTOMÁTICA DE 5 SEGUNDOS ==
2025-06-11 12:53:19 - INFO - [SERVIDOR INFO]: Consultando datos de teleoperador...
2025-06-11 12:53:26 - INFO - package: mysql.connector.plugins
2025-06-11 12:53:26 - INFO - plugin_name: caching_sha2_password
2025-06-11 12:53:26 - INFO - AUTHENTICATION_PLUGIN_CLASS: MySQLCachingSHA2PasswordAuthPlugin
2025-06-11 12:53:38 - INFO - [SERVIDOR INFO]: Teleoperador recibido: 3
2025-06-11 12:53:49 - INFO - [SERVIDOR INFO]: Semana recibida: Semana 5 de septiembre
2025-06-11 12:53:57 - INFO - [SERVIDOR INFO]: Inicio de jornada recibido: 09:30:00
2025-06-11 12:54:07 - INFO - [SERVIDOR INFO]: Fin de jornada recibido: 17:30:00
2025-06-11 12:54:07 - ERROR - Unhandled exception in client_connected_cb
transport: <_ProactorSocketTransport fd=1088 read=<_OverlappedFuture pending cb=[_ProactorReadPipeTransport._loop_reading()]>>
Traceback (most recent call last):
  File "c:\Users\nzjha\Desktop\Clon_Github\python_serve\Async\sv.py", line 241, in server_on
    await teleoperador_MySQL(writer, reader)
  File "c:\Users\nzjha\Desktop\Clon_Github\python_serve\Async\sv.py", line 185, in teleoperador_MySQL
    await add_horario_teleoperador(writer, reader)
  File "c:\Users\nzjha\Desktop\Clon_Github\python_serve\Async\sv.py", line 83, in add_horario_teleoperador
    crs.execute(query, values)
    ~~~~~~~~~~~^^^^^^^^^^^^^^^
  File "C:\Users\nzjha\AppData\Local\Packages\PythonSoftwareFoundation.Python.3.13_qbz5n2kfra8p0\LocalCache\local-packages\Python313\site-packages\mysql\connector\cursor.py", line 418, in execute
    self._connection.cmd_query(
    ~~~~~~~~~~~~~~~~~~~~~~~~~~^
        self._stmt_partition["mappable_stmt"],
        ^^^^^^^^^^^^^^^^^^^^^^^^^^^^^^^^^^^^^^
        read_timeout=self._read_timeout,
        ^^^^^^^^^^^^^^^^^^^^^^^^^^^^^^^^
        write_timeout=self._write_timeout,
        ^^^^^^^^^^^^^^^^^^^^^^^^^^^^^^^^^^
    )
    ^
  File "C:\Users\nzjha\AppData\Local\Packages\PythonSoftwareFoundation.Python.3.13_qbz5n2kfra8p0\LocalCache\local-packages\Python313\site-packages\mysql\connector\opentelemetry\context_propagation.py", line 97, in wrapper
    return method(cnx, *args, **kwargs)
  File "C:\Users\nzjha\AppData\Local\Packages\PythonSoftwareFoundation.Python.3.13_qbz5n2kfra8p0\LocalCache\local-packages\Python313\site-packages\mysql\connector\_decorating.py", line 89, in handle_cnx_method
    raise err
  File "C:\Users\nzjha\AppData\Local\Packages\PythonSoftwareFoundation.Python.3.13_qbz5n2kfra8p0\LocalCache\local-packages\Python313\site-packages\mysql\connector\_decorating.py", line 85, in handle_cnx_method
    return cnx_method(cnx, *args, **kwargs)
  File "C:\Users\nzjha\AppData\Local\Packages\PythonSoftwareFoundation.Python.3.13_qbz5n2kfra8p0\LocalCache\local-packages\Python313\site-packages\mysql\connector\connection.py", line 984, in cmd_query
    result = self._handle_result(
        self._send_cmd(
    ...<6 lines>...
        write_timeout,
    )
  File "C:\Users\nzjha\AppData\Local\Packages\PythonSoftwareFoundation.Python.3.13_qbz5n2kfra8p0\LocalCache\local-packages\Python313\site-packages\mysql\connector\_decorating.py", line 89, in handle_cnx_method
    raise err
  File "C:\Users\nzjha\AppData\Local\Packages\PythonSoftwareFoundation.Python.3.13_qbz5n2kfra8p0\LocalCache\local-packages\Python313\site-packages\mysql\connector\_decorating.py", line 85, in handle_cnx_method
    return cnx_method(cnx, *args, **kwargs)
  File "C:\Users\nzjha\AppData\Local\Packages\PythonSoftwareFoundation.Python.3.13_qbz5n2kfra8p0\LocalCache\local-packages\Python313\site-packages\mysql\connector\connection.py", line 745, in _handle_result
    raise get_exception(packet)
mysql.connector.errors.ProgrammingError: 1054 (42S22): Unknown column 'inicio_jornada' in 'field list'
2025-06-11 13:21:58 - INFO - [SERVIDOR INFO]: Servidor escuchando en localhost:8083
2025-06-11 13:22:04 - INFO - [SERVIDOR INFO]: Conexión desde ('127.0.0.1', 60454)
2025-06-11 13:22:09 - WARNING - [SERVIDOR WARNING]: == ESPERA AUTOMÁTICA DE 5 SEGUNDOS ==
2025-06-11 13:22:10 - INFO - [SERVIDOR INFO]: Consultando datos de teleoperador...
2025-06-11 13:22:13 - INFO - package: mysql.connector.plugins
2025-06-11 13:22:13 - INFO - plugin_name: caching_sha2_password
2025-06-11 13:22:13 - INFO - AUTHENTICATION_PLUGIN_CLASS: MySQLCachingSHA2PasswordAuthPlugin
2025-06-11 13:22:20 - INFO - [SERVIDOR INFO]: Teleoperador recibido: 4
2025-06-11 13:22:44 - INFO - [SERVIDOR INFO]: Semana recibida: Semana 5 de junio
2025-06-11 13:22:52 - INFO - [SERVIDOR INFO]: Inicio de jornada recibido: 09:00:00
2025-06-11 13:22:58 - INFO - [SERVIDOR INFO]: Fin de jornada recibido: 17:00:00
2025-06-11 13:22:58 - ERROR - Unhandled exception in client_connected_cb
transport: <_ProactorSocketTransport fd=1096 read=<_OverlappedFuture pending cb=[_ProactorReadPipeTransport._loop_reading()]>>
Traceback (most recent call last):
  File "c:\Users\nzjha\Desktop\Clon_Github\python_serve\Async\sv.py", line 242, in server_on
    await teleoperador_MySQL(writer, reader)
  File "c:\Users\nzjha\Desktop\Clon_Github\python_serve\Async\sv.py", line 186, in teleoperador_MySQL
    await add_horario_teleoperador(writer, reader)
  File "c:\Users\nzjha\Desktop\Clon_Github\python_serve\Async\sv.py", line 84, in add_horario_teleoperador
    crs.execute(query, values)
    ~~~~~~~~~~~^^^^^^^^^^^^^^^
  File "C:\Users\nzjha\AppData\Local\Packages\PythonSoftwareFoundation.Python.3.13_qbz5n2kfra8p0\LocalCache\local-packages\Python313\site-packages\mysql\connector\cursor.py", line 418, in execute
    self._connection.cmd_query(
    ~~~~~~~~~~~~~~~~~~~~~~~~~~^
        self._stmt_partition["mappable_stmt"],
        ^^^^^^^^^^^^^^^^^^^^^^^^^^^^^^^^^^^^^^
        read_timeout=self._read_timeout,
        ^^^^^^^^^^^^^^^^^^^^^^^^^^^^^^^^
        write_timeout=self._write_timeout,
        ^^^^^^^^^^^^^^^^^^^^^^^^^^^^^^^^^^
    )
    ^
  File "C:\Users\nzjha\AppData\Local\Packages\PythonSoftwareFoundation.Python.3.13_qbz5n2kfra8p0\LocalCache\local-packages\Python313\site-packages\mysql\connector\opentelemetry\context_propagation.py", line 97, in wrapper
    return method(cnx, *args, **kwargs)
  File "C:\Users\nzjha\AppData\Local\Packages\PythonSoftwareFoundation.Python.3.13_qbz5n2kfra8p0\LocalCache\local-packages\Python313\site-packages\mysql\connector\_decorating.py", line 89, in handle_cnx_method
    raise err
  File "C:\Users\nzjha\AppData\Local\Packages\PythonSoftwareFoundation.Python.3.13_qbz5n2kfra8p0\LocalCache\local-packages\Python313\site-packages\mysql\connector\_decorating.py", line 85, in handle_cnx_method
    return cnx_method(cnx, *args, **kwargs)
  File "C:\Users\nzjha\AppData\Local\Packages\PythonSoftwareFoundation.Python.3.13_qbz5n2kfra8p0\LocalCache\local-packages\Python313\site-packages\mysql\connector\connection.py", line 984, in cmd_query
    result = self._handle_result(
        self._send_cmd(
    ...<6 lines>...
        write_timeout,
    )
  File "C:\Users\nzjha\AppData\Local\Packages\PythonSoftwareFoundation.Python.3.13_qbz5n2kfra8p0\LocalCache\local-packages\Python313\site-packages\mysql\connector\_decorating.py", line 89, in handle_cnx_method
    raise err
  File "C:\Users\nzjha\AppData\Local\Packages\PythonSoftwareFoundation.Python.3.13_qbz5n2kfra8p0\LocalCache\local-packages\Python313\site-packages\mysql\connector\_decorating.py", line 85, in handle_cnx_method
    return cnx_method(cnx, *args, **kwargs)
  File "C:\Users\nzjha\AppData\Local\Packages\PythonSoftwareFoundation.Python.3.13_qbz5n2kfra8p0\LocalCache\local-packages\Python313\site-packages\mysql\connector\connection.py", line 745, in _handle_result
    raise get_exception(packet)
mysql.connector.errors.ProgrammingError: 1054 (42S22): Unknown column 'inicio_jornada' in 'field list'
2025-06-11 13:24:29 - INFO - [SERVIDOR INFO]: Servidor escuchando en localhost:8083
2025-06-11 13:25:49 - INFO - [SERVIDOR INFO]: Conexión desde ('127.0.0.1', 60498)
2025-06-11 13:25:54 - WARNING - [SERVIDOR WARNING]: == ESPERA AUTOMÁTICA DE 5 SEGUNDOS ==
2025-06-11 13:25:57 - INFO - [SERVIDOR INFO]: Consultando datos de teleoperador...
2025-06-11 13:26:02 - INFO - package: mysql.connector.plugins
2025-06-11 13:26:02 - INFO - plugin_name: caching_sha2_password
2025-06-11 13:26:02 - INFO - AUTHENTICATION_PLUGIN_CLASS: MySQLCachingSHA2PasswordAuthPlugin
2025-06-11 13:26:07 - INFO - [SERVIDOR INFO]: Teleoperador recibido: 4
2025-06-11 13:26:20 - INFO - [SERVIDOR INFO]: Semana recibida: Semana 5 de junio
2025-06-11 13:26:27 - INFO - [SERVIDOR INFO]: Inicio de jornada recibido: 09:00:00
2025-06-11 13:26:33 - INFO - [SERVIDOR INFO]: Fin de jornada recibido: 16:00:00
2025-06-11 13:26:37 - INFO - [SERVIDOR INFO]: Descripción recibida: des
2025-06-11 13:26:37 - ERROR - Unhandled exception in client_connected_cb
transport: <_ProactorSocketTransport fd=1088 read=<_OverlappedFuture pending cb=[_ProactorReadPipeTransport._loop_reading()]>>
Traceback (most recent call last):
  File "c:\Users\nzjha\Desktop\Clon_Github\python_serve\Async\sv.py", line 249, in server_on
    await teleoperador_MySQL(writer, reader)
  File "c:\Users\nzjha\Desktop\Clon_Github\python_serve\Async\sv.py", line 193, in teleoperador_MySQL
    await add_horario_teleoperador(writer, reader)
  File "c:\Users\nzjha\Desktop\Clon_Github\python_serve\Async\sv.py", line 91, in add_horario_teleoperador
    crs.execute(query, values)
    ~~~~~~~~~~~^^^^^^^^^^^^^^^
  File "C:\Users\nzjha\AppData\Local\Packages\PythonSoftwareFoundation.Python.3.13_qbz5n2kfra8p0\LocalCache\local-packages\Python313\site-packages\mysql\connector\cursor.py", line 394, in execute
    raise ProgrammingError(
        "Not all parameters were used in the SQL statement"
    )
mysql.connector.errors.ProgrammingError: Not all parameters were used in the SQL statement
2025-06-11 13:27:09 - INFO - [SERVIDOR INFO]: Servidor escuchando en localhost:8083
2025-06-11 13:27:12 - INFO - [SERVIDOR INFO]: Conexión desde ('127.0.0.1', 60518)
2025-06-11 13:27:17 - WARNING - [SERVIDOR WARNING]: == ESPERA AUTOMÁTICA DE 5 SEGUNDOS ==
2025-06-11 13:28:15 - INFO - [SERVIDOR INFO]: Consultando datos de teleoperador...
2025-06-11 13:28:31 - INFO - package: mysql.connector.plugins
2025-06-11 13:28:31 - INFO - plugin_name: caching_sha2_password
2025-06-11 13:28:31 - INFO - AUTHENTICATION_PLUGIN_CLASS: MySQLCachingSHA2PasswordAuthPlugin
2025-06-11 13:28:34 - INFO - [SERVIDOR INFO]: Teleoperador recibido: 1
2025-06-11 13:28:37 - INFO - [SERVIDOR INFO]: Semana recibida: Semana 5 de junio
2025-06-11 13:28:42 - INFO - [SERVIDOR INFO]: Inicio de jornada recibido: 09:00:00
2025-06-11 13:28:45 - INFO - [SERVIDOR INFO]: Fin de jornada recibido: 16:00:00
2025-06-11 13:28:49 - INFO - [SERVIDOR INFO]: Descripción recibida: des
2025-06-11 13:28:49 - INFO - [SERVIDOR INFO]: Horario del teleoperador con ID 1 insertado correctamente en la base de datos.
2025-06-11 13:36:00 - INFO - [SERVIDOR INFO]: Servidor escuchando en localhost:8083
2025-06-11 13:36:02 - INFO - [SERVIDOR INFO]: Conexión desde ('127.0.0.1', 60660)
2025-06-11 13:36:07 - WARNING - [SERVIDOR WARNING]: == ESPERA AUTOMÁTICA DE 5 SEGUNDOS ==
2025-06-11 13:36:10 - INFO - [SERVIDOR INFO]: Consultando datos de teleoperador...
2025-06-11 13:36:18 - INFO - package: mysql.connector.plugins
2025-06-11 13:36:18 - INFO - plugin_name: caching_sha2_password
2025-06-11 13:36:18 - INFO - AUTHENTICATION_PLUGIN_CLASS: MySQLCachingSHA2PasswordAuthPlugin
2025-06-11 13:36:22 - INFO - [SERVIDOR INFO]: Teleoperador recibido: 9
2025-06-11 13:36:22 - ERROR - Unhandled exception in client_connected_cb
transport: <_ProactorSocketTransport fd=1084 read=<_OverlappedFuture pending cb=[_ProactorReadPipeTransport._loop_reading()]>>
Traceback (most recent call last):
  File "c:\Users\nzjha\Desktop\Clon_Github\python_serve\Async\sv.py", line 261, in server_on
    await teleoperador_MySQL(writer, reader)
  File "c:\Users\nzjha\Desktop\Clon_Github\python_serve\Async\sv.py", line 217, in teleoperador_MySQL
    await delete_teleoperador(writer, reader)
  File "c:\Users\nzjha\Desktop\Clon_Github\python_serve\Async\sv.py", line 70, in delete_teleoperador
    crs.execute(query, (tele_id))
    ~~~~~~~~~~~^^^^^^^^^^^^^^^^^^
  File "C:\Users\nzjha\AppData\Local\Packages\PythonSoftwareFoundation.Python.3.13_qbz5n2kfra8p0\LocalCache\local-packages\Python313\site-packages\mysql\connector\cursor.py", line 398, in execute
    raise ProgrammingError(
    ...<2 lines>...
    )
mysql.connector.errors.ProgrammingError: Could not process parameters: int(9), it must be of type list, tuple or dict
2025-06-11 13:43:22 - INFO - [SERVIDOR INFO]: Servidor escuchando en localhost:8083
2025-06-11 13:43:27 - INFO - [SERVIDOR INFO]: Conexión desde ('127.0.0.1', 60928)
2025-06-11 13:43:32 - WARNING - [SERVIDOR WARNING]: == ESPERA AUTOMÁTICA DE 5 SEGUNDOS ==
2025-06-11 13:43:34 - INFO - [SERVIDOR INFO]: Consultando datos de teleoperador...
2025-06-11 13:43:39 - INFO - package: mysql.connector.plugins
2025-06-11 13:43:39 - INFO - plugin_name: caching_sha2_password
2025-06-11 13:43:39 - INFO - AUTHENTICATION_PLUGIN_CLASS: MySQLCachingSHA2PasswordAuthPlugin
2025-06-11 13:43:42 - INFO - [SERVIDOR INFO]: Teleoperador recibido: 9
2025-06-11 13:43:42 - INFO - [SERVIDOR INFO]: Teleoperador con ID 9 eliminado correctamente de la base de datos.
2025-06-11 13:43:52 - INFO - [SERVIDOR INFO]: Teleoperador recibido: 9
2025-06-11 13:43:52 - INFO - [SERVIDOR INFO]: Teleoperador con ID 9 eliminado correctamente de la base de datos.
2025-06-11 13:44:05 - ERROR - Unhandled exception in client_connected_cb
transport: <_ProactorSocketTransport closed>
Traceback (most recent call last):
  File "C:\Program Files\WindowsApps\PythonSoftwareFoundation.Python.3.13_3.13.1008.0_x64__qbz5n2kfra8p0\Lib\asyncio\windows_events.py", line 463, in finish_socket_func
    return ov.getresult()
           ~~~~~~~~~~~~^^
OSError: [WinError 64] El nombre de red especificado ya no está disponible

During handling of the above exception, another exception occurred:

Traceback (most recent call last):
  File "c:\Users\nzjha\Desktop\Clon_Github\python_serve\Async\sv.py", line 261, in server_on
    await teleoperador_MySQL(writer, reader)
  File "c:\Users\nzjha\Desktop\Clon_Github\python_serve\Async\sv.py", line 217, in teleoperador_MySQL
    await delete_teleoperador(writer, reader)
  File "c:\Users\nzjha\Desktop\Clon_Github\python_serve\Async\sv.py", line 57, in delete_teleoperador
    tele_id = (await reader.read(1024)).decode().strip()
               ^^^^^^^^^^^^^^^^^^^^^^^
  File "C:\Program Files\WindowsApps\PythonSoftwareFoundation.Python.3.13_3.13.1008.0_x64__qbz5n2kfra8p0\Lib\asyncio\streams.py", line 730, in read
    await self._wait_for_data('read')
  File "C:\Program Files\WindowsApps\PythonSoftwareFoundation.Python.3.13_3.13.1008.0_x64__qbz5n2kfra8p0\Lib\asyncio\streams.py", line 539, in _wait_for_data
    await self._waiter
  File "C:\Program Files\WindowsApps\PythonSoftwareFoundation.Python.3.13_3.13.1008.0_x64__qbz5n2kfra8p0\Lib\asyncio\proactor_events.py", line 286, in _loop_reading
    length = fut.result()
  File "C:\Program Files\WindowsApps\PythonSoftwareFoundation.Python.3.13_3.13.1008.0_x64__qbz5n2kfra8p0\Lib\asyncio\windows_events.py", line 804, in _poll
    value = callback(transferred, key, ov)
  File "C:\Program Files\WindowsApps\PythonSoftwareFoundation.Python.3.13_3.13.1008.0_x64__qbz5n2kfra8p0\Lib\asyncio\windows_events.py", line 467, in finish_socket_func
    raise ConnectionResetError(*exc.args)
ConnectionResetError: [WinError 64] El nombre de red especificado ya no está disponible
2025-06-11 13:44:21 - INFO - [SERVIDOR INFO]: Conexión desde ('127.0.0.1', 60938)
2025-06-11 13:44:26 - WARNING - [SERVIDOR WARNING]: == ESPERA AUTOMÁTICA DE 5 SEGUNDOS ==
2025-06-11 13:44:32 - INFO - [SERVIDOR INFO]: Consultando datos de teleoperador...
2025-06-11 13:44:44 - INFO - [SERVIDOR INFO]: Teleoperador recibido: 
2025-06-11 13:44:44 - ERROR - [SERVIDOR ERROR]: ID de teleoperador no válido
2025-06-11 13:44:44 - INFO - [SERVIDOR INFO]: Teleoperador recibido: 
2025-06-11 13:44:44 - ERROR - [SERVIDOR ERROR]: ID de teleoperador no válido
2025-06-11 13:44:44 - INFO - [SERVIDOR INFO]: Teleoperador recibido: 
2025-06-11 13:44:44 - ERROR - [SERVIDOR ERROR]: ID de teleoperador no válido
2025-06-11 13:44:44 - INFO - [SERVIDOR INFO]: Teleoperador recibido: 
2025-06-11 13:44:44 - ERROR - [SERVIDOR ERROR]: ID de teleoperador no válido
2025-06-11 13:44:44 - INFO - [SERVIDOR INFO]: Teleoperador recibido: 
2025-06-11 13:44:44 - ERROR - [SERVIDOR ERROR]: ID de teleoperador no válido
2025-06-11 13:44:44 - INFO - [SERVIDOR INFO]: Teleoperador recibido: 
2025-06-11 13:44:44 - ERROR - [SERVIDOR ERROR]: ID de teleoperador no válido
2025-06-11 13:44:44 - INFO - [SERVIDOR INFO]: Teleoperador recibido: 
2025-06-11 13:44:44 - ERROR - [SERVIDOR ERROR]: ID de teleoperador no válido
2025-06-11 13:44:44 - INFO - [SERVIDOR INFO]: Teleoperador recibido: 
2025-06-11 13:44:44 - ERROR - [SERVIDOR ERROR]: ID de teleoperador no válido
2025-06-11 13:44:44 - INFO - [SERVIDOR INFO]: Teleoperador recibido: 
2025-06-11 13:44:44 - ERROR - [SERVIDOR ERROR]: ID de teleoperador no válido
2025-06-11 13:44:44 - INFO - [SERVIDOR INFO]: Teleoperador recibido: 
2025-06-11 13:44:44 - ERROR - [SERVIDOR ERROR]: ID de teleoperador no válido
2025-06-11 13:44:44 - INFO - [SERVIDOR INFO]: Teleoperador recibido: 
2025-06-11 13:44:44 - ERROR - [SERVIDOR ERROR]: ID de teleoperador no válido
2025-06-11 13:44:44 - INFO - [SERVIDOR INFO]: Teleoperador recibido: 
2025-06-11 13:44:44 - ERROR - [SERVIDOR ERROR]: ID de teleoperador no válido
2025-06-11 13:44:44 - INFO - [SERVIDOR INFO]: Teleoperador recibido: 
2025-06-11 13:44:44 - ERROR - [SERVIDOR ERROR]: ID de teleoperador no válido
2025-06-11 13:44:44 - INFO - [SERVIDOR INFO]: Teleoperador recibido: 
2025-06-11 13:44:44 - ERROR - [SERVIDOR ERROR]: ID de teleoperador no válido
2025-06-11 13:44:44 - INFO - [SERVIDOR INFO]: Teleoperador recibido: 
2025-06-11 13:44:44 - ERROR - [SERVIDOR ERROR]: ID de teleoperador no válido
2025-06-11 13:44:44 - INFO - [SERVIDOR INFO]: Teleoperador recibido: 
2025-06-11 13:44:44 - ERROR - [SERVIDOR ERROR]: ID de teleoperador no válido
2025-06-11 13:44:44 - INFO - [SERVIDOR INFO]: Teleoperador recibido: 
2025-06-11 13:44:44 - ERROR - [SERVIDOR ERROR]: ID de teleoperador no válido
2025-06-11 13:44:44 - INFO - [SERVIDOR INFO]: Teleoperador recibido: 
2025-06-11 13:44:44 - ERROR - [SERVIDOR ERROR]: ID de teleoperador no válido
2025-06-11 13:44:44 - INFO - [SERVIDOR INFO]: Teleoperador recibido: 
2025-06-11 13:44:44 - ERROR - [SERVIDOR ERROR]: ID de teleoperador no válido
2025-06-11 13:44:44 - INFO - [SERVIDOR INFO]: Teleoperador recibido: 
2025-06-11 13:44:44 - ERROR - [SERVIDOR ERROR]: ID de teleoperador no válido
2025-06-11 13:44:44 - INFO - [SERVIDOR INFO]: Teleoperador recibido: 
2025-06-11 13:44:44 - ERROR - [SERVIDOR ERROR]: ID de teleoperador no válido
2025-06-11 13:44:44 - INFO - [SERVIDOR INFO]: Teleoperador recibido: 
2025-06-11 13:44:44 - ERROR - [SERVIDOR ERROR]: ID de teleoperador no válido
2025-06-11 13:44:44 - INFO - [SERVIDOR INFO]: Teleoperador recibido: 
2025-06-11 13:44:44 - ERROR - [SERVIDOR ERROR]: ID de teleoperador no válido
2025-06-11 13:44:44 - INFO - [SERVIDOR INFO]: Teleoperador recibido: 
2025-06-11 13:44:44 - ERROR - [SERVIDOR ERROR]: ID de teleoperador no válido
2025-06-11 13:44:44 - INFO - [SERVIDOR INFO]: Teleoperador recibido: 
2025-06-11 13:44:44 - ERROR - [SERVIDOR ERROR]: ID de teleoperador no válido
2025-06-11 13:44:44 - INFO - [SERVIDOR INFO]: Teleoperador recibido: 
2025-06-11 13:44:44 - ERROR - [SERVIDOR ERROR]: ID de teleoperador no válido
2025-06-11 13:44:44 - INFO - [SERVIDOR INFO]: Teleoperador recibido: 
2025-06-11 13:44:44 - ERROR - [SERVIDOR ERROR]: ID de teleoperador no válido
2025-06-11 13:44:44 - INFO - [SERVIDOR INFO]: Teleoperador recibido: 
2025-06-11 13:44:44 - ERROR - [SERVIDOR ERROR]: ID de teleoperador no válido
2025-06-11 13:44:44 - INFO - [SERVIDOR INFO]: Teleoperador recibido: 
2025-06-11 13:44:44 - ERROR - [SERVIDOR ERROR]: ID de teleoperador no válido
2025-06-11 13:44:44 - INFO - [SERVIDOR INFO]: Teleoperador recibido: 
2025-06-11 13:44:44 - ERROR - [SERVIDOR ERROR]: ID de teleoperador no válido
2025-06-11 13:44:44 - INFO - [SERVIDOR INFO]: Teleoperador recibido: 
2025-06-11 13:44:44 - ERROR - [SERVIDOR ERROR]: ID de teleoperador no válido
2025-06-11 13:44:44 - INFO - [SERVIDOR INFO]: Teleoperador recibido: 
2025-06-11 13:44:44 - ERROR - [SERVIDOR ERROR]: ID de teleoperador no válido
2025-06-11 13:44:44 - INFO - [SERVIDOR INFO]: Teleoperador recibido: 
2025-06-11 13:44:44 - ERROR - [SERVIDOR ERROR]: ID de teleoperador no válido
2025-06-11 13:44:44 - INFO - [SERVIDOR INFO]: Teleoperador recibido: 
2025-06-11 13:44:44 - ERROR - [SERVIDOR ERROR]: ID de teleoperador no válido
2025-06-11 13:44:44 - INFO - [SERVIDOR INFO]: Teleoperador recibido: 
2025-06-11 13:44:44 - ERROR - [SERVIDOR ERROR]: ID de teleoperador no válido
2025-06-11 13:44:44 - INFO - [SERVIDOR INFO]: Teleoperador recibido: 
2025-06-11 13:44:44 - ERROR - [SERVIDOR ERROR]: ID de teleoperador no válido
2025-06-11 13:44:44 - INFO - [SERVIDOR INFO]: Teleoperador recibido: 
2025-06-11 13:44:44 - ERROR - [SERVIDOR ERROR]: ID de teleoperador no válido
2025-06-11 13:44:44 - INFO - [SERVIDOR INFO]: Teleoperador recibido: 
2025-06-11 13:44:44 - ERROR - [SERVIDOR ERROR]: ID de teleoperador no válido
2025-06-11 13:44:44 - INFO - [SERVIDOR INFO]: Teleoperador recibido: 
2025-06-11 13:44:44 - ERROR - [SERVIDOR ERROR]: ID de teleoperador no válido
2025-06-11 13:44:44 - INFO - [SERVIDOR INFO]: Teleoperador recibido: 
2025-06-11 13:44:44 - ERROR - [SERVIDOR ERROR]: ID de teleoperador no válido
2025-06-11 13:44:44 - INFO - [SERVIDOR INFO]: Teleoperador recibido: 
2025-06-11 13:44:44 - ERROR - [SERVIDOR ERROR]: ID de teleoperador no válido
2025-06-11 13:44:44 - INFO - [SERVIDOR INFO]: Teleoperador recibido: 
2025-06-11 13:44:44 - ERROR - [SERVIDOR ERROR]: ID de teleoperador no válido
2025-06-11 13:44:44 - INFO - [SERVIDOR INFO]: Teleoperador recibido: 
2025-06-11 13:44:44 - ERROR - [SERVIDOR ERROR]: ID de teleoperador no válido
2025-06-11 13:44:44 - INFO - [SERVIDOR INFO]: Teleoperador recibido: 
2025-06-11 13:44:44 - ERROR - [SERVIDOR ERROR]: ID de teleoperador no válido
2025-06-11 13:44:44 - INFO - [SERVIDOR INFO]: Teleoperador recibido: 
2025-06-11 13:44:44 - ERROR - [SERVIDOR ERROR]: ID de teleoperador no válido
2025-06-11 13:44:44 - INFO - [SERVIDOR INFO]: Teleoperador recibido: 
2025-06-11 13:44:44 - ERROR - [SERVIDOR ERROR]: ID de teleoperador no válido
2025-06-11 13:44:44 - INFO - [SERVIDOR INFO]: Teleoperador recibido: 
2025-06-11 13:44:44 - ERROR - [SERVIDOR ERROR]: ID de teleoperador no válido
2025-06-11 13:44:44 - INFO - [SERVIDOR INFO]: Teleoperador recibido: 
2025-06-11 13:44:44 - ERROR - [SERVIDOR ERROR]: ID de teleoperador no válido
2025-06-11 13:44:44 - INFO - [SERVIDOR INFO]: Teleoperador recibido: 
2025-06-11 13:44:44 - ERROR - [SERVIDOR ERROR]: ID de teleoperador no válido
2025-06-11 13:44:44 - INFO - [SERVIDOR INFO]: Teleoperador recibido: 
2025-06-11 13:44:44 - ERROR - [SERVIDOR ERROR]: ID de teleoperador no válido
2025-06-11 13:44:44 - INFO - [SERVIDOR INFO]: Teleoperador recibido: 
2025-06-11 13:44:44 - ERROR - [SERVIDOR ERROR]: ID de teleoperador no válido
2025-06-11 13:44:44 - INFO - [SERVIDOR INFO]: Teleoperador recibido: 
2025-06-11 13:44:44 - ERROR - [SERVIDOR ERROR]: ID de teleoperador no válido
2025-06-11 13:44:44 - INFO - [SERVIDOR INFO]: Teleoperador recibido: 
2025-06-11 13:44:44 - ERROR - [SERVIDOR ERROR]: ID de teleoperador no válido
2025-06-11 13:44:44 - INFO - [SERVIDOR INFO]: Teleoperador recibido: 
2025-06-11 13:44:44 - ERROR - [SERVIDOR ERROR]: ID de teleoperador no válido
2025-06-11 13:44:44 - INFO - [SERVIDOR INFO]: Teleoperador recibido: 
2025-06-11 13:44:44 - ERROR - [SERVIDOR ERROR]: ID de teleoperador no válido
2025-06-11 13:44:44 - INFO - [SERVIDOR INFO]: Teleoperador recibido: 
2025-06-11 13:44:44 - ERROR - [SERVIDOR ERROR]: ID de teleoperador no válido
2025-06-11 13:44:44 - INFO - [SERVIDOR INFO]: Teleoperador recibido: 
2025-06-11 13:44:44 - ERROR - [SERVIDOR ERROR]: ID de teleoperador no válido
2025-06-11 13:44:44 - INFO - [SERVIDOR INFO]: Teleoperador recibido: 
2025-06-11 13:44:44 - ERROR - [SERVIDOR ERROR]: ID de teleoperador no válido
2025-06-11 13:44:44 - INFO - [SERVIDOR INFO]: Teleoperador recibido: 
2025-06-11 13:44:44 - ERROR - [SERVIDOR ERROR]: ID de teleoperador no válido
2025-06-11 13:44:44 - INFO - [SERVIDOR INFO]: Teleoperador recibido: 
2025-06-11 13:44:44 - ERROR - [SERVIDOR ERROR]: ID de teleoperador no válido
2025-06-11 13:44:44 - INFO - [SERVIDOR INFO]: Teleoperador recibido: 
2025-06-11 13:44:44 - ERROR - [SERVIDOR ERROR]: ID de teleoperador no válido
2025-06-11 13:44:44 - INFO - [SERVIDOR INFO]: Teleoperador recibido: 
2025-06-11 13:44:44 - ERROR - [SERVIDOR ERROR]: ID de teleoperador no válido
2025-06-11 13:44:44 - INFO - [SERVIDOR INFO]: Teleoperador recibido: 
2025-06-11 13:44:44 - ERROR - [SERVIDOR ERROR]: ID de teleoperador no válido
2025-06-11 13:44:44 - INFO - [SERVIDOR INFO]: Teleoperador recibido: 
2025-06-11 13:44:44 - ERROR - [SERVIDOR ERROR]: ID de teleoperador no válido
2025-06-11 13:44:44 - INFO - [SERVIDOR INFO]: Teleoperador recibido: 
2025-06-11 13:44:44 - ERROR - [SERVIDOR ERROR]: ID de teleoperador no válido
2025-06-11 13:44:44 - INFO - [SERVIDOR INFO]: Teleoperador recibido: 
2025-06-11 13:44:44 - ERROR - [SERVIDOR ERROR]: ID de teleoperador no válido
2025-06-11 13:44:44 - INFO - [SERVIDOR INFO]: Teleoperador recibido: 
2025-06-11 13:44:44 - ERROR - [SERVIDOR ERROR]: ID de teleoperador no válido
2025-06-11 13:44:44 - INFO - [SERVIDOR INFO]: Teleoperador recibido: 
2025-06-11 13:44:44 - ERROR - [SERVIDOR ERROR]: ID de teleoperador no válido
2025-06-11 13:44:44 - INFO - [SERVIDOR INFO]: Teleoperador recibido: 
2025-06-11 13:44:44 - ERROR - [SERVIDOR ERROR]: ID de teleoperador no válido
2025-06-11 13:44:44 - INFO - [SERVIDOR INFO]: Teleoperador recibido: 
2025-06-11 13:44:44 - ERROR - [SERVIDOR ERROR]: ID de teleoperador no válido
2025-06-11 13:44:44 - INFO - [SERVIDOR INFO]: Teleoperador recibido: 
2025-06-11 13:44:44 - ERROR - [SERVIDOR ERROR]: ID de teleoperador no válido
2025-06-11 13:44:44 - INFO - [SERVIDOR INFO]: Teleoperador recibido: 
2025-06-11 13:44:44 - ERROR - [SERVIDOR ERROR]: ID de teleoperador no válido
2025-06-11 13:44:44 - INFO - [SERVIDOR INFO]: Teleoperador recibido: 
2025-06-11 13:44:44 - ERROR - [SERVIDOR ERROR]: ID de teleoperador no válido
2025-06-11 13:44:44 - INFO - [SERVIDOR INFO]: Teleoperador recibido: 
2025-06-11 13:44:44 - ERROR - [SERVIDOR ERROR]: ID de teleoperador no válido
2025-06-11 13:44:44 - INFO - [SERVIDOR INFO]: Teleoperador recibido: 
2025-06-11 13:44:44 - ERROR - [SERVIDOR ERROR]: ID de teleoperador no válido
2025-06-11 13:44:44 - INFO - [SERVIDOR INFO]: Teleoperador recibido: 
2025-06-11 13:44:44 - ERROR - [SERVIDOR ERROR]: ID de teleoperador no válido
2025-06-11 13:44:44 - INFO - [SERVIDOR INFO]: Teleoperador recibido: 
2025-06-11 13:44:44 - ERROR - [SERVIDOR ERROR]: ID de teleoperador no válido
2025-06-11 13:44:44 - INFO - [SERVIDOR INFO]: Teleoperador recibido: 
2025-06-11 13:44:44 - ERROR - [SERVIDOR ERROR]: ID de teleoperador no válido
2025-06-11 13:44:44 - INFO - [SERVIDOR INFO]: Teleoperador recibido: 
2025-06-11 13:44:44 - ERROR - [SERVIDOR ERROR]: ID de teleoperador no válido
2025-06-11 13:44:44 - INFO - [SERVIDOR INFO]: Teleoperador recibido: 
2025-06-11 13:44:44 - ERROR - [SERVIDOR ERROR]: ID de teleoperador no válido
2025-06-11 13:44:44 - INFO - [SERVIDOR INFO]: Teleoperador recibido: 
2025-06-11 13:44:44 - ERROR - [SERVIDOR ERROR]: ID de teleoperador no válido
2025-06-11 13:44:44 - INFO - [SERVIDOR INFO]: Teleoperador recibido: 
2025-06-11 13:44:44 - ERROR - [SERVIDOR ERROR]: ID de teleoperador no válido
2025-06-11 13:44:44 - INFO - [SERVIDOR INFO]: Teleoperador recibido: 
2025-06-11 13:44:44 - ERROR - [SERVIDOR ERROR]: ID de teleoperador no válido
2025-06-11 13:44:44 - INFO - [SERVIDOR INFO]: Teleoperador recibido: 
2025-06-11 13:44:44 - ERROR - [SERVIDOR ERROR]: ID de teleoperador no válido
2025-06-11 13:44:44 - INFO - [SERVIDOR INFO]: Teleoperador recibido: 
2025-06-11 13:44:44 - ERROR - [SERVIDOR ERROR]: ID de teleoperador no válido
2025-06-11 13:44:44 - INFO - [SERVIDOR INFO]: Teleoperador recibido: 
2025-06-11 13:44:44 - ERROR - [SERVIDOR ERROR]: ID de teleoperador no válido
2025-06-11 13:44:44 - INFO - [SERVIDOR INFO]: Teleoperador recibido: 
2025-06-11 13:44:44 - ERROR - [SERVIDOR ERROR]: ID de teleoperador no válido
2025-06-11 13:44:44 - INFO - [SERVIDOR INFO]: Teleoperador recibido: 
2025-06-11 13:44:44 - ERROR - [SERVIDOR ERROR]: ID de teleoperador no válido
2025-06-11 13:44:44 - INFO - [SERVIDOR INFO]: Teleoperador recibido: 
2025-06-11 13:44:44 - ERROR - [SERVIDOR ERROR]: ID de teleoperador no válido
2025-06-11 13:44:44 - INFO - [SERVIDOR INFO]: Teleoperador recibido: 
2025-06-11 13:44:44 - ERROR - [SERVIDOR ERROR]: ID de teleoperador no válido
2025-06-11 13:44:44 - INFO - [SERVIDOR INFO]: Teleoperador recibido: 
2025-06-11 13:44:44 - ERROR - [SERVIDOR ERROR]: ID de teleoperador no válido
2025-06-11 13:44:44 - INFO - [SERVIDOR INFO]: Teleoperador recibido: 
2025-06-11 13:44:44 - ERROR - [SERVIDOR ERROR]: ID de teleoperador no válido
2025-06-11 13:44:44 - INFO - [SERVIDOR INFO]: Teleoperador recibido: 
2025-06-11 13:44:44 - ERROR - [SERVIDOR ERROR]: ID de teleoperador no válido
2025-06-11 13:44:44 - INFO - [SERVIDOR INFO]: Teleoperador recibido: 
2025-06-11 13:44:44 - ERROR - [SERVIDOR ERROR]: ID de teleoperador no válido
2025-06-11 13:44:44 - INFO - [SERVIDOR INFO]: Teleoperador recibido: 
2025-06-11 13:44:44 - ERROR - [SERVIDOR ERROR]: ID de teleoperador no válido
2025-06-11 13:44:44 - INFO - [SERVIDOR INFO]: Teleoperador recibido: 
2025-06-11 13:44:44 - ERROR - [SERVIDOR ERROR]: ID de teleoperador no válido
2025-06-11 13:44:44 - INFO - [SERVIDOR INFO]: Teleoperador recibido: 
2025-06-11 13:44:44 - ERROR - [SERVIDOR ERROR]: ID de teleoperador no válido
2025-06-11 13:44:44 - INFO - [SERVIDOR INFO]: Teleoperador recibido: 
2025-06-11 13:44:44 - ERROR - [SERVIDOR ERROR]: ID de teleoperador no válido
2025-06-11 13:44:44 - INFO - [SERVIDOR INFO]: Teleoperador recibido: 
2025-06-11 13:44:44 - ERROR - [SERVIDOR ERROR]: ID de teleoperador no válido
2025-06-11 13:44:44 - INFO - [SERVIDOR INFO]: Teleoperador recibido: 
2025-06-11 13:44:44 - ERROR - [SERVIDOR ERROR]: ID de teleoperador no válido
2025-06-11 13:44:44 - INFO - [SERVIDOR INFO]: Teleoperador recibido: 
2025-06-11 13:44:44 - ERROR - [SERVIDOR ERROR]: ID de teleoperador no válido
2025-06-11 13:44:44 - INFO - [SERVIDOR INFO]: Teleoperador recibido: 
2025-06-11 13:44:44 - ERROR - [SERVIDOR ERROR]: ID de teleoperador no válido
2025-06-11 13:44:44 - INFO - [SERVIDOR INFO]: Teleoperador recibido: 
2025-06-11 13:44:44 - ERROR - [SERVIDOR ERROR]: ID de teleoperador no válido
2025-06-11 13:44:44 - INFO - [SERVIDOR INFO]: Teleoperador recibido: 
2025-06-11 13:44:44 - ERROR - [SERVIDOR ERROR]: ID de teleoperador no válido
2025-06-11 13:44:44 - INFO - [SERVIDOR INFO]: Teleoperador recibido: 
2025-06-11 13:44:44 - ERROR - [SERVIDOR ERROR]: ID de teleoperador no válido
2025-06-11 13:44:44 - INFO - [SERVIDOR INFO]: Teleoperador recibido: 
2025-06-11 13:44:44 - ERROR - [SERVIDOR ERROR]: ID de teleoperador no válido
2025-06-11 13:44:44 - INFO - [SERVIDOR INFO]: Teleoperador recibido: 
2025-06-11 13:44:44 - ERROR - [SERVIDOR ERROR]: ID de teleoperador no válido
2025-06-11 13:44:44 - INFO - [SERVIDOR INFO]: Teleoperador recibido: 
2025-06-11 13:44:44 - ERROR - [SERVIDOR ERROR]: ID de teleoperador no válido
2025-06-11 13:44:44 - INFO - [SERVIDOR INFO]: Teleoperador recibido: 
2025-06-11 13:44:44 - ERROR - [SERVIDOR ERROR]: ID de teleoperador no válido
2025-06-11 13:44:44 - INFO - [SERVIDOR INFO]: Teleoperador recibido: 
2025-06-11 13:44:44 - ERROR - [SERVIDOR ERROR]: ID de teleoperador no válido
2025-06-11 13:44:44 - INFO - [SERVIDOR INFO]: Teleoperador recibido: 
2025-06-11 13:44:44 - ERROR - [SERVIDOR ERROR]: ID de teleoperador no válido
2025-06-11 13:44:44 - INFO - [SERVIDOR INFO]: Teleoperador recibido: 
2025-06-11 13:44:44 - ERROR - [SERVIDOR ERROR]: ID de teleoperador no válido
2025-06-11 13:44:44 - INFO - [SERVIDOR INFO]: Teleoperador recibido: 
2025-06-11 13:44:44 - ERROR - [SERVIDOR ERROR]: ID de teleoperador no válido
2025-06-11 13:44:44 - INFO - [SERVIDOR INFO]: Teleoperador recibido: 
2025-06-11 13:44:44 - ERROR - [SERVIDOR ERROR]: ID de teleoperador no válido
2025-06-11 13:44:44 - INFO - [SERVIDOR INFO]: Teleoperador recibido: 
2025-06-11 13:44:44 - ERROR - [SERVIDOR ERROR]: ID de teleoperador no válido
2025-06-11 13:44:44 - INFO - [SERVIDOR INFO]: Teleoperador recibido: 
2025-06-11 13:44:44 - ERROR - [SERVIDOR ERROR]: ID de teleoperador no válido
2025-06-11 13:44:44 - INFO - [SERVIDOR INFO]: Teleoperador recibido: 
2025-06-11 13:44:44 - ERROR - [SERVIDOR ERROR]: ID de teleoperador no válido
2025-06-11 13:44:44 - INFO - [SERVIDOR INFO]: Teleoperador recibido: 
2025-06-11 13:44:44 - ERROR - [SERVIDOR ERROR]: ID de teleoperador no válido
2025-06-11 13:44:44 - INFO - [SERVIDOR INFO]: Teleoperador recibido: 
2025-06-11 13:44:44 - ERROR - [SERVIDOR ERROR]: ID de teleoperador no válido
2025-06-11 13:44:44 - INFO - [SERVIDOR INFO]: Teleoperador recibido: 
2025-06-11 13:44:44 - ERROR - [SERVIDOR ERROR]: ID de teleoperador no válido
2025-06-11 13:44:44 - INFO - [SERVIDOR INFO]: Teleoperador recibido: 
2025-06-11 13:44:44 - ERROR - [SERVIDOR ERROR]: ID de teleoperador no válido
2025-06-11 13:44:44 - INFO - [SERVIDOR INFO]: Teleoperador recibido: 
2025-06-11 13:44:44 - ERROR - [SERVIDOR ERROR]: ID de teleoperador no válido
2025-06-11 13:44:44 - INFO - [SERVIDOR INFO]: Teleoperador recibido: 
2025-06-11 13:44:44 - ERROR - [SERVIDOR ERROR]: ID de teleoperador no válido
2025-06-11 13:44:44 - INFO - [SERVIDOR INFO]: Teleoperador recibido: 
2025-06-11 13:44:44 - ERROR - [SERVIDOR ERROR]: ID de teleoperador no válido
2025-06-11 13:44:44 - INFO - [SERVIDOR INFO]: Teleoperador recibido: 
2025-06-11 13:44:44 - ERROR - [SERVIDOR ERROR]: ID de teleoperador no válido
2025-06-11 13:44:44 - INFO - [SERVIDOR INFO]: Teleoperador recibido: 
2025-06-11 13:44:44 - ERROR - [SERVIDOR ERROR]: ID de teleoperador no válido
2025-06-11 13:44:44 - INFO - [SERVIDOR INFO]: Teleoperador recibido: 
2025-06-11 13:44:44 - ERROR - [SERVIDOR ERROR]: ID de teleoperador no válido
2025-06-11 13:44:44 - INFO - [SERVIDOR INFO]: Teleoperador recibido: 
2025-06-11 13:44:44 - ERROR - [SERVIDOR ERROR]: ID de teleoperador no válido
2025-06-11 13:44:44 - INFO - [SERVIDOR INFO]: Teleoperador recibido: 
2025-06-11 13:44:44 - ERROR - [SERVIDOR ERROR]: ID de teleoperador no válido
2025-06-11 13:44:44 - INFO - [SERVIDOR INFO]: Teleoperador recibido: 
2025-06-11 13:44:44 - ERROR - [SERVIDOR ERROR]: ID de teleoperador no válido
2025-06-11 13:44:44 - INFO - [SERVIDOR INFO]: Teleoperador recibido: 
2025-06-11 13:44:44 - ERROR - [SERVIDOR ERROR]: ID de teleoperador no válido
2025-06-11 13:44:44 - INFO - [SERVIDOR INFO]: Teleoperador recibido: 
2025-06-11 13:44:44 - ERROR - [SERVIDOR ERROR]: ID de teleoperador no válido
2025-06-11 13:44:44 - INFO - [SERVIDOR INFO]: Teleoperador recibido: 
2025-06-11 13:44:44 - ERROR - [SERVIDOR ERROR]: ID de teleoperador no válido
2025-06-11 13:44:44 - INFO - [SERVIDOR INFO]: Teleoperador recibido: 
2025-06-11 13:44:44 - ERROR - [SERVIDOR ERROR]: ID de teleoperador no válido
2025-06-11 13:44:44 - INFO - [SERVIDOR INFO]: Teleoperador recibido: 
2025-06-11 13:44:44 - ERROR - [SERVIDOR ERROR]: ID de teleoperador no válido
2025-06-11 13:44:44 - INFO - [SERVIDOR INFO]: Teleoperador recibido: 
2025-06-11 13:44:44 - ERROR - [SERVIDOR ERROR]: ID de teleoperador no válido
2025-06-11 13:44:44 - INFO - [SERVIDOR INFO]: Teleoperador recibido: 
2025-06-11 13:44:44 - ERROR - [SERVIDOR ERROR]: ID de teleoperador no válido
2025-06-11 13:44:44 - INFO - [SERVIDOR INFO]: Teleoperador recibido: 
2025-06-11 13:44:44 - ERROR - [SERVIDOR ERROR]: ID de teleoperador no válido
2025-06-11 13:44:44 - INFO - [SERVIDOR INFO]: Teleoperador recibido: 
2025-06-11 13:44:44 - ERROR - [SERVIDOR ERROR]: ID de teleoperador no válido
2025-06-11 13:44:44 - INFO - [SERVIDOR INFO]: Teleoperador recibido: 
2025-06-11 13:44:44 - ERROR - [SERVIDOR ERROR]: ID de teleoperador no válido
2025-06-11 13:44:44 - INFO - [SERVIDOR INFO]: Teleoperador recibido: 
2025-06-11 13:44:44 - ERROR - [SERVIDOR ERROR]: ID de teleoperador no válido
2025-06-11 13:44:44 - INFO - [SERVIDOR INFO]: Teleoperador recibido: 
2025-06-11 13:44:44 - ERROR - [SERVIDOR ERROR]: ID de teleoperador no válido
2025-06-11 13:44:44 - INFO - [SERVIDOR INFO]: Teleoperador recibido: 
2025-06-11 13:44:44 - ERROR - [SERVIDOR ERROR]: ID de teleoperador no válido
2025-06-11 13:44:44 - INFO - [SERVIDOR INFO]: Teleoperador recibido: 
2025-06-11 13:44:44 - ERROR - [SERVIDOR ERROR]: ID de teleoperador no válido
2025-06-11 13:44:44 - INFO - [SERVIDOR INFO]: Teleoperador recibido: 
2025-06-11 13:44:44 - ERROR - [SERVIDOR ERROR]: ID de teleoperador no válido
2025-06-11 13:44:44 - INFO - [SERVIDOR INFO]: Teleoperador recibido: 
2025-06-11 13:44:44 - ERROR - [SERVIDOR ERROR]: ID de teleoperador no válido
2025-06-11 13:44:44 - INFO - [SERVIDOR INFO]: Teleoperador recibido: 
2025-06-11 13:44:44 - ERROR - [SERVIDOR ERROR]: ID de teleoperador no válido
2025-06-11 13:44:44 - INFO - [SERVIDOR INFO]: Teleoperador recibido: 
2025-06-11 13:44:44 - ERROR - [SERVIDOR ERROR]: ID de teleoperador no válido
2025-06-11 13:44:44 - INFO - [SERVIDOR INFO]: Teleoperador recibido: 
2025-06-11 13:44:44 - ERROR - [SERVIDOR ERROR]: ID de teleoperador no válido
2025-06-11 13:44:44 - INFO - [SERVIDOR INFO]: Teleoperador recibido: 
2025-06-11 13:44:44 - ERROR - [SERVIDOR ERROR]: ID de teleoperador no válido
2025-06-11 13:44:44 - INFO - [SERVIDOR INFO]: Teleoperador recibido: 
2025-06-11 13:44:44 - ERROR - [SERVIDOR ERROR]: ID de teleoperador no válido
2025-06-11 13:44:44 - INFO - [SERVIDOR INFO]: Teleoperador recibido: 
2025-06-11 13:44:44 - ERROR - [SERVIDOR ERROR]: ID de teleoperador no válido
2025-06-11 13:44:44 - INFO - [SERVIDOR INFO]: Teleoperador recibido: 
2025-06-11 13:44:44 - ERROR - [SERVIDOR ERROR]: ID de teleoperador no válido
2025-06-11 13:44:44 - INFO - [SERVIDOR INFO]: Teleoperador recibido: 
2025-06-11 13:44:44 - ERROR - [SERVIDOR ERROR]: ID de teleoperador no válido
2025-06-11 13:44:44 - INFO - [SERVIDOR INFO]: Teleoperador recibido: 
2025-06-11 13:44:44 - ERROR - [SERVIDOR ERROR]: ID de teleoperador no válido
2025-06-11 13:44:44 - INFO - [SERVIDOR INFO]: Teleoperador recibido: 
2025-06-11 13:44:44 - ERROR - [SERVIDOR ERROR]: ID de teleoperador no válido
2025-06-11 13:44:44 - INFO - [SERVIDOR INFO]: Teleoperador recibido: 
2025-06-11 13:44:44 - ERROR - [SERVIDOR ERROR]: ID de teleoperador no válido
2025-06-11 13:44:44 - INFO - [SERVIDOR INFO]: Teleoperador recibido: 
2025-06-11 13:44:44 - ERROR - [SERVIDOR ERROR]: ID de teleoperador no válido
2025-06-11 13:44:44 - INFO - [SERVIDOR INFO]: Teleoperador recibido: 
2025-06-11 13:44:44 - ERROR - [SERVIDOR ERROR]: ID de teleoperador no válido
2025-06-11 13:44:44 - INFO - [SERVIDOR INFO]: Teleoperador recibido: 
2025-06-11 13:44:44 - ERROR - [SERVIDOR ERROR]: ID de teleoperador no válido
2025-06-11 13:44:44 - INFO - [SERVIDOR INFO]: Teleoperador recibido: 
2025-06-11 13:44:44 - ERROR - [SERVIDOR ERROR]: ID de teleoperador no válido
2025-06-11 13:44:44 - INFO - [SERVIDOR INFO]: Teleoperador recibido: 
2025-06-11 13:44:44 - ERROR - [SERVIDOR ERROR]: ID de teleoperador no válido
2025-06-11 13:44:44 - INFO - [SERVIDOR INFO]: Teleoperador recibido: 
2025-06-11 13:44:44 - ERROR - [SERVIDOR ERROR]: ID de teleoperador no válido
2025-06-11 13:44:44 - INFO - [SERVIDOR INFO]: Teleoperador recibido: 
2025-06-11 13:44:44 - ERROR - [SERVIDOR ERROR]: ID de teleoperador no válido
2025-06-11 13:44:44 - INFO - [SERVIDOR INFO]: Teleoperador recibido: 
2025-06-11 13:44:44 - ERROR - [SERVIDOR ERROR]: ID de teleoperador no válido
2025-06-11 13:44:44 - INFO - [SERVIDOR INFO]: Teleoperador recibido: 
2025-06-11 13:44:44 - ERROR - [SERVIDOR ERROR]: ID de teleoperador no válido
2025-06-11 13:44:44 - INFO - [SERVIDOR INFO]: Teleoperador recibido: 
2025-06-11 13:44:44 - ERROR - [SERVIDOR ERROR]: ID de teleoperador no válido
2025-06-11 13:44:44 - INFO - [SERVIDOR INFO]: Teleoperador recibido: 
2025-06-11 13:44:44 - ERROR - [SERVIDOR ERROR]: ID de teleoperador no válido
2025-06-11 13:44:44 - INFO - [SERVIDOR INFO]: Teleoperador recibido: 
2025-06-11 13:44:44 - ERROR - [SERVIDOR ERROR]: ID de teleoperador no válido
2025-06-11 13:44:44 - INFO - [SERVIDOR INFO]: Teleoperador recibido: 
2025-06-11 13:44:44 - ERROR - [SERVIDOR ERROR]: ID de teleoperador no válido
2025-06-11 13:44:44 - INFO - [SERVIDOR INFO]: Teleoperador recibido: 
2025-06-11 13:44:44 - ERROR - [SERVIDOR ERROR]: ID de teleoperador no válido
2025-06-11 13:44:44 - INFO - [SERVIDOR INFO]: Teleoperador recibido: 
2025-06-11 13:44:44 - ERROR - [SERVIDOR ERROR]: ID de teleoperador no válido
2025-06-11 13:44:44 - INFO - [SERVIDOR INFO]: Teleoperador recibido: 
2025-06-11 13:44:44 - ERROR - [SERVIDOR ERROR]: ID de teleoperador no válido
2025-06-11 13:44:44 - INFO - [SERVIDOR INFO]: Teleoperador recibido: 
2025-06-11 13:44:44 - ERROR - [SERVIDOR ERROR]: ID de teleoperador no válido
2025-06-11 13:44:44 - INFO - [SERVIDOR INFO]: Teleoperador recibido: 
2025-06-11 13:44:44 - ERROR - [SERVIDOR ERROR]: ID de teleoperador no válido
2025-06-11 13:44:44 - INFO - [SERVIDOR INFO]: Teleoperador recibido: 
2025-06-11 13:44:44 - ERROR - [SERVIDOR ERROR]: ID de teleoperador no válido
2025-06-11 13:44:44 - INFO - [SERVIDOR INFO]: Teleoperador recibido: 
2025-06-11 13:44:44 - ERROR - [SERVIDOR ERROR]: ID de teleoperador no válido
2025-06-11 13:44:44 - INFO - [SERVIDOR INFO]: Teleoperador recibido: 
2025-06-11 13:44:44 - ERROR - [SERVIDOR ERROR]: ID de teleoperador no válido
2025-06-11 13:44:44 - INFO - [SERVIDOR INFO]: Teleoperador recibido: 
2025-06-11 13:44:44 - ERROR - [SERVIDOR ERROR]: ID de teleoperador no válido
2025-06-11 13:44:44 - INFO - [SERVIDOR INFO]: Teleoperador recibido: 
2025-06-11 13:44:44 - ERROR - [SERVIDOR ERROR]: ID de teleoperador no válido
2025-06-11 13:44:44 - INFO - [SERVIDOR INFO]: Teleoperador recibido: 
2025-06-11 13:44:44 - ERROR - [SERVIDOR ERROR]: ID de teleoperador no válido
2025-06-11 13:44:44 - INFO - [SERVIDOR INFO]: Teleoperador recibido: 
2025-06-11 13:44:44 - ERROR - [SERVIDOR ERROR]: ID de teleoperador no válido
2025-06-11 13:44:44 - INFO - [SERVIDOR INFO]: Teleoperador recibido: 
2025-06-11 13:44:44 - ERROR - [SERVIDOR ERROR]: ID de teleoperador no válido
2025-06-11 13:44:44 - INFO - [SERVIDOR INFO]: Teleoperador recibido: 
2025-06-11 13:44:44 - ERROR - [SERVIDOR ERROR]: ID de teleoperador no válido
2025-06-11 13:44:44 - INFO - [SERVIDOR INFO]: Teleoperador recibido: 
2025-06-11 13:44:44 - ERROR - [SERVIDOR ERROR]: ID de teleoperador no válido
2025-06-11 13:44:44 - INFO - [SERVIDOR INFO]: Teleoperador recibido: 
2025-06-11 13:44:44 - ERROR - [SERVIDOR ERROR]: ID de teleoperador no válido
2025-06-11 13:44:44 - INFO - [SERVIDOR INFO]: Teleoperador recibido: 
2025-06-11 13:44:44 - ERROR - [SERVIDOR ERROR]: ID de teleoperador no válido
2025-06-11 13:44:44 - INFO - [SERVIDOR INFO]: Teleoperador recibido: 
2025-06-11 13:44:44 - ERROR - [SERVIDOR ERROR]: ID de teleoperador no válido
2025-06-11 13:44:44 - INFO - [SERVIDOR INFO]: Teleoperador recibido: 
2025-06-11 13:44:44 - ERROR - [SERVIDOR ERROR]: ID de teleoperador no válido
2025-06-11 13:44:44 - INFO - [SERVIDOR INFO]: Teleoperador recibido: 
2025-06-11 13:44:44 - ERROR - [SERVIDOR ERROR]: ID de teleoperador no válido
2025-06-11 13:44:44 - INFO - [SERVIDOR INFO]: Teleoperador recibido: 
2025-06-11 13:44:44 - ERROR - [SERVIDOR ERROR]: ID de teleoperador no válido
2025-06-11 13:44:44 - INFO - [SERVIDOR INFO]: Teleoperador recibido: 
2025-06-11 13:44:44 - ERROR - [SERVIDOR ERROR]: ID de teleoperador no válido
2025-06-11 13:44:44 - INFO - [SERVIDOR INFO]: Teleoperador recibido: 
2025-06-11 13:44:44 - ERROR - [SERVIDOR ERROR]: ID de teleoperador no válido
2025-06-11 13:44:44 - INFO - [SERVIDOR INFO]: Teleoperador recibido: 
2025-06-11 13:44:44 - ERROR - [SERVIDOR ERROR]: ID de teleoperador no válido
2025-06-11 13:44:44 - INFO - [SERVIDOR INFO]: Teleoperador recibido: 
2025-06-11 13:44:44 - ERROR - [SERVIDOR ERROR]: ID de teleoperador no válido
2025-06-11 13:44:44 - INFO - [SERVIDOR INFO]: Teleoperador recibido: 
2025-06-11 13:44:44 - ERROR - [SERVIDOR ERROR]: ID de teleoperador no válido
2025-06-11 13:44:44 - INFO - [SERVIDOR INFO]: Teleoperador recibido: 
2025-06-11 13:44:44 - ERROR - [SERVIDOR ERROR]: ID de teleoperador no válido
2025-06-11 13:44:44 - INFO - [SERVIDOR INFO]: Teleoperador recibido: 
2025-06-11 13:44:44 - ERROR - [SERVIDOR ERROR]: ID de teleoperador no válido
2025-06-11 13:44:44 - INFO - [SERVIDOR INFO]: Teleoperador recibido: 
2025-06-11 13:44:44 - ERROR - [SERVIDOR ERROR]: ID de teleoperador no válido
2025-06-11 13:44:44 - INFO - [SERVIDOR INFO]: Teleoperador recibido: 
2025-06-11 13:44:44 - ERROR - [SERVIDOR ERROR]: ID de teleoperador no válido
2025-06-11 13:44:44 - INFO - [SERVIDOR INFO]: Teleoperador recibido: 
2025-06-11 13:44:44 - ERROR - [SERVIDOR ERROR]: ID de teleoperador no válido
2025-06-11 13:44:44 - INFO - [SERVIDOR INFO]: Teleoperador recibido: 
2025-06-11 13:44:44 - ERROR - [SERVIDOR ERROR]: ID de teleoperador no válido
2025-06-11 13:44:44 - INFO - [SERVIDOR INFO]: Teleoperador recibido: 
2025-06-11 13:44:44 - ERROR - [SERVIDOR ERROR]: ID de teleoperador no válido
2025-06-11 13:44:44 - INFO - [SERVIDOR INFO]: Teleoperador recibido: 
2025-06-11 13:44:44 - ERROR - [SERVIDOR ERROR]: ID de teleoperador no válido
2025-06-11 13:44:44 - INFO - [SERVIDOR INFO]: Teleoperador recibido: 
2025-06-11 13:44:44 - ERROR - [SERVIDOR ERROR]: ID de teleoperador no válido
2025-06-11 13:44:44 - INFO - [SERVIDOR INFO]: Teleoperador recibido: 
2025-06-11 13:44:44 - ERROR - [SERVIDOR ERROR]: ID de teleoperador no válido
2025-06-11 13:44:44 - INFO - [SERVIDOR INFO]: Teleoperador recibido: 
2025-06-11 13:44:44 - ERROR - [SERVIDOR ERROR]: ID de teleoperador no válido
2025-06-11 13:44:44 - INFO - [SERVIDOR INFO]: Teleoperador recibido: 
2025-06-11 13:44:44 - ERROR - [SERVIDOR ERROR]: ID de teleoperador no válido
2025-06-11 13:44:44 - INFO - [SERVIDOR INFO]: Teleoperador recibido: 
2025-06-11 13:44:44 - ERROR - [SERVIDOR ERROR]: ID de teleoperador no válido
2025-06-11 13:44:44 - INFO - [SERVIDOR INFO]: Teleoperador recibido: 
2025-06-11 13:44:44 - ERROR - [SERVIDOR ERROR]: ID de teleoperador no válido
2025-06-11 13:44:44 - INFO - [SERVIDOR INFO]: Teleoperador recibido: 
2025-06-11 13:44:44 - ERROR - [SERVIDOR ERROR]: ID de teleoperador no válido
2025-06-11 13:44:44 - INFO - [SERVIDOR INFO]: Teleoperador recibido: 
2025-06-11 13:44:44 - ERROR - [SERVIDOR ERROR]: ID de teleoperador no válido
2025-06-11 13:44:44 - INFO - [SERVIDOR INFO]: Teleoperador recibido: 
2025-06-11 13:44:44 - ERROR - [SERVIDOR ERROR]: ID de teleoperador no válido
2025-06-11 13:44:44 - INFO - [SERVIDOR INFO]: Teleoperador recibido: 
2025-06-11 13:44:44 - ERROR - [SERVIDOR ERROR]: ID de teleoperador no válido
2025-06-11 13:44:44 - INFO - [SERVIDOR INFO]: Teleoperador recibido: 
2025-06-11 13:44:44 - ERROR - [SERVIDOR ERROR]: ID de teleoperador no válido
2025-06-11 13:44:44 - INFO - [SERVIDOR INFO]: Teleoperador recibido: 
2025-06-11 13:44:44 - ERROR - [SERVIDOR ERROR]: ID de teleoperador no válido
2025-06-11 13:44:44 - INFO - [SERVIDOR INFO]: Teleoperador recibido: 
2025-06-11 13:44:44 - ERROR - [SERVIDOR ERROR]: ID de teleoperador no válido
2025-06-11 13:44:44 - INFO - [SERVIDOR INFO]: Teleoperador recibido: 
2025-06-11 13:44:44 - ERROR - [SERVIDOR ERROR]: ID de teleoperador no válido
2025-06-11 13:44:44 - INFO - [SERVIDOR INFO]: Teleoperador recibido: 
2025-06-11 13:44:44 - ERROR - [SERVIDOR ERROR]: ID de teleoperador no válido
2025-06-11 13:44:44 - INFO - [SERVIDOR INFO]: Teleoperador recibido: 
2025-06-11 13:44:44 - ERROR - [SERVIDOR ERROR]: ID de teleoperador no válido
2025-06-11 13:44:44 - ERROR - Unhandled exception in client_connected_cb
transport: <_ProactorSocketTransport closed>
Traceback (most recent call last):
  File "c:\Users\nzjha\Desktop\Clon_Github\python_serve\Async\sv.py", line 261, in server_on
    await teleoperador_MySQL(writer, reader)
  File "c:\Users\nzjha\Desktop\Clon_Github\python_serve\Async\sv.py", line 217, in teleoperador_MySQL
    await delete_teleoperador(writer, reader)
  File "c:\Users\nzjha\Desktop\Clon_Github\python_serve\Async\sv.py", line 53, in delete_teleoperador
    await writer.drain()
  File "C:\Program Files\WindowsApps\PythonSoftwareFoundation.Python.3.13_3.13.1008.0_x64__qbz5n2kfra8p0\Lib\asyncio\streams.py", line 386, in drain
    await self._protocol._drain_helper()
  File "C:\Program Files\WindowsApps\PythonSoftwareFoundation.Python.3.13_3.13.1008.0_x64__qbz5n2kfra8p0\Lib\asyncio\streams.py", line 172, in _drain_helper
    await waiter
  File "C:\Program Files\WindowsApps\PythonSoftwareFoundation.Python.3.13_3.13.1008.0_x64__qbz5n2kfra8p0\Lib\asyncio\proactor_events.py", line 402, in _loop_writing
    self._write_fut = self._loop._proactor.send(self._sock, data)
                      ~~~~~~~~~~~~~~~~~~~~~~~~~^^^^^^^^^^^^^^^^^^
  File "C:\Program Files\WindowsApps\PythonSoftwareFoundation.Python.3.13_3.13.1008.0_x64__qbz5n2kfra8p0\Lib\asyncio\windows_events.py", line 543, in send
    ov.WSASend(conn.fileno(), buf, flags)
    ~~~~~~~~~~^^^^^^^^^^^^^^^^^^^^^^^^^^^
ConnectionAbortedError: [WinError 10053] Se ha anulado una conexión establecida por el software en su equipo host
2025-06-11 13:45:38 - INFO - [SERVIDOR INFO]: Servidor escuchando en localhost:8083
2025-06-11 13:45:43 - INFO - [SERVIDOR INFO]: Conexión desde ('127.0.0.1', 60964)
2025-06-11 13:45:48 - WARNING - [SERVIDOR WARNING]: == ESPERA AUTOMÁTICA DE 5 SEGUNDOS ==
2025-06-11 13:45:49 - INFO - [SERVIDOR INFO]: Consultando datos de teleoperador...
2025-06-11 13:45:53 - INFO - package: mysql.connector.plugins
2025-06-11 13:45:53 - INFO - plugin_name: caching_sha2_password
2025-06-11 13:45:53 - INFO - AUTHENTICATION_PLUGIN_CLASS: MySQLCachingSHA2PasswordAuthPlugin
2025-06-11 14:21:23 - INFO - [SERVIDOR INFO]: Servidor escuchando en localhost:8083
2025-06-11 14:21:30 - INFO - [SERVIDOR INFO]: Conexión desde ('127.0.0.1', 62049)
2025-06-11 14:21:35 - WARNING - [SERVIDOR WARNING]: == ESPERA AUTOMÁTICA DE 5 SEGUNDOS ==
2025-06-11 14:21:40 - INFO - [SERVIDOR INFO]: Consultando datos de Tecnicos...
2025-06-11 14:21:40 - ERROR - Unhandled exception in client_connected_cb
transport: <_ProactorSocketTransport fd=1252 read=<_OverlappedFuture pending cb=[_ProactorReadPipeTransport._loop_reading()]>>
Traceback (most recent call last):
  File "c:\Users\nzjha\Desktop\Clon_Github\python_serve\Async\sv.py", line 399, in server_on
    await tecnico_MySQL(writer, reader)
  File "c:\Users\nzjha\Desktop\Clon_Github\python_serve\Async\sv.py", line 132, in tecnico_MySQL
    writer.write(menu.encode())
                 ^^^^^^^^^^^
AttributeError: 'bytes' object has no attribute 'encode'. Did you mean: 'decode'?
2025-06-11 14:22:36 - INFO - [SERVIDOR INFO]: Servidor escuchando en localhost:8083
2025-06-11 14:22:37 - INFO - [SERVIDOR INFO]: Conexión desde ('127.0.0.1', 62072)
2025-06-11 14:22:42 - WARNING - [SERVIDOR WARNING]: == ESPERA AUTOMÁTICA DE 5 SEGUNDOS ==
2025-06-11 14:22:45 - INFO - [SERVIDOR INFO]: Consultando datos de Tecnicos...
2025-06-11 14:22:45 - ERROR - Unhandled exception in client_connected_cb
transport: <_ProactorSocketTransport fd=1196 read=<_OverlappedFuture pending cb=[_ProactorReadPipeTransport._loop_reading()]>>
Traceback (most recent call last):
  File "c:\Users\nzjha\Desktop\Clon_Github\python_serve\Async\sv.py", line 399, in server_on
    await tecnico_MySQL(writer, reader)
  File "c:\Users\nzjha\Desktop\Clon_Github\python_serve\Async\sv.py", line 132, in tecnico_MySQL
    writer.write(menu.encode())
                 ^^^^^^^^^^^
AttributeError: 'bytes' object has no attribute 'encode'. Did you mean: 'decode'?
2025-06-11 14:29:27 - INFO - [SERVIDOR INFO]: Servidor escuchando en localhost:8083
2025-06-11 14:29:29 - INFO - [SERVIDOR INFO]: Conexión desde ('127.0.0.1', 62168)
2025-06-11 14:29:34 - WARNING - [SERVIDOR WARNING]: == ESPERA AUTOMÁTICA DE 5 SEGUNDOS ==
2025-06-11 14:29:37 - INFO - [SERVIDOR INFO]: Consultando datos de Tecnicos...
2025-06-11 14:29:37 - ERROR - Unhandled exception in client_connected_cb
transport: <_ProactorSocketTransport fd=1092 read=<_OverlappedFuture pending cb=[_ProactorReadPipeTransport._loop_reading()]>>
Traceback (most recent call last):
  File "c:\Users\nzjha\Desktop\Clon_Github\python_serve\Async\sv.py", line 400, in server_on
    await tecnico_MySQL(writer, reader)
  File "c:\Users\nzjha\Desktop\Clon_Github\python_serve\Async\sv.py", line 133, in tecnico_MySQL
    writer.write(menu.encode())
                 ^^^^^^^^^^^
AttributeError: 'bytes' object has no attribute 'encode'. Did you mean: 'decode'?
2025-06-11 14:31:57 - INFO - [SERVIDOR INFO]: Servidor escuchando en localhost:8083
2025-06-11 14:31:57 - INFO - [SERVIDOR INFO]: Conexión desde ('127.0.0.1', 62221)
2025-06-11 14:32:02 - WARNING - [SERVIDOR WARNING]: == ESPERA AUTOMÁTICA DE 5 SEGUNDOS ==
2025-06-11 14:32:04 - INFO - [SERVIDOR INFO]: Consultando datos de teleoperador...
2025-06-11 14:32:09 - INFO - package: mysql.connector.plugins
2025-06-11 14:32:09 - INFO - plugin_name: caching_sha2_password
2025-06-11 14:32:09 - INFO - AUTHENTICATION_PLUGIN_CLASS: MySQLCachingSHA2PasswordAuthPlugin
2025-06-11 14:32:15 - ERROR - Unhandled exception in client_connected_cb
transport: <_ProactorSocketTransport closed>
Traceback (most recent call last):
  File "C:\Program Files\WindowsApps\PythonSoftwareFoundation.Python.3.13_3.13.1008.0_x64__qbz5n2kfra8p0\Lib\asyncio\windows_events.py", line 463, in finish_socket_func
    return ov.getresult()
           ~~~~~~~~~~~~^^
OSError: [WinError 64] El nombre de red especificado ya no está disponible

During handling of the above exception, another exception occurred:

Traceback (most recent call last):
  File "c:\Users\nzjha\Desktop\Clon_Github\python_serve\Async\sv.py", line 394, in server_on
    await teleoperador_MySQL(writer, reader)
  File "c:\Users\nzjha\Desktop\Clon_Github\python_serve\Async\sv.py", line 356, in teleoperador_MySQL
    await add_teleoperador(writer, reader)
  File "c:\Users\nzjha\Desktop\Clon_Github\python_serve\Async\sv.py", line 292, in add_teleoperador
    nombre = (await reader.read(1024)).decode().strip()
              ^^^^^^^^^^^^^^^^^^^^^^^
  File "C:\Program Files\WindowsApps\PythonSoftwareFoundation.Python.3.13_3.13.1008.0_x64__qbz5n2kfra8p0\Lib\asyncio\streams.py", line 730, in read
    await self._wait_for_data('read')
  File "C:\Program Files\WindowsApps\PythonSoftwareFoundation.Python.3.13_3.13.1008.0_x64__qbz5n2kfra8p0\Lib\asyncio\streams.py", line 539, in _wait_for_data
    await self._waiter
  File "C:\Program Files\WindowsApps\PythonSoftwareFoundation.Python.3.13_3.13.1008.0_x64__qbz5n2kfra8p0\Lib\asyncio\proactor_events.py", line 286, in _loop_reading
    length = fut.result()
  File "C:\Program Files\WindowsApps\PythonSoftwareFoundation.Python.3.13_3.13.1008.0_x64__qbz5n2kfra8p0\Lib\asyncio\windows_events.py", line 804, in _poll
    value = callback(transferred, key, ov)
  File "C:\Program Files\WindowsApps\PythonSoftwareFoundation.Python.3.13_3.13.1008.0_x64__qbz5n2kfra8p0\Lib\asyncio\windows_events.py", line 467, in finish_socket_func
    raise ConnectionResetError(*exc.args)
ConnectionResetError: [WinError 64] El nombre de red especificado ya no está disponible
2025-06-11 14:32:18 - INFO - [SERVIDOR INFO]: Conexión desde ('127.0.0.1', 62286)
2025-06-11 14:32:23 - WARNING - [SERVIDOR WARNING]: == ESPERA AUTOMÁTICA DE 5 SEGUNDOS ==
2025-06-11 14:33:27 - INFO - [SERVIDOR INFO]: Consultando datos de Tecnicos...
2025-06-11 14:33:27 - ERROR - Unhandled exception in client_connected_cb
transport: <_ProactorSocketTransport fd=1096 read=<_OverlappedFuture pending cb=[_ProactorReadPipeTransport._loop_reading()]>>
Traceback (most recent call last):
  File "c:\Users\nzjha\Desktop\Clon_Github\python_serve\Async\sv.py", line 400, in server_on
    await tecnico_MySQL(writer, reader)
  File "c:\Users\nzjha\Desktop\Clon_Github\python_serve\Async\sv.py", line 133, in tecnico_MySQL
    writer.write(menu.encode())
                 ^^^^^^^^^^^
AttributeError: 'bytes' object has no attribute 'encode'. Did you mean: 'decode'?
2025-06-11 14:35:26 - INFO - [SERVIDOR INFO]: Servidor escuchando en localhost:8083
2025-06-11 14:35:26 - INFO - [SERVIDOR INFO]: Conexión desde ('127.0.0.1', 62342)
2025-06-11 14:35:31 - WARNING - [SERVIDOR WARNING]: == ESPERA AUTOMÁTICA DE 5 SEGUNDOS ==
2025-06-11 14:35:34 - INFO - [SERVIDOR INFO]: Consultando datos de Tecnicos...
2025-06-11 14:35:39 - INFO - package: mysql.connector.plugins
2025-06-11 14:35:39 - INFO - plugin_name: caching_sha2_password
2025-06-11 14:35:39 - INFO - AUTHENTICATION_PLUGIN_CLASS: MySQLCachingSHA2PasswordAuthPlugin
2025-06-11 14:35:46 - INFO - [SERVIDOR INFO]: Nombre recibido: aether
2025-06-11 14:35:55 - INFO - [SERVIDOR INFO]: Apellido recibido: Tabivito
2025-06-11 14:35:58 - INFO - [SERVIDOR INFO]: Telefono recibido: 92823owe23289
2025-06-11 14:36:07 - INFO - [SERVIDOR INFO]: Email recibido: tavivito@uuu.com
2025-06-11 14:36:07 - INFO - [SERVIDOR INFO]: Teleoperador aether Tabivito insertado correctamente en la base de datos.
2025-06-11 14:38:10 - ERROR - Unhandled exception in client_connected_cb
transport: <_ProactorSocketTransport closed>
Traceback (most recent call last):
  File "C:\Program Files\WindowsApps\PythonSoftwareFoundation.Python.3.13_3.13.1008.0_x64__qbz5n2kfra8p0\Lib\asyncio\windows_events.py", line 463, in finish_socket_func
    return ov.getresult()
           ~~~~~~~~~~~~^^
OSError: [WinError 64] El nombre de red especificado ya no está disponible

During handling of the above exception, another exception occurred:

Traceback (most recent call last):
  File "c:\Users\nzjha\Desktop\Clon_Github\python_serve\Async\sv.py", line 401, in server_on
    print(f"Conexión desde {addr}")
            ^^^^^^^^^^^^^^^^^^^^^^^
  File "c:\Users\nzjha\Desktop\Clon_Github\python_serve\Async\sv.py", line 139, in tecnico_MySQL
    crs.execute(query, values)
    ~~~~~~~~~~~^^^^^^^^^^^^^^^
  File "c:\Users\nzjha\Desktop\Clon_Github\python_serve\Async\sv.py", line 116, in add_tecnico
    await writer.drain()
  File "c:\Users\nzjha\Desktop\Clon_Github\python_serve\Async\sv.py", line 353, in teleoperador_MySQL
    except ValueError:
               ^^^^^^^
  File "C:\Program Files\WindowsApps\PythonSoftwareFoundation.Python.3.13_3.13.1008.0_x64__qbz5n2kfra8p0\Lib\asyncio\streams.py", line 730, in read
    await self._wait_for_data('read')
  File "C:\Program Files\WindowsApps\PythonSoftwareFoundation.Python.3.13_3.13.1008.0_x64__qbz5n2kfra8p0\Lib\asyncio\streams.py", line 539, in _wait_for_data
    await self._waiter
  File "C:\Program Files\WindowsApps\PythonSoftwareFoundation.Python.3.13_3.13.1008.0_x64__qbz5n2kfra8p0\Lib\asyncio\proactor_events.py", line 286, in _loop_reading
    length = fut.result()
  File "C:\Program Files\WindowsApps\PythonSoftwareFoundation.Python.3.13_3.13.1008.0_x64__qbz5n2kfra8p0\Lib\asyncio\windows_events.py", line 804, in _poll
    value = callback(transferred, key, ov)
  File "C:\Program Files\WindowsApps\PythonSoftwareFoundation.Python.3.13_3.13.1008.0_x64__qbz5n2kfra8p0\Lib\asyncio\windows_events.py", line 467, in finish_socket_func
    raise ConnectionResetError(*exc.args)
ConnectionResetError: [WinError 64] El nombre de red especificado ya no está disponible
2025-06-11 14:38:25 - INFO - [SERVIDOR INFO]: Servidor escuchando en localhost:8083
2025-06-11 14:38:26 - INFO - [SERVIDOR INFO]: Conexión desde ('127.0.0.1', 62397)
2025-06-11 14:38:31 - WARNING - [SERVIDOR WARNING]: == ESPERA AUTOMÁTICA DE 5 SEGUNDOS ==
2025-06-11 14:39:22 - INFO - [SERVIDOR INFO]: Servidor escuchando en localhost:8083
2025-06-11 14:39:24 - INFO - [SERVIDOR INFO]: Conexión desde ('127.0.0.1', 62418)
2025-06-11 14:39:29 - WARNING - [SERVIDOR WARNING]: == ESPERA AUTOMÁTICA DE 5 SEGUNDOS ==
2025-06-11 14:40:14 - INFO - [SERVIDOR INFO]: Consultando datos de Tecnicos...
2025-06-11 14:40:21 - INFO - package: mysql.connector.plugins
2025-06-11 14:40:21 - INFO - plugin_name: caching_sha2_password
2025-06-11 14:40:21 - INFO - AUTHENTICATION_PLUGIN_CLASS: MySQLCachingSHA2PasswordAuthPlugin
2025-06-11 14:40:25 - INFO - [SERVIDOR INFO]: Tecnico recibido: 5
2025-06-11 14:40:25 - INFO - [SERVIDOR INFO]: Tecnico con ID 5 eliminado correctamente de la base de datos.
2025-06-11 14:53:49 - ERROR - Unhandled exception in client_connected_cb
transport: <_ProactorSocketTransport closed>
Traceback (most recent call last):
  File "C:\Program Files\WindowsApps\PythonSoftwareFoundation.Python.3.13_3.13.1008.0_x64__qbz5n2kfra8p0\Lib\asyncio\windows_events.py", line 463, in finish_socket_func
    return ov.getresult()
           ~~~~~~~~~~~~^^
OSError: [WinError 64] El nombre de red especificado ya no está disponible

During handling of the above exception, another exception occurred:

Traceback (most recent call last):
  File "c:\Users\nzjha\Desktop\Clon_Github\python_serve\Async\sv.py", line 430, in server_on
    # TODO: ============== SERVIDOR ==============
  File "c:\Users\nzjha\Desktop\Clon_Github\python_serve\Async\sv.py", line 172, in tecnico_MySQL
    else:
  File "c:\Users\nzjha\Desktop\Clon_Github\python_serve\Async\sv.py", line 94, in delete_tecnico
    tele_id = (await reader.read(1024)).decode().strip()
               ^^^^^^^^^^^^^^^^^^^^^^^
  File "C:\Program Files\WindowsApps\PythonSoftwareFoundation.Python.3.13_3.13.1008.0_x64__qbz5n2kfra8p0\Lib\asyncio\streams.py", line 730, in read
    await self._wait_for_data('read')
  File "C:\Program Files\WindowsApps\PythonSoftwareFoundation.Python.3.13_3.13.1008.0_x64__qbz5n2kfra8p0\Lib\asyncio\streams.py", line 539, in _wait_for_data
    await self._waiter
  File "C:\Program Files\WindowsApps\PythonSoftwareFoundation.Python.3.13_3.13.1008.0_x64__qbz5n2kfra8p0\Lib\asyncio\proactor_events.py", line 286, in _loop_reading
    length = fut.result()
  File "C:\Program Files\WindowsApps\PythonSoftwareFoundation.Python.3.13_3.13.1008.0_x64__qbz5n2kfra8p0\Lib\asyncio\windows_events.py", line 804, in _poll
    value = callback(transferred, key, ov)
  File "C:\Program Files\WindowsApps\PythonSoftwareFoundation.Python.3.13_3.13.1008.0_x64__qbz5n2kfra8p0\Lib\asyncio\windows_events.py", line 467, in finish_socket_func
    raise ConnectionResetError(*exc.args)
ConnectionResetError: [WinError 64] El nombre de red especificado ya no está disponible
2025-06-11 15:01:25 - INFO - [SERVIDOR INFO]: Servidor escuchando en localhost:8083
2025-06-11 15:01:26 - INFO - [SERVIDOR INFO]: Conexión desde ('127.0.0.1', 62874)
2025-06-11 15:01:31 - WARNING - [SERVIDOR WARNING]: == ESPERA AUTOMÁTICA DE 5 SEGUNDOS ==
2025-06-11 15:01:33 - INFO - [SERVIDOR INFO]: Consultando datos de Tecnicos...
2025-06-11 15:01:44 - INFO - package: mysql.connector.plugins
2025-06-11 15:01:44 - INFO - plugin_name: caching_sha2_password
2025-06-11 15:01:44 - INFO - AUTHENTICATION_PLUGIN_CLASS: MySQLCachingSHA2PasswordAuthPlugin
2025-06-11 15:01:44 - ERROR - Unhandled exception in client_connected_cb
transport: <_ProactorSocketTransport fd=1088 read=<_OverlappedFuture pending cb=[_ProactorReadPipeTransport._loop_reading()]>>
Traceback (most recent call last):
  File "c:\Users\nzjha\Desktop\Clon_Github\python_serve\Async\sv.py", line 490, in server_on
    await tecnico_MySQL(writer, reader)
  File "c:\Users\nzjha\Desktop\Clon_Github\python_serve\Async\sv.py", line 234, in tecnico_MySQL
    await consult_tecnicos_horarios(writer, reader)
  File "c:\Users\nzjha\Desktop\Clon_Github\python_serve\Async\sv.py", line 90, in consult_tecnicos_horarios
    crs.execute(query)
    ~~~~~~~~~~~^^^^^^^
  File "C:\Users\nzjha\AppData\Local\Packages\PythonSoftwareFoundation.Python.3.13_qbz5n2kfra8p0\LocalCache\local-packages\Python313\site-packages\mysql\connector\cursor.py", line 418, in execute
    self._connection.cmd_query(
    ~~~~~~~~~~~~~~~~~~~~~~~~~~^
        self._stmt_partition["mappable_stmt"],
        ^^^^^^^^^^^^^^^^^^^^^^^^^^^^^^^^^^^^^^
        read_timeout=self._read_timeout,
        ^^^^^^^^^^^^^^^^^^^^^^^^^^^^^^^^
        write_timeout=self._write_timeout,
        ^^^^^^^^^^^^^^^^^^^^^^^^^^^^^^^^^^
    )
    ^
  File "C:\Users\nzjha\AppData\Local\Packages\PythonSoftwareFoundation.Python.3.13_qbz5n2kfra8p0\LocalCache\local-packages\Python313\site-packages\mysql\connector\opentelemetry\context_propagation.py", line 97, in wrapper
    return method(cnx, *args, **kwargs)
  File "C:\Users\nzjha\AppData\Local\Packages\PythonSoftwareFoundation.Python.3.13_qbz5n2kfra8p0\LocalCache\local-packages\Python313\site-packages\mysql\connector\_decorating.py", line 89, in handle_cnx_method
    raise err
  File "C:\Users\nzjha\AppData\Local\Packages\PythonSoftwareFoundation.Python.3.13_qbz5n2kfra8p0\LocalCache\local-packages\Python313\site-packages\mysql\connector\_decorating.py", line 85, in handle_cnx_method
    return cnx_method(cnx, *args, **kwargs)
  File "C:\Users\nzjha\AppData\Local\Packages\PythonSoftwareFoundation.Python.3.13_qbz5n2kfra8p0\LocalCache\local-packages\Python313\site-packages\mysql\connector\connection.py", line 984, in cmd_query
    result = self._handle_result(
        self._send_cmd(
    ...<6 lines>...
        write_timeout,
    )
  File "C:\Users\nzjha\AppData\Local\Packages\PythonSoftwareFoundation.Python.3.13_qbz5n2kfra8p0\LocalCache\local-packages\Python313\site-packages\mysql\connector\_decorating.py", line 89, in handle_cnx_method
    raise err
  File "C:\Users\nzjha\AppData\Local\Packages\PythonSoftwareFoundation.Python.3.13_qbz5n2kfra8p0\LocalCache\local-packages\Python313\site-packages\mysql\connector\_decorating.py", line 85, in handle_cnx_method
    return cnx_method(cnx, *args, **kwargs)
  File "C:\Users\nzjha\AppData\Local\Packages\PythonSoftwareFoundation.Python.3.13_qbz5n2kfra8p0\LocalCache\local-packages\Python313\site-packages\mysql\connector\connection.py", line 745, in _handle_result
    raise get_exception(packet)
mysql.connector.errors.ProgrammingError: 1054 (42S22): Unknown column 't.ubicacion_id' in 'on clause'
2025-06-11 15:10:12 - INFO - [SERVIDOR INFO]: Conexión desde ('127.0.0.1', 63027)
2025-06-11 15:10:17 - WARNING - [SERVIDOR WARNING]: == ESPERA AUTOMÁTICA DE 5 SEGUNDOS ==
2025-06-11 15:10:20 - INFO - [SERVIDOR INFO]: Consultando datos de Tecnicos...
2025-06-11 15:10:27 - ERROR - Unhandled exception in client_connected_cb
transport: <_ProactorSocketTransport fd=1096 read=<_OverlappedFuture pending cb=[_ProactorReadPipeTransport._loop_reading()]>>
Traceback (most recent call last):
  File "c:\Users\nzjha\Desktop\Clon_Github\python_serve\Async\sv.py", line 490, in server_on
    writer.write("Consultando datos de Incidencias...\n".encode())
    ^^^^^^^^^^^^^^^^^^^^^^^^^^^^^^^^^^^
  File "c:\Users\nzjha\Desktop\Clon_Github\python_serve\Async\sv.py", line 234, in tecnico_MySQL
  File "c:\Users\nzjha\Desktop\Clon_Github\python_serve\Async\sv.py", line 90, in consult_tecnicos_horarios
    writer.write("No hay tecnicos registrados.\n".encode())
    ^^^^^^^^^^^^^^
  File "C:\Users\nzjha\AppData\Local\Packages\PythonSoftwareFoundation.Python.3.13_qbz5n2kfra8p0\LocalCache\local-packages\Python313\site-packages\mysql\connector\cursor.py", line 418, in execute
    self._connection.cmd_query(
    ~~~~~~~~~~~~~~~~~~~~~~~~~~^
        self._stmt_partition["mappable_stmt"],
        ^^^^^^^^^^^^^^^^^^^^^^^^^^^^^^^^^^^^^^
        read_timeout=self._read_timeout,
        ^^^^^^^^^^^^^^^^^^^^^^^^^^^^^^^^
        write_timeout=self._write_timeout,
        ^^^^^^^^^^^^^^^^^^^^^^^^^^^^^^^^^^
    )
    ^
  File "C:\Users\nzjha\AppData\Local\Packages\PythonSoftwareFoundation.Python.3.13_qbz5n2kfra8p0\LocalCache\local-packages\Python313\site-packages\mysql\connector\opentelemetry\context_propagation.py", line 97, in wrapper
    return method(cnx, *args, **kwargs)
  File "C:\Users\nzjha\AppData\Local\Packages\PythonSoftwareFoundation.Python.3.13_qbz5n2kfra8p0\LocalCache\local-packages\Python313\site-packages\mysql\connector\_decorating.py", line 89, in handle_cnx_method
    raise err
  File "C:\Users\nzjha\AppData\Local\Packages\PythonSoftwareFoundation.Python.3.13_qbz5n2kfra8p0\LocalCache\local-packages\Python313\site-packages\mysql\connector\_decorating.py", line 85, in handle_cnx_method
    return cnx_method(cnx, *args, **kwargs)
  File "C:\Users\nzjha\AppData\Local\Packages\PythonSoftwareFoundation.Python.3.13_qbz5n2kfra8p0\LocalCache\local-packages\Python313\site-packages\mysql\connector\connection.py", line 984, in cmd_query
    result = self._handle_result(
        self._send_cmd(
    ...<6 lines>...
        write_timeout,
    )
  File "C:\Users\nzjha\AppData\Local\Packages\PythonSoftwareFoundation.Python.3.13_qbz5n2kfra8p0\LocalCache\local-packages\Python313\site-packages\mysql\connector\_decorating.py", line 89, in handle_cnx_method
    raise err
  File "C:\Users\nzjha\AppData\Local\Packages\PythonSoftwareFoundation.Python.3.13_qbz5n2kfra8p0\LocalCache\local-packages\Python313\site-packages\mysql\connector\_decorating.py", line 85, in handle_cnx_method
    return cnx_method(cnx, *args, **kwargs)
  File "C:\Users\nzjha\AppData\Local\Packages\PythonSoftwareFoundation.Python.3.13_qbz5n2kfra8p0\LocalCache\local-packages\Python313\site-packages\mysql\connector\connection.py", line 745, in _handle_result
    raise get_exception(packet)
mysql.connector.errors.ProgrammingError: 1054 (42S22): Unknown column 't.ubicacion_id' in 'on clause'
2025-06-11 15:10:44 - INFO - [SERVIDOR INFO]: Conexión desde ('127.0.0.1', 63054)
2025-06-11 15:10:49 - WARNING - [SERVIDOR WARNING]: == ESPERA AUTOMÁTICA DE 5 SEGUNDOS ==
2025-06-11 15:14:32 - INFO - [SERVIDOR INFO]: Servidor escuchando en localhost:8083
2025-06-11 15:14:34 - INFO - [SERVIDOR INFO]: Conexión desde ('127.0.0.1', 63117)
2025-06-11 15:14:39 - WARNING - [SERVIDOR WARNING]: == ESPERA AUTOMÁTICA DE 5 SEGUNDOS ==
2025-06-11 15:14:43 - INFO - [SERVIDOR INFO]: Consultando datos de Tecnicos...
2025-06-11 15:14:49 - INFO - package: mysql.connector.plugins
2025-06-11 15:14:49 - INFO - plugin_name: caching_sha2_password
2025-06-11 15:14:49 - INFO - AUTHENTICATION_PLUGIN_CLASS: MySQLCachingSHA2PasswordAuthPlugin
2025-06-11 15:15:35 - ERROR - Unhandled exception in client_connected_cb
transport: <_ProactorSocketTransport closed>
Traceback (most recent call last):
  File "C:\Program Files\WindowsApps\PythonSoftwareFoundation.Python.3.13_3.13.1008.0_x64__qbz5n2kfra8p0\Lib\asyncio\windows_events.py", line 463, in finish_socket_func
    return ov.getresult()
           ~~~~~~~~~~~~^^
OSError: [WinError 64] El nombre de red especificado ya no está disponible

During handling of the above exception, another exception occurred:

Traceback (most recent call last):
  File "c:\Users\nzjha\Desktop\Clon_Github\python_serve\Async\.py", line 402, in server_on
    await tecnico_MySQL(writer, reader)
  File "c:\Users\nzjha\Desktop\Clon_Github\python_serve\Async\.py", line 189, in tecnico_MySQL
    await consult_tecnicos_horarios(writer, reader)
  File "c:\Users\nzjha\Desktop\Clon_Github\python_serve\Async\.py", line 85, in consult_tecnicos_horarios
    await tecnico_MySQL(writer, reader)  # Volver al menú de tecnico
    ^^^^^^^^^^^^^^^^^^^^^^^^^^^^^^^^^^^
  File "c:\Users\nzjha\Desktop\Clon_Github\python_serve\Async\.py", line 180, in tecnico_MySQL
    message = (await reader.read(1024)).decode().strip()
               ^^^^^^^^^^^^^^^^^^^^^^^
  File "C:\Program Files\WindowsApps\PythonSoftwareFoundation.Python.3.13_3.13.1008.0_x64__qbz5n2kfra8p0\Lib\asyncio\streams.py", line 730, in read
    await self._wait_for_data('read')
  File "C:\Program Files\WindowsApps\PythonSoftwareFoundation.Python.3.13_3.13.1008.0_x64__qbz5n2kfra8p0\Lib\asyncio\streams.py", line 539, in _wait_for_data
    await self._waiter
  File "C:\Program Files\WindowsApps\PythonSoftwareFoundation.Python.3.13_3.13.1008.0_x64__qbz5n2kfra8p0\Lib\asyncio\proactor_events.py", line 286, in _loop_reading
    length = fut.result()
  File "C:\Program Files\WindowsApps\PythonSoftwareFoundation.Python.3.13_3.13.1008.0_x64__qbz5n2kfra8p0\Lib\asyncio\windows_events.py", line 804, in _poll
    value = callback(transferred, key, ov)
  File "C:\Program Files\WindowsApps\PythonSoftwareFoundation.Python.3.13_3.13.1008.0_x64__qbz5n2kfra8p0\Lib\asyncio\windows_events.py", line 467, in finish_socket_func
    raise ConnectionResetError(*exc.args)
ConnectionResetError: [WinError 64] El nombre de red especificado ya no está disponible
2025-06-11 15:15:38 - INFO - [SERVIDOR INFO]: Conexión desde ('127.0.0.1', 63135)
2025-06-11 15:15:43 - WARNING - [SERVIDOR WARNING]: == ESPERA AUTOMÁTICA DE 5 SEGUNDOS ==
2025-06-11 15:15:47 - INFO - [SERVIDOR INFO]: Servidor escuchando en localhost:8083
2025-06-11 15:15:48 - INFO - [SERVIDOR INFO]: Conexión desde ('127.0.0.1', 63140)
2025-06-11 15:15:53 - WARNING - [SERVIDOR WARNING]: == ESPERA AUTOMÁTICA DE 5 SEGUNDOS ==
2025-06-11 15:15:56 - INFO - [SERVIDOR INFO]: Consultando datos de Tecnicos...
2025-06-11 15:16:01 - INFO - package: mysql.connector.plugins
2025-06-11 15:16:01 - INFO - plugin_name: caching_sha2_password
2025-06-11 15:16:01 - INFO - AUTHENTICATION_PLUGIN_CLASS: MySQLCachingSHA2PasswordAuthPlugin
2025-06-11 15:28:55 - INFO - [SERVIDOR INFO]: Servidor escuchando en localhost:8083
2025-06-11 15:29:02 - INFO - [SERVIDOR INFO]: Conexión desde ('127.0.0.1', 63504)
2025-06-11 15:29:07 - WARNING - [SERVIDOR WARNING]: == ESPERA AUTOMÁTICA DE 5 SEGUNDOS ==
2025-06-11 15:29:12 - INFO - [SERVIDOR INFO]: Consultando datos de Tecnicos...
2025-06-11 15:29:14 - INFO - package: mysql.connector.plugins
2025-06-11 15:29:14 - INFO - plugin_name: caching_sha2_password
2025-06-11 15:29:14 - INFO - AUTHENTICATION_PLUGIN_CLASS: MySQLCachingSHA2PasswordAuthPlugin
2025-06-11 15:29:14 - ERROR - Unhandled exception in client_connected_cb
transport: <_ProactorSocketTransport fd=1088 read=<_OverlappedFuture pending cb=[_ProactorReadPipeTransport._loop_reading()]>>
Traceback (most recent call last):
  File "c:\Users\nzjha\Desktop\Clon_Github\python_serve\Async\sv.py", line 477, in server_on
    await tecnico_MySQL(writer, reader)
  File "c:\Users\nzjha\Desktop\Clon_Github\python_serve\Async\sv.py", line 219, in tecnico_MySQL
    await consult_tecnicos_horarios(writer, reader)
  File "c:\Users\nzjha\Desktop\Clon_Github\python_serve\Async\sv.py", line 92, in consult_tecnicos_horarios
    f"Ubicación: {row[5]} | Semana: {row[6]} | Inicio: {row[7]} | Fin: {row[8]} | Descripción: {row[9]}\n"
                                                                                                ~~~^^^
IndexError: tuple index out of range
2025-06-11 15:30:02 - INFO - [SERVIDOR INFO]: Servidor escuchando en localhost:8083
2025-06-11 15:30:06 - INFO - [SERVIDOR INFO]: Conexión desde ('127.0.0.1', 63522)
2025-06-11 15:30:11 - WARNING - [SERVIDOR WARNING]: == ESPERA AUTOMÁTICA DE 5 SEGUNDOS ==
2025-06-11 15:30:13 - INFO - [SERVIDOR INFO]: Consultando datos de Tecnicos...
2025-06-11 15:30:18 - INFO - package: mysql.connector.plugins
2025-06-11 15:30:18 - INFO - plugin_name: caching_sha2_password
2025-06-11 15:30:18 - INFO - AUTHENTICATION_PLUGIN_CLASS: MySQLCachingSHA2PasswordAuthPlugin
2025-06-11 15:30:18 - ERROR - Unhandled exception in client_connected_cb
transport: <_ProactorSocketTransport fd=1088 read=<_OverlappedFuture pending cb=[_ProactorReadPipeTransport._loop_reading()]>>
Traceback (most recent call last):
  File "c:\Users\nzjha\Desktop\Clon_Github\python_serve\Async\sv.py", line 477, in server_on
    await tecnico_MySQL(writer, reader)
  File "c:\Users\nzjha\Desktop\Clon_Github\python_serve\Async\sv.py", line 219, in tecnico_MySQL
    await consult_tecnicos_horarios(writer, reader)
  File "c:\Users\nzjha\Desktop\Clon_Github\python_serve\Async\sv.py", line 92, in consult_tecnicos_horarios
    f"Ubicación: {row[5]} | Semana: {row[6]} | Inicio: {row[7]} | Fin: {row[8]} | Descripción: {row[9]}\n"
                                                                                                ~~~^^^
IndexError: tuple index out of range
2025-06-11 15:30:53 - INFO - [SERVIDOR INFO]: Servidor escuchando en localhost:8083
2025-06-11 15:30:53 - INFO - [SERVIDOR INFO]: Conexión desde ('127.0.0.1', 63542)
2025-06-11 15:30:58 - WARNING - [SERVIDOR WARNING]: == ESPERA AUTOMÁTICA DE 5 SEGUNDOS ==
2025-06-11 15:31:01 - INFO - [SERVIDOR INFO]: Consultando datos de Tecnicos...
2025-06-11 15:31:06 - INFO - package: mysql.connector.plugins
2025-06-11 15:31:06 - INFO - plugin_name: caching_sha2_password
2025-06-11 15:31:06 - INFO - AUTHENTICATION_PLUGIN_CLASS: MySQLCachingSHA2PasswordAuthPlugin
2025-06-11 15:31:16 - ERROR - Unhandled exception in client_connected_cb
transport: <_ProactorSocketTransport closed>
Traceback (most recent call last):
  File "C:\Program Files\WindowsApps\PythonSoftwareFoundation.Python.3.13_3.13.1008.0_x64__qbz5n2kfra8p0\Lib\asyncio\windows_events.py", line 463, in finish_socket_func
    return ov.getresult()
           ~~~~~~~~~~~~^^
OSError: [WinError 64] El nombre de red especificado ya no está disponible

During handling of the above exception, another exception occurred:

Traceback (most recent call last):
  File "c:\Users\nzjha\Desktop\Clon_Github\python_serve\Async\sv.py", line 477, in server_on
    await tecnico_MySQL(writer, reader)
  File "c:\Users\nzjha\Desktop\Clon_Github\python_serve\Async\sv.py", line 219, in tecnico_MySQL
    await consult_tecnicos_horarios(writer, reader)
  File "c:\Users\nzjha\Desktop\Clon_Github\python_serve\Async\sv.py", line 98, in consult_tecnicos_horarios
    await tecnico_MySQL(writer, reader)  # Volver al menú de tecnico
    ^^^^^^^^^^^^^^^^^^^^^^^^^^^^^^^^^^^
  File "c:\Users\nzjha\Desktop\Clon_Github\python_serve\Async\sv.py", line 214, in tecnico_MySQL
    message = (await reader.read(1024)).decode().strip()
               ^^^^^^^^^^^^^^^^^^^^^^^
  File "C:\Program Files\WindowsApps\PythonSoftwareFoundation.Python.3.13_3.13.1008.0_x64__qbz5n2kfra8p0\Lib\asyncio\streams.py", line 730, in read
    await self._wait_for_data('read')
  File "C:\Program Files\WindowsApps\PythonSoftwareFoundation.Python.3.13_3.13.1008.0_x64__qbz5n2kfra8p0\Lib\asyncio\streams.py", line 539, in _wait_for_data
    await self._waiter
  File "C:\Program Files\WindowsApps\PythonSoftwareFoundation.Python.3.13_3.13.1008.0_x64__qbz5n2kfra8p0\Lib\asyncio\proactor_events.py", line 286, in _loop_reading
    length = fut.result()
  File "C:\Program Files\WindowsApps\PythonSoftwareFoundation.Python.3.13_3.13.1008.0_x64__qbz5n2kfra8p0\Lib\asyncio\windows_events.py", line 804, in _poll
    value = callback(transferred, key, ov)
  File "C:\Program Files\WindowsApps\PythonSoftwareFoundation.Python.3.13_3.13.1008.0_x64__qbz5n2kfra8p0\Lib\asyncio\windows_events.py", line 467, in finish_socket_func
    raise ConnectionResetError(*exc.args)
ConnectionResetError: [WinError 64] El nombre de red especificado ya no está disponible
2025-06-11 15:31:37 - INFO - [SERVIDOR INFO]: Servidor escuchando en localhost:8083
2025-06-11 15:31:37 - INFO - [SERVIDOR INFO]: Conexión desde ('127.0.0.1', 63562)
2025-06-11 15:31:42 - WARNING - [SERVIDOR WARNING]: == ESPERA AUTOMÁTICA DE 5 SEGUNDOS ==
2025-06-11 15:31:45 - INFO - [SERVIDOR INFO]: Consultando datos de Tecnicos...
2025-06-11 15:31:48 - INFO - package: mysql.connector.plugins
2025-06-11 15:31:48 - INFO - plugin_name: caching_sha2_password
2025-06-11 15:31:48 - INFO - AUTHENTICATION_PLUGIN_CLASS: MySQLCachingSHA2PasswordAuthPlugin
2025-06-11 15:31:48 - WARNING - [SERVIDOR WARNING]: == ESPERA AUTOMÁTICA DE 5 SEGUNDOS ==
2025-06-11 15:31:56 - ERROR - Unhandled exception in client_connected_cb
transport: <_ProactorSocketTransport closed>
Traceback (most recent call last):
  File "C:\Program Files\WindowsApps\PythonSoftwareFoundation.Python.3.13_3.13.1008.0_x64__qbz5n2kfra8p0\Lib\asyncio\windows_events.py", line 463, in finish_socket_func
    return ov.getresult()
           ~~~~~~~~~~~~^^
OSError: [WinError 64] El nombre de red especificado ya no está disponible

During handling of the above exception, another exception occurred:

Traceback (most recent call last):
  File "c:\Users\nzjha\Desktop\Clon_Github\python_serve\Async\sv.py", line 480, in server_on
    await tecnico_MySQL(writer, reader)
  File "c:\Users\nzjha\Desktop\Clon_Github\python_serve\Async\sv.py", line 222, in tecnico_MySQL
    await consult_tecnicos_horarios(writer, reader)
  File "c:\Users\nzjha\Desktop\Clon_Github\python_serve\Async\sv.py", line 101, in consult_tecnicos_horarios
    await tecnico_MySQL(writer, reader)  # Volver al menú de tecnico
    ^^^^^^^^^^^^^^^^^^^^^^^^^^^^^^^^^^^
  File "c:\Users\nzjha\Desktop\Clon_Github\python_serve\Async\sv.py", line 217, in tecnico_MySQL
    message = (await reader.read(1024)).decode().strip()
               ^^^^^^^^^^^^^^^^^^^^^^^
  File "C:\Program Files\WindowsApps\PythonSoftwareFoundation.Python.3.13_3.13.1008.0_x64__qbz5n2kfra8p0\Lib\asyncio\streams.py", line 730, in read
    await self._wait_for_data('read')
  File "C:\Program Files\WindowsApps\PythonSoftwareFoundation.Python.3.13_3.13.1008.0_x64__qbz5n2kfra8p0\Lib\asyncio\streams.py", line 539, in _wait_for_data
    await self._waiter
  File "C:\Program Files\WindowsApps\PythonSoftwareFoundation.Python.3.13_3.13.1008.0_x64__qbz5n2kfra8p0\Lib\asyncio\proactor_events.py", line 286, in _loop_reading
    length = fut.result()
  File "C:\Program Files\WindowsApps\PythonSoftwareFoundation.Python.3.13_3.13.1008.0_x64__qbz5n2kfra8p0\Lib\asyncio\windows_events.py", line 804, in _poll
    value = callback(transferred, key, ov)
  File "C:\Program Files\WindowsApps\PythonSoftwareFoundation.Python.3.13_3.13.1008.0_x64__qbz5n2kfra8p0\Lib\asyncio\windows_events.py", line 467, in finish_socket_func
    raise ConnectionResetError(*exc.args)
ConnectionResetError: [WinError 64] El nombre de red especificado ya no está disponible
2025-06-11 15:32:22 - INFO - [SERVIDOR INFO]: Servidor escuchando en localhost:8083
2025-06-11 15:32:23 - INFO - [SERVIDOR INFO]: Conexión desde ('127.0.0.1', 63638)
2025-06-11 15:32:28 - WARNING - [SERVIDOR WARNING]: == ESPERA AUTOMÁTICA DE 5 SEGUNDOS ==
2025-06-11 15:32:29 - INFO - [SERVIDOR INFO]: Consultando datos de Tecnicos...
2025-06-11 15:32:33 - INFO - package: mysql.connector.plugins
2025-06-11 15:32:33 - INFO - plugin_name: caching_sha2_password
2025-06-11 15:32:33 - INFO - AUTHENTICATION_PLUGIN_CLASS: MySQLCachingSHA2PasswordAuthPlugin
2025-06-11 15:32:38 - WARNING - [SERVIDOR WARNING]: == ESPERA AUTOMÁTICA DE 5 SEGUNDOS ==
2025-06-11 16:10:08 - INFO - [SERVIDOR INFO]: Servidor escuchando en localhost:8083
2025-06-11 16:10:14 - INFO - [SERVIDOR INFO]: Conexión desde ('127.0.0.1', 64287)
2025-06-11 16:10:19 - WARNING - [SERVIDOR WARNING]: == ESPERA AUTOMÁTICA DE 5 SEGUNDOS ==
2025-06-11 16:10:23 - INFO - [SERVIDOR INFO]: Consultando datos de Incidencias...
2025-06-11 16:10:23 - ERROR - Unhandled exception in client_connected_cb
transport: <_ProactorSocketTransport fd=1084 read=<_OverlappedFuture pending cb=[_ProactorReadPipeTransport._loop_reading()]>>
Traceback (most recent call last):
  File "c:\Users\nzjha\Desktop\Clon_Github\python_serve\Async\sv.py", line 600, in server_on
    await incidencias_MySQL(writer, reader)  # Placeholder para la función de incidencias
    ^^^^^^^^^^^^^^^^^^^^^^^^^^^^^^^^^^^^^^^
  File "c:\Users\nzjha\Desktop\Clon_Github\python_serve\Async\sv.py", line 113, in incidencias_MySQL
    writer.write(menu.encode())
                 ^^^^^^^^^^^
AttributeError: 'bytes' object has no attribute 'encode'. Did you mean: 'decode'?
2025-06-11 16:11:08 - INFO - [SERVIDOR INFO]: Servidor escuchando en localhost:8083
2025-06-11 16:11:08 - INFO - [SERVIDOR INFO]: Conexión desde ('127.0.0.1', 64302)
2025-06-11 16:11:13 - WARNING - [SERVIDOR WARNING]: == ESPERA AUTOMÁTICA DE 5 SEGUNDOS ==
2025-06-11 16:11:14 - INFO - [SERVIDOR INFO]: Consultando datos de Incidencias...
2025-06-11 16:11:14 - ERROR - Unhandled exception in client_connected_cb
transport: <_ProactorSocketTransport fd=1092 read=<_OverlappedFuture pending cb=[_ProactorReadPipeTransport._loop_reading()]>>
Traceback (most recent call last):
  File "c:\Users\nzjha\Desktop\Clon_Github\python_serve\Async\sv.py", line 600, in server_on
    await incidencias_MySQL(writer, reader)  # Placeholder para la función de incidencias
    ^^^^^^^^^^^^^^^^^^^^^^^^^^^^^^^^^^^^^^^
  File "c:\Users\nzjha\Desktop\Clon_Github\python_serve\Async\sv.py", line 113, in incidencias_MySQL
    writer.write(menu.encode())
                 ^^^^^^^^^^^
AttributeError: 'bytes' object has no attribute 'encode'. Did you mean: 'decode'?
2025-06-11 16:11:34 - INFO - [SERVIDOR INFO]: Servidor escuchando en localhost:8083
2025-06-11 16:11:36 - INFO - [SERVIDOR INFO]: Conexión desde ('127.0.0.1', 64322)
2025-06-11 16:11:41 - WARNING - [SERVIDOR WARNING]: == ESPERA AUTOMÁTICA DE 5 SEGUNDOS ==
2025-06-11 16:11:45 - INFO - [SERVIDOR INFO]: Consultando datos de Incidencias...
2025-06-11 16:11:49 - INFO - package: mysql.connector.plugins
2025-06-11 16:11:49 - INFO - plugin_name: caching_sha2_password
2025-06-11 16:11:49 - INFO - AUTHENTICATION_PLUGIN_CLASS: MySQLCachingSHA2PasswordAuthPlugin
2025-06-11 16:11:56 - INFO - [SERVIDOR INFO]: Tecnico recibido: 2
2025-06-11 16:12:01 - ERROR - Unhandled exception in client_connected_cb
transport: <_ProactorSocketTransport fd=1092 read=<_OverlappedFuture pending cb=[_ProactorReadPipeTransport._loop_reading()]>>
Traceback (most recent call last):
  File "c:\Users\nzjha\Desktop\Clon_Github\python_serve\Async\sv.py", line 600, in server_on
    await incidencias_MySQL(writer, reader)  # Placeholder para la función de incidencias
    ^^^^^^^^^^^^^^^^^^^^^^^^^^^^^^^^^^^^^^^
  File "c:\Users\nzjha\Desktop\Clon_Github\python_serve\Async\sv.py", line 121, in incidencias_MySQL
    await add_incidencia(writer, reader)
  File "c:\Users\nzjha\Desktop\Clon_Github\python_serve\Async\sv.py", line 63, in add_incidencia
    crs.execute(f"SELECT id, nombre FROM {TABLE_MySQL_1}")
    ~~~~~~~~~~~^^^^^^^^^^^^^^^^^^^^^^^^^^^^^^^^^^^^^^^^^^^
  File "C:\Users\nzjha\AppData\Local\Packages\PythonSoftwareFoundation.Python.3.13_qbz5n2kfra8p0\LocalCache\local-packages\Python313\site-packages\mysql\connector\cursor.py", line 418, in execute
    self._connection.cmd_query(
    ~~~~~~~~~~~~~~~~~~~~~~~~~~^
        self._stmt_partition["mappable_stmt"],
        ^^^^^^^^^^^^^^^^^^^^^^^^^^^^^^^^^^^^^^
        read_timeout=self._read_timeout,
        ^^^^^^^^^^^^^^^^^^^^^^^^^^^^^^^^
        write_timeout=self._write_timeout,
        ^^^^^^^^^^^^^^^^^^^^^^^^^^^^^^^^^^
    )
    ^
  File "C:\Users\nzjha\AppData\Local\Packages\PythonSoftwareFoundation.Python.3.13_qbz5n2kfra8p0\LocalCache\local-packages\Python313\site-packages\mysql\connector\opentelemetry\context_propagation.py", line 97, in wrapper
    return method(cnx, *args, **kwargs)
  File "C:\Users\nzjha\AppData\Local\Packages\PythonSoftwareFoundation.Python.3.13_qbz5n2kfra8p0\LocalCache\local-packages\Python313\site-packages\mysql\connector\_decorating.py", line 89, in handle_cnx_method
    raise err
  File "C:\Users\nzjha\AppData\Local\Packages\PythonSoftwareFoundation.Python.3.13_qbz5n2kfra8p0\LocalCache\local-packages\Python313\site-packages\mysql\connector\_decorating.py", line 85, in handle_cnx_method
    return cnx_method(cnx, *args, **kwargs)
  File "C:\Users\nzjha\AppData\Local\Packages\PythonSoftwareFoundation.Python.3.13_qbz5n2kfra8p0\LocalCache\local-packages\Python313\site-packages\mysql\connector\connection.py", line 984, in cmd_query
    result = self._handle_result(
        self._send_cmd(
    ...<6 lines>...
        write_timeout,
    )
  File "C:\Users\nzjha\AppData\Local\Packages\PythonSoftwareFoundation.Python.3.13_qbz5n2kfra8p0\LocalCache\local-packages\Python313\site-packages\mysql\connector\_decorating.py", line 89, in handle_cnx_method
    raise err
  File "C:\Users\nzjha\AppData\Local\Packages\PythonSoftwareFoundation.Python.3.13_qbz5n2kfra8p0\LocalCache\local-packages\Python313\site-packages\mysql\connector\_decorating.py", line 85, in handle_cnx_method
    return cnx_method(cnx, *args, **kwargs)
  File "C:\Users\nzjha\AppData\Local\Packages\PythonSoftwareFoundation.Python.3.13_qbz5n2kfra8p0\LocalCache\local-packages\Python313\site-packages\mysql\connector\connection.py", line 745, in _handle_result
    raise get_exception(packet)
mysql.connector.errors.ProgrammingError: 1054 (42S22): Unknown column 'nombre' in 'field list'
2025-06-11 16:13:11 - INFO - [SERVIDOR INFO]: Servidor escuchando en localhost:8083
2025-06-11 16:13:14 - INFO - [SERVIDOR INFO]: Conexión desde ('127.0.0.1', 64347)
2025-06-11 16:13:19 - WARNING - [SERVIDOR WARNING]: == ESPERA AUTOMÁTICA DE 5 SEGUNDOS ==
2025-06-11 16:13:22 - INFO - [SERVIDOR INFO]: Consultando datos de Incidencias...
2025-06-11 16:13:25 - INFO - package: mysql.connector.plugins
2025-06-11 16:13:25 - INFO - plugin_name: caching_sha2_password
2025-06-11 16:13:25 - INFO - AUTHENTICATION_PLUGIN_CLASS: MySQLCachingSHA2PasswordAuthPlugin
2025-06-11 16:13:29 - INFO - [SERVIDOR INFO]: Tecnico recibido: 1
2025-06-11 16:13:29 - ERROR - Unhandled exception in client_connected_cb
transport: <_ProactorSocketTransport fd=1092 read=<_OverlappedFuture pending cb=[_ProactorReadPipeTransport._loop_reading()]>>
Traceback (most recent call last):
  File "c:\Users\nzjha\Desktop\Clon_Github\python_serve\Async\sv.py", line 604, in server_on
    await incidencias_MySQL(writer, reader)  # Placeholder para la función de incidencias
    ^^^^^^^^^^^^^^^^^^^^^^^^^^^^^^^^^^^^^^^
  File "c:\Users\nzjha\Desktop\Clon_Github\python_serve\Async\sv.py", line 125, in incidencias_MySQL
    await add_incidencia(writer, reader)
  File "c:\Users\nzjha\Desktop\Clon_Github\python_serve\Async\sv.py", line 67, in add_incidencia
    crs_2.execute(f"SELECT id, nombre FROM {TABLE_MySQL_1}")
    ~~~~~~~~~~~~~^^^^^^^^^^^^^^^^^^^^^^^^^^^^^^^^^^^^^^^^^^^
  File "C:\Users\nzjha\AppData\Local\Packages\PythonSoftwareFoundation.Python.3.13_qbz5n2kfra8p0\LocalCache\local-packages\Python313\site-packages\mysql\connector\cursor.py", line 418, in execute
    self._connection.cmd_query(
    ~~~~~~~~~~~~~~~~~~~~~~~~~~^
        self._stmt_partition["mappable_stmt"],
        ^^^^^^^^^^^^^^^^^^^^^^^^^^^^^^^^^^^^^^
        read_timeout=self._read_timeout,
        ^^^^^^^^^^^^^^^^^^^^^^^^^^^^^^^^
        write_timeout=self._write_timeout,
        ^^^^^^^^^^^^^^^^^^^^^^^^^^^^^^^^^^
    )
    ^
  File "C:\Users\nzjha\AppData\Local\Packages\PythonSoftwareFoundation.Python.3.13_qbz5n2kfra8p0\LocalCache\local-packages\Python313\site-packages\mysql\connector\opentelemetry\context_propagation.py", line 97, in wrapper
    return method(cnx, *args, **kwargs)
  File "C:\Users\nzjha\AppData\Local\Packages\PythonSoftwareFoundation.Python.3.13_qbz5n2kfra8p0\LocalCache\local-packages\Python313\site-packages\mysql\connector\_decorating.py", line 89, in handle_cnx_method
    raise err
  File "C:\Users\nzjha\AppData\Local\Packages\PythonSoftwareFoundation.Python.3.13_qbz5n2kfra8p0\LocalCache\local-packages\Python313\site-packages\mysql\connector\_decorating.py", line 85, in handle_cnx_method
    return cnx_method(cnx, *args, **kwargs)
  File "C:\Users\nzjha\AppData\Local\Packages\PythonSoftwareFoundation.Python.3.13_qbz5n2kfra8p0\LocalCache\local-packages\Python313\site-packages\mysql\connector\connection.py", line 984, in cmd_query
    result = self._handle_result(
        self._send_cmd(
    ...<6 lines>...
        write_timeout,
    )
  File "C:\Users\nzjha\AppData\Local\Packages\PythonSoftwareFoundation.Python.3.13_qbz5n2kfra8p0\LocalCache\local-packages\Python313\site-packages\mysql\connector\_decorating.py", line 89, in handle_cnx_method
    raise err
  File "C:\Users\nzjha\AppData\Local\Packages\PythonSoftwareFoundation.Python.3.13_qbz5n2kfra8p0\LocalCache\local-packages\Python313\site-packages\mysql\connector\_decorating.py", line 85, in handle_cnx_method
    return cnx_method(cnx, *args, **kwargs)
  File "C:\Users\nzjha\AppData\Local\Packages\PythonSoftwareFoundation.Python.3.13_qbz5n2kfra8p0\LocalCache\local-packages\Python313\site-packages\mysql\connector\connection.py", line 745, in _handle_result
    raise get_exception(packet)
mysql.connector.errors.ProgrammingError: 1054 (42S22): Unknown column 'nombre' in 'field list'
2025-06-11 16:19:35 - INFO - [SERVIDOR INFO]: Servidor escuchando en localhost:8083
2025-06-11 16:19:39 - INFO - [SERVIDOR INFO]: Conexión desde ('127.0.0.1', 64513)
2025-06-11 16:19:44 - WARNING - [SERVIDOR WARNING]: == ESPERA AUTOMÁTICA DE 5 SEGUNDOS ==
2025-06-11 16:19:51 - INFO - [SERVIDOR INFO]: Consultando datos de Incidencias...
2025-06-11 16:19:56 - INFO - package: mysql.connector.plugins
2025-06-11 16:19:56 - INFO - plugin_name: caching_sha2_password
2025-06-11 16:19:56 - INFO - AUTHENTICATION_PLUGIN_CLASS: MySQLCachingSHA2PasswordAuthPlugin
2025-06-11 16:19:59 - INFO - [SERVIDOR INFO]: Tecnico recibido: 1
2025-06-11 16:19:59 - ERROR - Unhandled exception in client_connected_cb
transport: <_ProactorSocketTransport fd=1088 read=<_OverlappedFuture pending cb=[_ProactorReadPipeTransport._loop_reading()]>>
Traceback (most recent call last):
  File "c:\Users\nzjha\Desktop\Clon_Github\python_serve\Async\sv.py", line 603, in server_on
    await incidencias_MySQL(writer, reader)  # Placeholder para la función de incidencias
    ^^^^^^^^^^^^^^^^^^^^^^^^^^^^^^^^^^^^^^^
  File "c:\Users\nzjha\Desktop\Clon_Github\python_serve\Async\sv.py", line 124, in incidencias_MySQL
    await add_incidencia(writer, reader)
  File "c:\Users\nzjha\Desktop\Clon_Github\python_serve\Async\sv.py", line 66, in add_incidencia
    crs_2.execute(f"SELECT id, nombre FROM {TABLE_MySQL_1}")
    ~~~~~~~~~~~~~^^^^^^^^^^^^^^^^^^^^^^^^^^^^^^^^^^^^^^^^^^^
  File "C:\Users\nzjha\AppData\Local\Packages\PythonSoftwareFoundation.Python.3.13_qbz5n2kfra8p0\LocalCache\local-packages\Python313\site-packages\mysql\connector\cursor.py", line 418, in execute
    self._connection.cmd_query(
    ~~~~~~~~~~~~~~~~~~~~~~~~~~^
        self._stmt_partition["mappable_stmt"],
        ^^^^^^^^^^^^^^^^^^^^^^^^^^^^^^^^^^^^^^
        read_timeout=self._read_timeout,
        ^^^^^^^^^^^^^^^^^^^^^^^^^^^^^^^^
        write_timeout=self._write_timeout,
        ^^^^^^^^^^^^^^^^^^^^^^^^^^^^^^^^^^
    )
    ^
  File "C:\Users\nzjha\AppData\Local\Packages\PythonSoftwareFoundation.Python.3.13_qbz5n2kfra8p0\LocalCache\local-packages\Python313\site-packages\mysql\connector\opentelemetry\context_propagation.py", line 97, in wrapper
    return method(cnx, *args, **kwargs)
  File "C:\Users\nzjha\AppData\Local\Packages\PythonSoftwareFoundation.Python.3.13_qbz5n2kfra8p0\LocalCache\local-packages\Python313\site-packages\mysql\connector\_decorating.py", line 89, in handle_cnx_method
    raise err
  File "C:\Users\nzjha\AppData\Local\Packages\PythonSoftwareFoundation.Python.3.13_qbz5n2kfra8p0\LocalCache\local-packages\Python313\site-packages\mysql\connector\_decorating.py", line 85, in handle_cnx_method
    return cnx_method(cnx, *args, **kwargs)
  File "C:\Users\nzjha\AppData\Local\Packages\PythonSoftwareFoundation.Python.3.13_qbz5n2kfra8p0\LocalCache\local-packages\Python313\site-packages\mysql\connector\connection.py", line 984, in cmd_query
    result = self._handle_result(
        self._send_cmd(
    ...<6 lines>...
        write_timeout,
    )
  File "C:\Users\nzjha\AppData\Local\Packages\PythonSoftwareFoundation.Python.3.13_qbz5n2kfra8p0\LocalCache\local-packages\Python313\site-packages\mysql\connector\_decorating.py", line 89, in handle_cnx_method
    raise err
  File "C:\Users\nzjha\AppData\Local\Packages\PythonSoftwareFoundation.Python.3.13_qbz5n2kfra8p0\LocalCache\local-packages\Python313\site-packages\mysql\connector\_decorating.py", line 85, in handle_cnx_method
    return cnx_method(cnx, *args, **kwargs)
  File "C:\Users\nzjha\AppData\Local\Packages\PythonSoftwareFoundation.Python.3.13_qbz5n2kfra8p0\LocalCache\local-packages\Python313\site-packages\mysql\connector\connection.py", line 745, in _handle_result
    raise get_exception(packet)
mysql.connector.errors.ProgrammingError: 1054 (42S22): Unknown column 'nombre' in 'field list'
2025-06-11 16:29:41 - INFO - [SERVIDOR INFO]: Conexión desde ('127.0.0.1', 64754)
2025-06-11 16:29:45 - INFO - [SERVIDOR INFO]: Servidor escuchando en localhost:8083
2025-06-11 16:29:46 - INFO - [SERVIDOR INFO]: Conexión desde ('127.0.0.1', 64758)
2025-06-11 16:29:51 - WARNING - [SERVIDOR WARNING]: == ESPERA AUTOMÁTICA DE 5 SEGUNDOS ==
2025-06-11 16:29:58 - INFO - [SERVIDOR INFO]: Consultando datos de Incidencias...
2025-06-11 16:30:03 - INFO - package: mysql.connector.plugins
2025-06-11 16:30:03 - INFO - plugin_name: caching_sha2_password
2025-06-11 16:30:03 - INFO - AUTHENTICATION_PLUGIN_CLASS: MySQLCachingSHA2PasswordAuthPlugin
2025-06-11 16:30:07 - INFO - [SERVIDOR INFO]: Tecnico recibido: 1
2025-06-11 16:30:15 - INFO - [SERVIDOR INFO]: Terminal recibido: 6
2025-06-11 16:30:24 - INFO - [SERVIDOR INFO]: Descripción recibida: algo le pasa
2025-06-11 16:31:08 - INFO - [SERVIDOR INFO]: Fecha y hora recibida: 2025-06-11 16:30:59
2025-06-11 16:31:08 - ERROR - Unhandled exception in client_connected_cb
transport: <_ProactorSocketTransport fd=1088 read=<_OverlappedFuture pending cb=[_ProactorReadPipeTransport._loop_reading()]>>
Traceback (most recent call last):
  File "c:\Users\nzjha\Desktop\Clon_Github\python_serve\Async\sv.py", line 603, in server_on
    await incidencias_MySQL(writer, reader)  # Placeholder para la función de incidencias
    ^^^^^^^^^^^^^^^^^^^^^^^^^^^^^^^^^^^^^^^
  File "c:\Users\nzjha\Desktop\Clon_Github\python_serve\Async\sv.py", line 124, in incidencias_MySQL
    await add_incidencia(writer, reader)
  File "c:\Users\nzjha\Desktop\Clon_Github\python_serve\Async\sv.py", line 93, in add_incidencia
    insertar.execute(query, values)
    ~~~~~~~~~~~~~~~~^^^^^^^^^^^^^^^
  File "C:\Users\nzjha\AppData\Local\Packages\PythonSoftwareFoundation.Python.3.13_qbz5n2kfra8p0\LocalCache\local-packages\Python313\site-packages\mysql\connector\cursor.py", line 418, in execute
    self._connection.cmd_query(
    ~~~~~~~~~~~~~~~~~~~~~~~~~~^
        self._stmt_partition["mappable_stmt"],
        ^^^^^^^^^^^^^^^^^^^^^^^^^^^^^^^^^^^^^^
        read_timeout=self._read_timeout,
        ^^^^^^^^^^^^^^^^^^^^^^^^^^^^^^^^
        write_timeout=self._write_timeout,
        ^^^^^^^^^^^^^^^^^^^^^^^^^^^^^^^^^^
    )
    ^
  File "C:\Users\nzjha\AppData\Local\Packages\PythonSoftwareFoundation.Python.3.13_qbz5n2kfra8p0\LocalCache\local-packages\Python313\site-packages\mysql\connector\opentelemetry\context_propagation.py", line 97, in wrapper
    return method(cnx, *args, **kwargs)
  File "C:\Users\nzjha\AppData\Local\Packages\PythonSoftwareFoundation.Python.3.13_qbz5n2kfra8p0\LocalCache\local-packages\Python313\site-packages\mysql\connector\_decorating.py", line 89, in handle_cnx_method
    raise err
  File "C:\Users\nzjha\AppData\Local\Packages\PythonSoftwareFoundation.Python.3.13_qbz5n2kfra8p0\LocalCache\local-packages\Python313\site-packages\mysql\connector\_decorating.py", line 85, in handle_cnx_method
    return cnx_method(cnx, *args, **kwargs)
  File "C:\Users\nzjha\AppData\Local\Packages\PythonSoftwareFoundation.Python.3.13_qbz5n2kfra8p0\LocalCache\local-packages\Python313\site-packages\mysql\connector\connection.py", line 984, in cmd_query
    result = self._handle_result(
        self._send_cmd(
    ...<6 lines>...
        write_timeout,
    )
  File "C:\Users\nzjha\AppData\Local\Packages\PythonSoftwareFoundation.Python.3.13_qbz5n2kfra8p0\LocalCache\local-packages\Python313\site-packages\mysql\connector\_decorating.py", line 89, in handle_cnx_method
    raise err
  File "C:\Users\nzjha\AppData\Local\Packages\PythonSoftwareFoundation.Python.3.13_qbz5n2kfra8p0\LocalCache\local-packages\Python313\site-packages\mysql\connector\_decorating.py", line 85, in handle_cnx_method
    return cnx_method(cnx, *args, **kwargs)
  File "C:\Users\nzjha\AppData\Local\Packages\PythonSoftwareFoundation.Python.3.13_qbz5n2kfra8p0\LocalCache\local-packages\Python313\site-packages\mysql\connector\connection.py", line 745, in _handle_result
    raise get_exception(packet)
mysql.connector.errors.ProgrammingError: 1054 (42S22): Unknown column 'fecha_hora' in 'field list'
2025-06-11 16:35:08 - INFO - [SERVIDOR INFO]: Servidor escuchando en localhost:8083
2025-06-11 16:35:14 - INFO - [SERVIDOR INFO]: Conexión desde ('127.0.0.1', 64858)
2025-06-11 16:35:19 - WARNING - [SERVIDOR WARNING]: == ESPERA AUTOMÁTICA DE 5 SEGUNDOS ==
2025-06-11 16:35:21 - INFO - [SERVIDOR INFO]: Consultando datos de Incidencias...
2025-06-11 16:35:24 - INFO - package: mysql.connector.plugins
2025-06-11 16:35:24 - INFO - plugin_name: caching_sha2_password
2025-06-11 16:35:24 - INFO - AUTHENTICATION_PLUGIN_CLASS: MySQLCachingSHA2PasswordAuthPlugin
2025-06-11 16:35:27 - INFO - [SERVIDOR INFO]: Tecnico recibido: 2
2025-06-11 16:35:30 - INFO - [SERVIDOR INFO]: Terminal recibido: 4
2025-06-11 16:35:39 - INFO - [SERVIDOR INFO]: Descripción recibida: le duele el estomago a la chisma
2025-06-11 16:35:59 - INFO - [SERVIDOR INFO]: Fecha y hora recibida: 2025-06-11 16:35:59
2025-06-11 16:35:59 - INFO - [SERVIDOR INFO]: Incidencia para tecnico 2 y terminal 4 insertada correctamente en la base de datos.
2025-06-11 16:36:32 - ERROR - Unhandled exception in client_connected_cb
transport: <_ProactorSocketTransport closed>
Traceback (most recent call last):
  File "C:\Program Files\WindowsApps\PythonSoftwareFoundation.Python.3.13_3.13.1008.0_x64__qbz5n2kfra8p0\Lib\asyncio\windows_events.py", line 463, in finish_socket_func
    return ov.getresult()
           ~~~~~~~~~~~~^^
OSError: [WinError 64] El nombre de red especificado ya no está disponible

During handling of the above exception, another exception occurred:

Traceback (most recent call last):
  File "c:\Users\nzjha\Desktop\Clon_Github\python_serve\Async\sv.py", line 603, in server_on
    await incidencias_MySQL(writer, reader)  # Placeholder para la función de incidencias
    ^^^^^^^^^^^^^^^^^^^^^^^^^^^^^^^^^^^^^^^
  File "c:\Users\nzjha\Desktop\Clon_Github\python_serve\Async\sv.py", line 124, in incidencias_MySQL
    await add_incidencia(writer, reader)
  File "c:\Users\nzjha\Desktop\Clon_Github\python_serve\Async\sv.py", line 98, in add_incidencia
    await incidencias_MySQL(writer, reader)  # Volver al menú de incidencias
    ^^^^^^^^^^^^^^^^^^^^^^^^^^^^^^^^^^^^^^^
  File "c:\Users\nzjha\Desktop\Clon_Github\python_serve\Async\sv.py", line 119, in incidencias_MySQL
    message = (await reader.read(1024)).decode().strip()
               ^^^^^^^^^^^^^^^^^^^^^^^
  File "C:\Program Files\WindowsApps\PythonSoftwareFoundation.Python.3.13_3.13.1008.0_x64__qbz5n2kfra8p0\Lib\asyncio\streams.py", line 730, in read
    await self._wait_for_data('read')
  File "C:\Program Files\WindowsApps\PythonSoftwareFoundation.Python.3.13_3.13.1008.0_x64__qbz5n2kfra8p0\Lib\asyncio\streams.py", line 539, in _wait_for_data
    await self._waiter
  File "C:\Program Files\WindowsApps\PythonSoftwareFoundation.Python.3.13_3.13.1008.0_x64__qbz5n2kfra8p0\Lib\asyncio\proactor_events.py", line 286, in _loop_reading
    length = fut.result()
  File "C:\Program Files\WindowsApps\PythonSoftwareFoundation.Python.3.13_3.13.1008.0_x64__qbz5n2kfra8p0\Lib\asyncio\windows_events.py", line 804, in _poll
    value = callback(transferred, key, ov)
  File "C:\Program Files\WindowsApps\PythonSoftwareFoundation.Python.3.13_3.13.1008.0_x64__qbz5n2kfra8p0\Lib\asyncio\windows_events.py", line 467, in finish_socket_func
    raise ConnectionResetError(*exc.args)
ConnectionResetError: [WinError 64] El nombre de red especificado ya no está disponible
2025-06-11 16:57:53 - INFO - [SERVIDOR INFO]: Servidor escuchando en localhost:8083
2025-06-11 16:57:55 - INFO - [SERVIDOR INFO]: Conexión desde ('127.0.0.1', 65349)
2025-06-11 16:58:00 - WARNING - [SERVIDOR WARNING]: == ESPERA AUTOMÁTICA DE 5 SEGUNDOS ==
2025-06-11 16:58:02 - INFO - [SERVIDOR INFO]: Consultando datos de Incidencias...
2025-06-11 16:58:07 - INFO - package: mysql.connector.plugins
2025-06-11 16:58:07 - INFO - plugin_name: caching_sha2_password
2025-06-11 16:58:07 - INFO - AUTHENTICATION_PLUGIN_CLASS: MySQLCachingSHA2PasswordAuthPlugin
2025-06-11 16:58:12 - INFO - [SERVIDOR INFO]: ID de incidencia recibido: 5
2025-06-11 16:58:17 - ERROR - Unhandled exception in client_connected_cb
transport: <_ProactorSocketTransport closed>
Traceback (most recent call last):
  File "C:\Program Files\WindowsApps\PythonSoftwareFoundation.Python.3.13_3.13.1008.0_x64__qbz5n2kfra8p0\Lib\asyncio\windows_events.py", line 463, in finish_socket_func
    return ov.getresult()
           ~~~~~~~~~~~~^^
OSError: [WinError 64] El nombre de red especificado ya no está disponible

During handling of the above exception, another exception occurred:

Traceback (most recent call last):
  File "c:\Users\nzjha\Desktop\Clon_Github\python_serve\Async\sv.py", line 623, in server_on
    await incidencias_MySQL(writer, reader)  # Placeholder para la función de incidencias
    ^^^^^^^^^^^^^^^^^^^^^^^^^^^^^^^^^^^^^^^
  File "c:\Users\nzjha\Desktop\Clon_Github\python_serve\Async\sv.py", line 146, in incidencias_MySQL
    await update_incidencia(writer, reader)
  File "c:\Users\nzjha\Desktop\Clon_Github\python_serve\Async\sv.py", line 62, in update_incidencia
    incidencia_id = (await reader.read(1024)).decode().strip()
                     ^^^^^^^^^^^^^^^^^^^^^^^
  File "C:\Program Files\WindowsApps\PythonSoftwareFoundation.Python.3.13_3.13.1008.0_x64__qbz5n2kfra8p0\Lib\asyncio\streams.py", line 730, in read
    await self._wait_for_data('read')
  File "C:\Program Files\WindowsApps\PythonSoftwareFoundation.Python.3.13_3.13.1008.0_x64__qbz5n2kfra8p0\Lib\asyncio\streams.py", line 539, in _wait_for_data
    await self._waiter
  File "C:\Program Files\WindowsApps\PythonSoftwareFoundation.Python.3.13_3.13.1008.0_x64__qbz5n2kfra8p0\Lib\asyncio\proactor_events.py", line 286, in _loop_reading
    length = fut.result()
  File "C:\Program Files\WindowsApps\PythonSoftwareFoundation.Python.3.13_3.13.1008.0_x64__qbz5n2kfra8p0\Lib\asyncio\windows_events.py", line 804, in _poll
    value = callback(transferred, key, ov)
  File "C:\Program Files\WindowsApps\PythonSoftwareFoundation.Python.3.13_3.13.1008.0_x64__qbz5n2kfra8p0\Lib\asyncio\windows_events.py", line 467, in finish_socket_func
    raise ConnectionResetError(*exc.args)
ConnectionResetError: [WinError 64] El nombre de red especificado ya no está disponible
2025-06-12 10:09:06 - INFO - [SERVIDOR INFO]: Servidor escuchando en localhost:8083
2025-06-12 10:09:10 - INFO - [SERVIDOR INFO]: Conexión desde ('127.0.0.1', 51930)
2025-06-12 10:09:15 - WARNING - [SERVIDOR WARNING]: == ESPERA AUTOMÁTICA DE 5 SEGUNDOS ==
2025-06-12 10:10:53 - INFO - [SERVIDOR INFO]: Consultando datos de Incidencias...
2025-06-12 10:11:02 - WARNING - [SERVIDOR WARNING]: == ESPERA AUTOMÁTICA DE 5 SEGUNDOS ==
2025-06-12 10:11:02 - ERROR - Unhandled exception in client_connected_cb
transport: <_ProactorSocketTransport closed>
Traceback (most recent call last):
  File "C:\Program Files\WindowsApps\PythonSoftwareFoundation.Python.3.13_3.13.1008.0_x64__qbz5n2kfra8p0\Lib\asyncio\windows_events.py", line 463, in finish_socket_func
    return ov.getresult()
           ~~~~~~~~~~~~^^
OSError: [WinError 64] El nombre de red especificado ya no está disponible

During handling of the above exception, another exception occurred:

Traceback (most recent call last):
  File "c:\Users\nzjha\Desktop\Clon_Github\python_serve\Async\sv.py", line 598, in server_on
    await writer.drain()
  File "C:\Program Files\WindowsApps\PythonSoftwareFoundation.Python.3.13_3.13.1008.0_x64__qbz5n2kfra8p0\Lib\asyncio\streams.py", line 374, in drain
    raise exc
  File "C:\Program Files\WindowsApps\PythonSoftwareFoundation.Python.3.13_3.13.1008.0_x64__qbz5n2kfra8p0\Lib\asyncio\proactor_events.py", line 286, in _loop_reading
    length = fut.result()
  File "C:\Program Files\WindowsApps\PythonSoftwareFoundation.Python.3.13_3.13.1008.0_x64__qbz5n2kfra8p0\Lib\asyncio\windows_events.py", line 804, in _poll
    value = callback(transferred, key, ov)
  File "C:\Program Files\WindowsApps\PythonSoftwareFoundation.Python.3.13_3.13.1008.0_x64__qbz5n2kfra8p0\Lib\asyncio\windows_events.py", line 467, in finish_socket_func
    raise ConnectionResetError(*exc.args)
ConnectionResetError: [WinError 64] El nombre de red especificado ya no está disponible
2025-06-12 10:12:29 - INFO - [SERVIDOR INFO]: Servidor escuchando en localhost:8083
2025-06-12 10:12:29 - INFO - [SERVIDOR INFO]: Conexión desde ('127.0.0.1', 52218)
2025-06-12 10:12:34 - WARNING - [SERVIDOR WARNING]: == ESPERA AUTOMÁTICA DE 5 SEGUNDOS ==
2025-06-12 10:12:36 - INFO - [SERVIDOR INFO]: Consultando datos de Incidencias...
2025-06-12 10:12:39 - INFO - package: mysql.connector.plugins
2025-06-12 10:12:39 - INFO - plugin_name: caching_sha2_password
2025-06-12 10:12:39 - INFO - AUTHENTICATION_PLUGIN_CLASS: MySQLCachingSHA2PasswordAuthPlugin
2025-06-12 10:12:39 - ERROR - Unhandled exception in client_connected_cb
transport: <_ProactorSocketTransport fd=1084 read=<_OverlappedFuture pending cb=[_ProactorReadPipeTransport._loop_reading()]>>
Traceback (most recent call last):
  File "c:\Users\nzjha\Desktop\Clon_Github\python_serve\Async\sv.py", line 642, in server_on
    await incidencias_MySQL(writer, reader)  # Placeholder para la función de incidencias
    ^^^^^^^^^^^^^^^^^^^^^^^^^^^^^^^^^^^^^^^
  File "c:\Users\nzjha\Desktop\Clon_Github\python_serve\Async\sv.py", line 161, in incidencias_MySQL
    await consult_incidencias(writer, reader)
  File "c:\Users\nzjha\Desktop\Clon_Github\python_serve\Async\sv.py", line 133, in consult_incidencias
    crs.execute(f"select ter.nombre , ter.estado, u.nombre, z.nombre, i.fecha_reportada, i.descripcion, tec.nombre "\
    ~~~~~~~~~~~^^^^^^^^^^^^^^^^^^^^^^^^^^^^^^^^^^^^^^^^^^^^^^^^^^^^^^^^^^^^^^^^^^^^^^^^^^^^^^^^^^^^^^^^^^^^^^^^^^^^^^
        "from terminal ter inner join ubicacion u on ter.ubicacion_id = u.id"\
        ^^^^^^^^^^^^^^^^^^^^^^^^^^^^^^^^^^^^^^^^^^^^^^^^^^^^^^^^^^^^^^^^^^^^^^
    ...<2 lines>...
        "inner join tecnico tec on i.tecnico_id = tec.id "\
        ^^^^^^^^^^^^^^^^^^^^^^^^^^^^^^^^^^^^^^^^^^^^^^^^^^^
        "where ter.estado like '%averiado%' and i.fecha_solucion is NULL and i.solucionada is false")
        ^^^^^^^^^^^^^^^^^^^^^^^^^^^^^^^^^^^^^^^^^^^^^^^^^^^^^^^^^^^^^^^^^^^^^^^^^^^^^^^^^^^^^^^^^^^^^
  File "C:\Users\nzjha\AppData\Local\Packages\PythonSoftwareFoundation.Python.3.13_qbz5n2kfra8p0\LocalCache\local-packages\Python313\site-packages\mysql\connector\cursor.py", line 418, in execute
    self._connection.cmd_query(
    ~~~~~~~~~~~~~~~~~~~~~~~~~~^
        self._stmt_partition["mappable_stmt"],
        ^^^^^^^^^^^^^^^^^^^^^^^^^^^^^^^^^^^^^^
        read_timeout=self._read_timeout,
        ^^^^^^^^^^^^^^^^^^^^^^^^^^^^^^^^
        write_timeout=self._write_timeout,
        ^^^^^^^^^^^^^^^^^^^^^^^^^^^^^^^^^^
    )
    ^
  File "C:\Users\nzjha\AppData\Local\Packages\PythonSoftwareFoundation.Python.3.13_qbz5n2kfra8p0\LocalCache\local-packages\Python313\site-packages\mysql\connector\opentelemetry\context_propagation.py", line 97, in wrapper
    return method(cnx, *args, **kwargs)
  File "C:\Users\nzjha\AppData\Local\Packages\PythonSoftwareFoundation.Python.3.13_qbz5n2kfra8p0\LocalCache\local-packages\Python313\site-packages\mysql\connector\_decorating.py", line 89, in handle_cnx_method
    raise err
  File "C:\Users\nzjha\AppData\Local\Packages\PythonSoftwareFoundation.Python.3.13_qbz5n2kfra8p0\LocalCache\local-packages\Python313\site-packages\mysql\connector\_decorating.py", line 85, in handle_cnx_method
    return cnx_method(cnx, *args, **kwargs)
  File "C:\Users\nzjha\AppData\Local\Packages\PythonSoftwareFoundation.Python.3.13_qbz5n2kfra8p0\LocalCache\local-packages\Python313\site-packages\mysql\connector\connection.py", line 984, in cmd_query
    result = self._handle_result(
        self._send_cmd(
    ...<6 lines>...
        write_timeout,
    )
  File "C:\Users\nzjha\AppData\Local\Packages\PythonSoftwareFoundation.Python.3.13_qbz5n2kfra8p0\LocalCache\local-packages\Python313\site-packages\mysql\connector\_decorating.py", line 89, in handle_cnx_method
    raise err
  File "C:\Users\nzjha\AppData\Local\Packages\PythonSoftwareFoundation.Python.3.13_qbz5n2kfra8p0\LocalCache\local-packages\Python313\site-packages\mysql\connector\_decorating.py", line 85, in handle_cnx_method
    return cnx_method(cnx, *args, **kwargs)
  File "C:\Users\nzjha\AppData\Local\Packages\PythonSoftwareFoundation.Python.3.13_qbz5n2kfra8p0\LocalCache\local-packages\Python313\site-packages\mysql\connector\connection.py", line 745, in _handle_result
    raise get_exception(packet)
mysql.connector.errors.ProgrammingError: 1054 (42S22): Unknown column 'ter.idinner' in 'on clause'
2025-06-12 10:13:38 - INFO - [SERVIDOR INFO]: Servidor escuchando en localhost:8083
2025-06-12 10:13:41 - INFO - [SERVIDOR INFO]: Conexión desde ('127.0.0.1', 52291)
2025-06-12 10:13:46 - WARNING - [SERVIDOR WARNING]: == ESPERA AUTOMÁTICA DE 5 SEGUNDOS ==
2025-06-12 10:13:48 - INFO - [SERVIDOR INFO]: Consultando datos de Incidencias...
2025-06-12 10:13:53 - INFO - package: mysql.connector.plugins
2025-06-12 10:13:53 - INFO - plugin_name: caching_sha2_password
2025-06-12 10:13:53 - INFO - AUTHENTICATION_PLUGIN_CLASS: MySQLCachingSHA2PasswordAuthPlugin
2025-06-12 10:14:10 - INFO - [SERVIDOR INFO]: Tecnico recibido: 3
2025-06-12 10:14:17 - INFO - [SERVIDOR INFO]: Terminal recibido: 4
2025-06-12 10:14:23 - INFO - [SERVIDOR INFO]: Descripción recibida: sda
2025-06-12 10:14:38 - INFO - [SERVIDOR INFO]: Fecha y hora recibida: 2025-06-13 12:00:01
2025-06-12 10:14:38 - INFO - [SERVIDOR INFO]: Incidencia para tecnico 3 y terminal 4 insertada correctamente en la base de datos.
2025-06-12 11:24:35 - INFO - [SERVIDOR INFO]: Servidor escuchando en localhost:8083
2025-06-12 11:24:36 - INFO - [SERVIDOR INFO]: Conexión desde ('127.0.0.1', 53429)
2025-06-12 11:24:41 - WARNING - [SERVIDOR WARNING]: == ESPERA AUTOMÁTICA DE 5 SEGUNDOS ==
2025-06-12 11:24:44 - INFO - [SERVIDOR INFO]: Consultando datos de Incidencias...
2025-06-12 11:24:54 - WARNING - [SERVIDOR WARNING]: == ESPERA AUTOMÁTICA DE 5 SEGUNDOS ==
2025-06-12 11:24:58 - INFO - [SERVIDOR INFO]: Consultando datos de Incidencias...
2025-06-12 11:25:08 - WARNING - [SERVIDOR WARNING]: == ESPERA AUTOMÁTICA DE 5 SEGUNDOS ==
2025-06-12 11:25:11 - INFO - [SERVIDOR INFO]: Consultando datos de Incidencias...
2025-06-12 11:25:15 - INFO - package: mysql.connector.plugins
2025-06-12 11:25:15 - INFO - plugin_name: caching_sha2_password
2025-06-12 11:25:15 - INFO - AUTHENTICATION_PLUGIN_CLASS: MySQLCachingSHA2PasswordAuthPlugin
2025-06-12 11:25:23 - ERROR - Unhandled exception in client_connected_cb
transport: <_ProactorSocketTransport closed>
Traceback (most recent call last):
  File "C:\Program Files\WindowsApps\PythonSoftwareFoundation.Python.3.13_3.13.1008.0_x64__qbz5n2kfra8p0\Lib\asyncio\windows_events.py", line 463, in finish_socket_func
    return ov.getresult()
           ~~~~~~~~~~~~^^
OSError: [WinError 64] El nombre de red especificado ya no está disponible

During handling of the above exception, another exception occurred:

Traceback (most recent call last):
  File "c:\Users\nzjha\Desktop\Clon_Github\python_serve\Async\sv.py", line 700, in server_on
    await incidencias_MySQL(writer, reader)  # Placeholder para la función de incidencias
    ^^^^^^^^^^^^^^^^^^^^^^^^^^^^^^^^^^^^^^^
  File "c:\Users\nzjha\Desktop\Clon_Github\python_serve\Async\sv.py", line 202, in incidencias_MySQL
    await update_incidencia(writer, reader)
  File "c:\Users\nzjha\Desktop\Clon_Github\python_serve\Async\sv.py", line 69, in update_incidencia
    incidencia_id = (await reader.read(1024)).decode().strip()
                     ^^^^^^^^^^^^^^^^^^^^^^^
  File "C:\Program Files\WindowsApps\PythonSoftwareFoundation.Python.3.13_3.13.1008.0_x64__qbz5n2kfra8p0\Lib\asyncio\streams.py", line 730, in read
    await self._wait_for_data('read')
  File "C:\Program Files\WindowsApps\PythonSoftwareFoundation.Python.3.13_3.13.1008.0_x64__qbz5n2kfra8p0\Lib\asyncio\streams.py", line 539, in _wait_for_data
    await self._waiter
  File "C:\Program Files\WindowsApps\PythonSoftwareFoundation.Python.3.13_3.13.1008.0_x64__qbz5n2kfra8p0\Lib\asyncio\proactor_events.py", line 286, in _loop_reading
    length = fut.result()
  File "C:\Program Files\WindowsApps\PythonSoftwareFoundation.Python.3.13_3.13.1008.0_x64__qbz5n2kfra8p0\Lib\asyncio\windows_events.py", line 804, in _poll
    value = callback(transferred, key, ov)
  File "C:\Program Files\WindowsApps\PythonSoftwareFoundation.Python.3.13_3.13.1008.0_x64__qbz5n2kfra8p0\Lib\asyncio\windows_events.py", line 467, in finish_socket_func
    raise ConnectionResetError(*exc.args)
ConnectionResetError: [WinError 64] El nombre de red especificado ya no está disponible
2025-06-12 11:25:40 - INFO - [SERVIDOR INFO]: Servidor escuchando en localhost:8083
2025-06-12 11:25:42 - INFO - [SERVIDOR INFO]: Conexión desde ('127.0.0.1', 53454)
2025-06-12 11:25:47 - WARNING - [SERVIDOR WARNING]: == ESPERA AUTOMÁTICA DE 5 SEGUNDOS ==
2025-06-12 11:25:55 - INFO - [SERVIDOR INFO]: Consultando datos de Incidencias...
2025-06-12 11:26:04 - INFO - package: mysql.connector.plugins
2025-06-12 11:26:04 - INFO - plugin_name: caching_sha2_password
2025-06-12 11:26:04 - INFO - AUTHENTICATION_PLUGIN_CLASS: MySQLCachingSHA2PasswordAuthPlugin
2025-06-12 11:26:22 - INFO - [SERVIDOR INFO]: ID de incidencia recibido: 3
2025-06-12 11:26:28 - INFO - [SERVIDOR INFO]: Incidencia 3 actualizada correctamente.
2025-06-12 11:26:45 - INFO - [SERVIDOR INFO]: Tecnico recibido: 1
2025-06-12 11:26:49 - INFO - [SERVIDOR INFO]: Terminal recibido: 3
2025-06-12 11:26:52 - INFO - [SERVIDOR INFO]: Descripción recibida: 3
2025-06-12 11:26:56 - INFO - [SERVIDOR INFO]: Fecha y hora recibida: jodida
2025-06-12 11:26:56 - ERROR - Unhandled exception in client_connected_cb
transport: <_ProactorSocketTransport fd=1092 read=<_OverlappedFuture pending cb=[_ProactorReadPipeTransport._loop_reading()]>>
Traceback (most recent call last):
  File "c:\Users\nzjha\Desktop\Clon_Github\python_serve\Async\sv.py", line 700, in server_on
    await incidencias_MySQL(writer, reader)  # Placeholder para la función de incidencias
    ^^^^^^^^^^^^^^^^^^^^^^^^^^^^^^^^^^^^^^^
  File "c:\Users\nzjha\Desktop\Clon_Github\python_serve\Async\sv.py", line 202, in incidencias_MySQL
    await update_incidencia(writer, reader)
  File "c:\Users\nzjha\Desktop\Clon_Github\python_serve\Async\sv.py", line 99, in update_incidencia
    await incidencias_MySQL(writer, reader)
  File "c:\Users\nzjha\Desktop\Clon_Github\python_serve\Async\sv.py", line 200, in incidencias_MySQL
    await add_incidencia(writer, reader)
  File "c:\Users\nzjha\Desktop\Clon_Github\python_serve\Async\sv.py", line 159, in add_incidencia
    insertar.execute(query, values)
    ~~~~~~~~~~~~~~~~^^^^^^^^^^^^^^^
  File "C:\Users\nzjha\AppData\Local\Packages\PythonSoftwareFoundation.Python.3.13_qbz5n2kfra8p0\LocalCache\local-packages\Python313\site-packages\mysql\connector\cursor.py", line 418, in execute
    self._connection.cmd_query(
    ~~~~~~~~~~~~~~~~~~~~~~~~~~^
        self._stmt_partition["mappable_stmt"],
        ^^^^^^^^^^^^^^^^^^^^^^^^^^^^^^^^^^^^^^
        read_timeout=self._read_timeout,
        ^^^^^^^^^^^^^^^^^^^^^^^^^^^^^^^^
        write_timeout=self._write_timeout,
        ^^^^^^^^^^^^^^^^^^^^^^^^^^^^^^^^^^
    )
    ^
  File "C:\Users\nzjha\AppData\Local\Packages\PythonSoftwareFoundation.Python.3.13_qbz5n2kfra8p0\LocalCache\local-packages\Python313\site-packages\mysql\connector\opentelemetry\context_propagation.py", line 97, in wrapper
    return method(cnx, *args, **kwargs)
  File "C:\Users\nzjha\AppData\Local\Packages\PythonSoftwareFoundation.Python.3.13_qbz5n2kfra8p0\LocalCache\local-packages\Python313\site-packages\mysql\connector\_decorating.py", line 89, in handle_cnx_method
    raise err
  File "C:\Users\nzjha\AppData\Local\Packages\PythonSoftwareFoundation.Python.3.13_qbz5n2kfra8p0\LocalCache\local-packages\Python313\site-packages\mysql\connector\_decorating.py", line 85, in handle_cnx_method
    return cnx_method(cnx, *args, **kwargs)
  File "C:\Users\nzjha\AppData\Local\Packages\PythonSoftwareFoundation.Python.3.13_qbz5n2kfra8p0\LocalCache\local-packages\Python313\site-packages\mysql\connector\connection.py", line 984, in cmd_query
    result = self._handle_result(
        self._send_cmd(
    ...<6 lines>...
        write_timeout,
    )
  File "C:\Users\nzjha\AppData\Local\Packages\PythonSoftwareFoundation.Python.3.13_qbz5n2kfra8p0\LocalCache\local-packages\Python313\site-packages\mysql\connector\_decorating.py", line 89, in handle_cnx_method
    raise err
  File "C:\Users\nzjha\AppData\Local\Packages\PythonSoftwareFoundation.Python.3.13_qbz5n2kfra8p0\LocalCache\local-packages\Python313\site-packages\mysql\connector\_decorating.py", line 85, in handle_cnx_method
    return cnx_method(cnx, *args, **kwargs)
  File "C:\Users\nzjha\AppData\Local\Packages\PythonSoftwareFoundation.Python.3.13_qbz5n2kfra8p0\LocalCache\local-packages\Python313\site-packages\mysql\connector\connection.py", line 745, in _handle_result
    raise get_exception(packet)
mysql.connector.errors.DataError: 1292 (22007): Incorrect datetime value: 'jodida' for column 'fecha_reportada' at row 1
2025-06-12 11:27:10 - INFO - [SERVIDOR INFO]: Conexión desde ('127.0.0.1', 53479)
2025-06-12 11:27:15 - WARNING - [SERVIDOR WARNING]: == ESPERA AUTOMÁTICA DE 5 SEGUNDOS ==
2025-06-12 12:48:18 - INFO - [SERVIDOR INFO]: Servidor escuchando en localhost:8083
2025-06-12 12:48:35 - INFO - [SERVIDOR INFO]: Conexión desde ('127.0.0.1', 54738)
2025-06-12 12:48:40 - WARNING - [SERVIDOR WARNING]: == ESPERA AUTOMÁTICA DE 5 SEGUNDOS ==
2025-06-12 12:48:43 - INFO - [SERVIDOR INFO]: Consultando datos de Incidencias...
2025-06-12 12:48:46 - INFO - package: mysql.connector.plugins
2025-06-12 12:48:46 - INFO - plugin_name: caching_sha2_password
2025-06-12 12:48:46 - INFO - AUTHENTICATION_PLUGIN_CLASS: MySQLCachingSHA2PasswordAuthPlugin
2025-06-12 12:51:38 - INFO - [SERVIDOR INFO]: Servidor escuchando en localhost:8083
2025-06-12 12:51:45 - INFO - [SERVIDOR INFO]: Conexión desde ('127.0.0.1', 54827)
2025-06-12 12:51:50 - WARNING - [SERVIDOR WARNING]: == ESPERA AUTOMÁTICA DE 5 SEGUNDOS ==
2025-06-12 12:51:54 - INFO - [SERVIDOR INFO]: Consultando datos de Incidencias...
2025-06-12 12:52:00 - INFO - package: mysql.connector.plugins
2025-06-12 12:52:00 - INFO - plugin_name: caching_sha2_password
2025-06-12 12:52:00 - INFO - AUTHENTICATION_PLUGIN_CLASS: MySQLCachingSHA2PasswordAuthPlugin
2025-06-12 12:52:26 - INFO - [SERVIDOR INFO]: Tecnico recibido: 4
2025-06-12 12:52:31 - INFO - [SERVIDOR INFO]: Terminal recibido: 4
2025-06-12 12:52:33 - INFO - [SERVIDOR INFO]: Descripción recibida: 4
2025-06-12 12:52:36 - INFO - [SERVIDOR INFO]: Fecha y hora recibida: DKS
2025-06-12 12:52:36 - ERROR - Unhandled exception in client_connected_cb
transport: <_ProactorSocketTransport fd=1088 read=<_OverlappedFuture pending cb=[_ProactorReadPipeTransport._loop_reading()]>>
Traceback (most recent call last):
  File "c:\Users\nzjha\Desktop\Clon_Github\python_serve\Async\sv.py", line 707, in server_on
    await incidencias_MySQL(writer, reader)  # Placeholder para la función de incidencias
    ^^^^^^^^^^^^^^^^^^^^^^^^^^^^^^^^^^^^^^^
  File "c:\Users\nzjha\Desktop\Clon_Github\python_serve\Async\sv.py", line 205, in incidencias_MySQL
    await consult_incidencias(writer, reader)
  File "c:\Users\nzjha\Desktop\Clon_Github\python_serve\Async\sv.py", line 188, in consult_incidencias
    await incidencias_MySQL(writer, reader)  # Volver al menú de incidencias
    ^^^^^^^^^^^^^^^^^^^^^^^^^^^^^^^^^^^^^^^
  File "c:\Users\nzjha\Desktop\Clon_Github\python_serve\Async\sv.py", line 207, in incidencias_MySQL
    await add_incidencia(writer, reader)
  File "c:\Users\nzjha\Desktop\Clon_Github\python_serve\Async\sv.py", line 159, in add_incidencia
    insertar.execute(query, values)
    ~~~~~~~~~~~~~~~~^^^^^^^^^^^^^^^
  File "C:\Users\nzjha\AppData\Local\Packages\PythonSoftwareFoundation.Python.3.13_qbz5n2kfra8p0\LocalCache\local-packages\Python313\site-packages\mysql\connector\cursor.py", line 418, in execute
    self._connection.cmd_query(
    ~~~~~~~~~~~~~~~~~~~~~~~~~~^
        self._stmt_partition["mappable_stmt"],
        ^^^^^^^^^^^^^^^^^^^^^^^^^^^^^^^^^^^^^^
        read_timeout=self._read_timeout,
        ^^^^^^^^^^^^^^^^^^^^^^^^^^^^^^^^
        write_timeout=self._write_timeout,
        ^^^^^^^^^^^^^^^^^^^^^^^^^^^^^^^^^^
    )
    ^
  File "C:\Users\nzjha\AppData\Local\Packages\PythonSoftwareFoundation.Python.3.13_qbz5n2kfra8p0\LocalCache\local-packages\Python313\site-packages\mysql\connector\opentelemetry\context_propagation.py", line 97, in wrapper
    return method(cnx, *args, **kwargs)
  File "C:\Users\nzjha\AppData\Local\Packages\PythonSoftwareFoundation.Python.3.13_qbz5n2kfra8p0\LocalCache\local-packages\Python313\site-packages\mysql\connector\_decorating.py", line 89, in handle_cnx_method
    raise err
  File "C:\Users\nzjha\AppData\Local\Packages\PythonSoftwareFoundation.Python.3.13_qbz5n2kfra8p0\LocalCache\local-packages\Python313\site-packages\mysql\connector\_decorating.py", line 85, in handle_cnx_method
    return cnx_method(cnx, *args, **kwargs)
  File "C:\Users\nzjha\AppData\Local\Packages\PythonSoftwareFoundation.Python.3.13_qbz5n2kfra8p0\LocalCache\local-packages\Python313\site-packages\mysql\connector\connection.py", line 984, in cmd_query
    result = self._handle_result(
        self._send_cmd(
    ...<6 lines>...
        write_timeout,
    )
  File "C:\Users\nzjha\AppData\Local\Packages\PythonSoftwareFoundation.Python.3.13_qbz5n2kfra8p0\LocalCache\local-packages\Python313\site-packages\mysql\connector\_decorating.py", line 89, in handle_cnx_method
    raise err
  File "C:\Users\nzjha\AppData\Local\Packages\PythonSoftwareFoundation.Python.3.13_qbz5n2kfra8p0\LocalCache\local-packages\Python313\site-packages\mysql\connector\_decorating.py", line 85, in handle_cnx_method
    return cnx_method(cnx, *args, **kwargs)
  File "C:\Users\nzjha\AppData\Local\Packages\PythonSoftwareFoundation.Python.3.13_qbz5n2kfra8p0\LocalCache\local-packages\Python313\site-packages\mysql\connector\connection.py", line 745, in _handle_result
    raise get_exception(packet)
mysql.connector.errors.DataError: 1292 (22007): Incorrect datetime value: 'DKS' for column 'fecha_reportada' at row 1
2025-06-12 12:52:51 - INFO - [SERVIDOR INFO]: Conexión desde ('127.0.0.1', 54837)
2025-06-12 12:52:56 - WARNING - [SERVIDOR WARNING]: == ESPERA AUTOMÁTICA DE 5 SEGUNDOS ==
2025-06-12 12:53:01 - INFO - [SERVIDOR INFO]: Consultando datos de Incidencias...
2025-06-12 12:53:07 - ERROR - Unhandled exception in client_connected_cb
transport: <_ProactorSocketTransport closed>
Traceback (most recent call last):
  File "C:\Program Files\WindowsApps\PythonSoftwareFoundation.Python.3.13_3.13.1008.0_x64__qbz5n2kfra8p0\Lib\asyncio\windows_events.py", line 463, in finish_socket_func
    return ov.getresult()
           ~~~~~~~~~~~~^^
OSError: [WinError 64] El nombre de red especificado ya no está disponible

During handling of the above exception, another exception occurred:

Traceback (most recent call last):
  File "c:\Users\nzjha\Desktop\Clon_Github\python_serve\Async\sv.py", line 707, in server_on
    await incidencias_MySQL(writer, reader)  # Placeholder para la función de incidencias
    ^^^^^^^^^^^^^^^^^^^^^^^^^^^^^^^^^^^^^^^
  File "c:\Users\nzjha\Desktop\Clon_Github\python_serve\Async\sv.py", line 202, in incidencias_MySQL
    message = (await reader.read(1024)).decode().strip()
               ^^^^^^^^^^^^^^^^^^^^^^^
  File "C:\Program Files\WindowsApps\PythonSoftwareFoundation.Python.3.13_3.13.1008.0_x64__qbz5n2kfra8p0\Lib\asyncio\streams.py", line 730, in read
    await self._wait_for_data('read')
  File "C:\Program Files\WindowsApps\PythonSoftwareFoundation.Python.3.13_3.13.1008.0_x64__qbz5n2kfra8p0\Lib\asyncio\streams.py", line 539, in _wait_for_data
    await self._waiter
  File "C:\Program Files\WindowsApps\PythonSoftwareFoundation.Python.3.13_3.13.1008.0_x64__qbz5n2kfra8p0\Lib\asyncio\proactor_events.py", line 286, in _loop_reading
    length = fut.result()
  File "C:\Program Files\WindowsApps\PythonSoftwareFoundation.Python.3.13_3.13.1008.0_x64__qbz5n2kfra8p0\Lib\asyncio\windows_events.py", line 804, in _poll
    value = callback(transferred, key, ov)
  File "C:\Program Files\WindowsApps\PythonSoftwareFoundation.Python.3.13_3.13.1008.0_x64__qbz5n2kfra8p0\Lib\asyncio\windows_events.py", line 467, in finish_socket_func
    raise ConnectionResetError(*exc.args)
ConnectionResetError: [WinError 64] El nombre de red especificado ya no está disponible
2025-06-12 14:20:51 - INFO - [SERVIDOR INFO]: Servidor escuchando en localhost:8083
2025-06-12 14:20:57 - INFO - [SERVIDOR INFO]: Conexión desde ('127.0.0.1', 56880)
2025-06-12 14:21:02 - WARNING - [SERVIDOR WARNING]: == ESPERA AUTOMÁTICA DE 5 SEGUNDOS ==
2025-06-12 14:21:24 - INFO - [SERVIDOR INFO]: Servidor escuchando en localhost:8083
2025-06-12 14:21:24 - INFO - [SERVIDOR INFO]: Conexión desde ('127.0.0.1', 56892)
2025-06-12 14:21:29 - WARNING - [SERVIDOR WARNING]: == ESPERA AUTOMÁTICA DE 5 SEGUNDOS ==
2025-06-12 14:21:34 - INFO - [SERVIDOR INFO]: Consultando datos de Incidencias...
2025-06-12 14:21:47 - WARNING - [SERVIDOR WARNING]: == ESPERA AUTOMÁTICA DE 5 SEGUNDOS ==
2025-06-12 14:46:30 - ERROR - Unhandled exception in client_connected_cb
transport: <_ProactorSocketTransport closed>
Traceback (most recent call last):
  File "C:\Program Files\WindowsApps\PythonSoftwareFoundation.Python.3.13_3.13.1008.0_x64__qbz5n2kfra8p0\Lib\asyncio\windows_events.py", line 463, in finish_socket_func
    return ov.getresult()
           ~~~~~~~~~~~~^^
OSError: [WinError 64] El nombre de red especificado ya no está disponible

During handling of the above exception, another exception occurred:

Traceback (most recent call last):
  File "c:\Users\nzjha\Desktop\Clon_Github\python_serve\Async\sv.py", line 682, in server_on
    while True:
              ^
  File "C:\Program Files\WindowsApps\PythonSoftwareFoundation.Python.3.13_3.13.1008.0_x64__qbz5n2kfra8p0\Lib\asyncio\streams.py", line 730, in read
    await self._wait_for_data('read')
  File "C:\Program Files\WindowsApps\PythonSoftwareFoundation.Python.3.13_3.13.1008.0_x64__qbz5n2kfra8p0\Lib\asyncio\streams.py", line 539, in _wait_for_data
    await self._waiter
  File "C:\Program Files\WindowsApps\PythonSoftwareFoundation.Python.3.13_3.13.1008.0_x64__qbz5n2kfra8p0\Lib\asyncio\proactor_events.py", line 286, in _loop_reading
    length = fut.result()
  File "C:\Program Files\WindowsApps\PythonSoftwareFoundation.Python.3.13_3.13.1008.0_x64__qbz5n2kfra8p0\Lib\asyncio\windows_events.py", line 804, in _poll
    value = callback(transferred, key, ov)
  File "C:\Program Files\WindowsApps\PythonSoftwareFoundation.Python.3.13_3.13.1008.0_x64__qbz5n2kfra8p0\Lib\asyncio\windows_events.py", line 467, in finish_socket_func
    raise ConnectionResetError(*exc.args)
ConnectionResetError: [WinError 64] El nombre de red especificado ya no está disponible
2025-06-12 14:46:35 - INFO - [SERVIDOR INFO]: Servidor escuchando en localhost:8083
2025-06-12 14:46:36 - INFO - [SERVIDOR INFO]: Conexión desde ('127.0.0.1', 57444)
2025-06-12 14:46:41 - WARNING - [SERVIDOR WARNING]: == ESPERA AUTOMÁTICA DE 5 SEGUNDOS ==
2025-06-12 14:47:24 - INFO - [SERVIDOR INFO]: Consultando datos de Incidencias...
2025-06-12 14:47:36 - INFO - package: mysql.connector.plugins
2025-06-12 14:47:36 - INFO - plugin_name: caching_sha2_password
2025-06-12 14:47:36 - INFO - AUTHENTICATION_PLUGIN_CLASS: MySQLCachingSHA2PasswordAuthPlugin
2025-06-12 14:47:47 - INFO - [SERVIDOR INFO]: ID de incidencia recibido: 3
2025-06-12 14:47:49 - INFO - [SERVIDOR INFO]: Incidencia 3 actualizada correctamente.
2025-06-12 14:55:42 - INFO - [SERVIDOR INFO]: Servidor escuchando en localhost:8083
2025-06-12 14:55:43 - INFO - [SERVIDOR INFO]: Conexión desde ('127.0.0.1', 57579)
2025-06-12 14:55:48 - WARNING - [SERVIDOR WARNING]: == ESPERA AUTOMÁTICA DE 5 SEGUNDOS ==
2025-06-12 14:55:50 - INFO - [SERVIDOR INFO]: Consultando datos de Incidencias...
2025-06-12 14:55:55 - INFO - package: mysql.connector.plugins
2025-06-12 14:55:55 - INFO - plugin_name: caching_sha2_password
2025-06-12 14:55:55 - INFO - AUTHENTICATION_PLUGIN_CLASS: MySQLCachingSHA2PasswordAuthPlugin
2025-06-12 14:55:59 - INFO - [SERVIDOR INFO]: ID de incidencia recibido: 3
2025-06-12 14:56:09 - INFO - [SERVIDOR INFO]: Fecha de solución recibida: 12/06
2025-06-12 14:56:09 - ERROR - Unhandled exception in client_connected_cb
transport: <_ProactorSocketTransport fd=1088 read=<_OverlappedFuture pending cb=[_ProactorReadPipeTransport._loop_reading()]>>
Traceback (most recent call last):
  File "c:\Users\nzjha\Desktop\Clon_Github\python_serve\Async\sv.py", line 713, in server_on
    await incidencias_MySQL(writer, reader)  # Placeholder para la función de incidencias
    ^^^^^^^^^^^^^^^^^^^^^^^^^^^^^^^^^^^^^^^
  File "c:\Users\nzjha\Desktop\Clon_Github\python_serve\Async\sv.py", line 213, in incidencias_MySQL
    await update_incidencia(writer, reader)
  File "c:\Users\nzjha\Desktop\Clon_Github\python_serve\Async\sv.py", line 91, in update_incidencia
    crs.execute(
    ~~~~~~~~~~~^
        f"UPDATE {TABLE_MySQL_2} SET solucionada = %s, fecha_solucion = %s WHERE id = %s",
        ^^^^^^^^^^^^^^^^^^^^^^^^^^^^^^^^^^^^^^^^^^^^^^^^^^^^^^^^^^^^^^^^^^^^^^^^^^^^^^^^^^
        (solucionada, fecha_solucion, incidencia_id)
        ^^^^^^^^^^^^^^^^^^^^^^^^^^^^^^^^^^^^^^^^^^^^
    )
    ^
  File "C:\Users\nzjha\AppData\Local\Packages\PythonSoftwareFoundation.Python.3.13_qbz5n2kfra8p0\LocalCache\local-packages\Python313\site-packages\mysql\connector\cursor.py", line 418, in execute
    self._connection.cmd_query(
    ~~~~~~~~~~~~~~~~~~~~~~~~~~^
        self._stmt_partition["mappable_stmt"],
        ^^^^^^^^^^^^^^^^^^^^^^^^^^^^^^^^^^^^^^
        read_timeout=self._read_timeout,
        ^^^^^^^^^^^^^^^^^^^^^^^^^^^^^^^^
        write_timeout=self._write_timeout,
        ^^^^^^^^^^^^^^^^^^^^^^^^^^^^^^^^^^
    )
    ^
  File "C:\Users\nzjha\AppData\Local\Packages\PythonSoftwareFoundation.Python.3.13_qbz5n2kfra8p0\LocalCache\local-packages\Python313\site-packages\mysql\connector\opentelemetry\context_propagation.py", line 97, in wrapper
    return method(cnx, *args, **kwargs)
  File "C:\Users\nzjha\AppData\Local\Packages\PythonSoftwareFoundation.Python.3.13_qbz5n2kfra8p0\LocalCache\local-packages\Python313\site-packages\mysql\connector\_decorating.py", line 89, in handle_cnx_method
    raise err
  File "C:\Users\nzjha\AppData\Local\Packages\PythonSoftwareFoundation.Python.3.13_qbz5n2kfra8p0\LocalCache\local-packages\Python313\site-packages\mysql\connector\_decorating.py", line 85, in handle_cnx_method
    return cnx_method(cnx, *args, **kwargs)
  File "C:\Users\nzjha\AppData\Local\Packages\PythonSoftwareFoundation.Python.3.13_qbz5n2kfra8p0\LocalCache\local-packages\Python313\site-packages\mysql\connector\connection.py", line 984, in cmd_query
    result = self._handle_result(
        self._send_cmd(
    ...<6 lines>...
        write_timeout,
    )
  File "C:\Users\nzjha\AppData\Local\Packages\PythonSoftwareFoundation.Python.3.13_qbz5n2kfra8p0\LocalCache\local-packages\Python313\site-packages\mysql\connector\_decorating.py", line 89, in handle_cnx_method
    raise err
  File "C:\Users\nzjha\AppData\Local\Packages\PythonSoftwareFoundation.Python.3.13_qbz5n2kfra8p0\LocalCache\local-packages\Python313\site-packages\mysql\connector\_decorating.py", line 85, in handle_cnx_method
    return cnx_method(cnx, *args, **kwargs)
  File "C:\Users\nzjha\AppData\Local\Packages\PythonSoftwareFoundation.Python.3.13_qbz5n2kfra8p0\LocalCache\local-packages\Python313\site-packages\mysql\connector\connection.py", line 745, in _handle_result
    raise get_exception(packet)
mysql.connector.errors.DataError: 1292 (22007): Incorrect datetime value: '12/06' for column 'fecha_solucion' at row 1
2025-06-12 14:56:19 - INFO - [SERVIDOR INFO]: Conexión desde ('127.0.0.1', 57589)
2025-06-12 14:56:24 - WARNING - [SERVIDOR WARNING]: == ESPERA AUTOMÁTICA DE 5 SEGUNDOS ==
2025-06-12 14:56:25 - INFO - [SERVIDOR INFO]: Consultando datos de Incidencias...
2025-06-12 14:56:32 - WARNING - [SERVIDOR WARNING]: == ESPERA AUTOMÁTICA DE 5 SEGUNDOS ==
2025-06-12 14:56:37 - ERROR - Unhandled exception in client_connected_cb
transport: <_ProactorSocketTransport closed>
Traceback (most recent call last):
  File "C:\Program Files\WindowsApps\PythonSoftwareFoundation.Python.3.13_3.13.1008.0_x64__qbz5n2kfra8p0\Lib\asyncio\windows_events.py", line 463, in finish_socket_func
    return ov.getresult()
           ~~~~~~~~~~~~^^
OSError: [WinError 64] El nombre de red especificado ya no está disponible

During handling of the above exception, another exception occurred:

Traceback (most recent call last):
  File "c:\Users\nzjha\Desktop\Clon_Github\python_serve\Async\sv.py", line 688, in server_on
    msg = await reader.read(1024)
          ^^^^^^^^^^^^^^^^^^^^^^^
  File "C:\Program Files\WindowsApps\PythonSoftwareFoundation.Python.3.13_3.13.1008.0_x64__qbz5n2kfra8p0\Lib\asyncio\streams.py", line 730, in read
    await self._wait_for_data('read')
  File "C:\Program Files\WindowsApps\PythonSoftwareFoundation.Python.3.13_3.13.1008.0_x64__qbz5n2kfra8p0\Lib\asyncio\streams.py", line 539, in _wait_for_data
    await self._waiter
  File "C:\Program Files\WindowsApps\PythonSoftwareFoundation.Python.3.13_3.13.1008.0_x64__qbz5n2kfra8p0\Lib\asyncio\proactor_events.py", line 286, in _loop_reading
    length = fut.result()
  File "C:\Program Files\WindowsApps\PythonSoftwareFoundation.Python.3.13_3.13.1008.0_x64__qbz5n2kfra8p0\Lib\asyncio\windows_events.py", line 804, in _poll
    value = callback(transferred, key, ov)
  File "C:\Program Files\WindowsApps\PythonSoftwareFoundation.Python.3.13_3.13.1008.0_x64__qbz5n2kfra8p0\Lib\asyncio\windows_events.py", line 467, in finish_socket_func
    raise ConnectionResetError(*exc.args)
ConnectionResetError: [WinError 64] El nombre de red especificado ya no está disponible
2025-06-12 14:56:40 - INFO - [SERVIDOR INFO]: Conexión desde ('127.0.0.1', 57595)
2025-06-12 14:56:45 - WARNING - [SERVIDOR WARNING]: == ESPERA AUTOMÁTICA DE 5 SEGUNDOS ==
2025-06-12 14:56:47 - INFO - [SERVIDOR INFO]: Consultando datos de Incidencias...
2025-06-12 14:56:53 - INFO - [SERVIDOR INFO]: ID de incidencia recibido: 3
2025-06-12 14:57:16 - INFO - [SERVIDOR INFO]: Fecha de solución recibida: 2025-06-12 14:57:09
2025-06-12 14:57:16 - INFO - [SERVIDOR INFO]: Incidencia 3 actualizada correctamente.
2025-06-12 15:00:47 - INFO - [SERVIDOR INFO]: Servidor escuchando en localhost:8083
2025-06-12 15:00:51 - INFO - [SERVIDOR INFO]: Conexión desde ('127.0.0.1', 57783)
2025-06-12 15:00:56 - WARNING - [SERVIDOR WARNING]: == ESPERA AUTOMÁTICA DE 5 SEGUNDOS ==
2025-06-12 15:00:59 - INFO - [SERVIDOR INFO]: Consultando datos de Incidencias...
2025-06-12 15:01:02 - INFO - package: mysql.connector.plugins
2025-06-12 15:01:02 - INFO - plugin_name: caching_sha2_password
2025-06-12 15:01:02 - INFO - AUTHENTICATION_PLUGIN_CLASS: MySQLCachingSHA2PasswordAuthPlugin
2025-06-12 15:01:05 - INFO - [SERVIDOR INFO]: ID de incidencia recibido: 5
2025-06-12 15:01:26 - INFO - [SERVIDOR INFO]: Fecha de solución recibida: 2025-08-10 09:00:32
2025-06-12 15:01:26 - ERROR - Unhandled exception in client_connected_cb
transport: <_ProactorSocketTransport fd=1088 read=<_OverlappedFuture pending cb=[_ProactorReadPipeTransport._loop_reading()]>>
Traceback (most recent call last):
  File "c:\Users\nzjha\Desktop\Clon_Github\python_serve\Async\sv.py", line 714, in server_on
    await incidencias_MySQL(writer, reader)  # Placeholder para la función de incidencias
    ^^^^^^^^^^^^^^^^^^^^^^^^^^^^^^^^^^^^^^^
  File "c:\Users\nzjha\Desktop\Clon_Github\python_serve\Async\sv.py", line 214, in incidencias_MySQL
    await update_incidencia(writer, reader)
  File "c:\Users\nzjha\Desktop\Clon_Github\python_serve\Async\sv.py", line 92, in update_incidencia
    crs.execute(
    ~~~~~~~~~~~^
        f"UPDATE {TABLE_MySQL_2} SET solucionada = %s, fecha_solucion = %s, WHERE id = %s",
        ^^^^^^^^^^^^^^^^^^^^^^^^^^^^^^^^^^^^^^^^^^^^^^^^^^^^^^^^^^^^^^^^^^^^^^^^^^^^^^^^^^^
        (solucionada, fecha_solucion, incidencia_id)
        ^^^^^^^^^^^^^^^^^^^^^^^^^^^^^^^^^^^^^^^^^^^^
    )
    ^
  File "C:\Users\nzjha\AppData\Local\Packages\PythonSoftwareFoundation.Python.3.13_qbz5n2kfra8p0\LocalCache\local-packages\Python313\site-packages\mysql\connector\cursor.py", line 418, in execute
    self._connection.cmd_query(
    ~~~~~~~~~~~~~~~~~~~~~~~~~~^
        self._stmt_partition["mappable_stmt"],
        ^^^^^^^^^^^^^^^^^^^^^^^^^^^^^^^^^^^^^^
        read_timeout=self._read_timeout,
        ^^^^^^^^^^^^^^^^^^^^^^^^^^^^^^^^
        write_timeout=self._write_timeout,
        ^^^^^^^^^^^^^^^^^^^^^^^^^^^^^^^^^^
    )
    ^
  File "C:\Users\nzjha\AppData\Local\Packages\PythonSoftwareFoundation.Python.3.13_qbz5n2kfra8p0\LocalCache\local-packages\Python313\site-packages\mysql\connector\opentelemetry\context_propagation.py", line 97, in wrapper
    return method(cnx, *args, **kwargs)
  File "C:\Users\nzjha\AppData\Local\Packages\PythonSoftwareFoundation.Python.3.13_qbz5n2kfra8p0\LocalCache\local-packages\Python313\site-packages\mysql\connector\_decorating.py", line 89, in handle_cnx_method
    raise err
  File "C:\Users\nzjha\AppData\Local\Packages\PythonSoftwareFoundation.Python.3.13_qbz5n2kfra8p0\LocalCache\local-packages\Python313\site-packages\mysql\connector\_decorating.py", line 85, in handle_cnx_method
    return cnx_method(cnx, *args, **kwargs)
  File "C:\Users\nzjha\AppData\Local\Packages\PythonSoftwareFoundation.Python.3.13_qbz5n2kfra8p0\LocalCache\local-packages\Python313\site-packages\mysql\connector\connection.py", line 984, in cmd_query
    result = self._handle_result(
        self._send_cmd(
    ...<6 lines>...
        write_timeout,
    )
  File "C:\Users\nzjha\AppData\Local\Packages\PythonSoftwareFoundation.Python.3.13_qbz5n2kfra8p0\LocalCache\local-packages\Python313\site-packages\mysql\connector\_decorating.py", line 89, in handle_cnx_method
    raise err
  File "C:\Users\nzjha\AppData\Local\Packages\PythonSoftwareFoundation.Python.3.13_qbz5n2kfra8p0\LocalCache\local-packages\Python313\site-packages\mysql\connector\_decorating.py", line 85, in handle_cnx_method
    return cnx_method(cnx, *args, **kwargs)
  File "C:\Users\nzjha\AppData\Local\Packages\PythonSoftwareFoundation.Python.3.13_qbz5n2kfra8p0\LocalCache\local-packages\Python313\site-packages\mysql\connector\connection.py", line 745, in _handle_result
    raise get_exception(packet)
mysql.connector.errors.ProgrammingError: 1064 (42000): You have an error in your SQL syntax; check the manual that corresponds to your MySQL server version for the right syntax to use near 'WHERE id = '5'' at line 1
2025-06-12 15:01:36 - INFO - [SERVIDOR INFO]: Conexión desde ('127.0.0.1', 57800)
2025-06-12 15:01:41 - WARNING - [SERVIDOR WARNING]: == ESPERA AUTOMÁTICA DE 5 SEGUNDOS ==
2025-06-12 15:01:52 - INFO - [SERVIDOR INFO]: Consultando datos de Incidencias...
2025-06-12 15:02:00 - INFO - [SERVIDOR INFO]: ID de incidencia recibido: 5
2025-06-12 15:02:29 - INFO - [SERVIDOR INFO]: Fecha de solución recibida: 2025-06-17 09:09:02
2025-06-12 15:02:29 - ERROR - Unhandled exception in client_connected_cb
transport: <_ProactorSocketTransport fd=1096 read=<_OverlappedFuture pending cb=[_ProactorReadPipeTransport._loop_reading()]>>
Traceback (most recent call last):
  File "c:\Users\nzjha\Desktop\Clon_Github\python_serve\Async\sv.py", line 714, in server_on
    await incidencias_MySQL(writer, reader)  # Placeholder para la función de incidencias
    ^^^^^^^^^^^^^^^^^^^^^^^^^^^^^^^^^^^^^^^
  File "c:\Users\nzjha\Desktop\Clon_Github\python_serve\Async\sv.py", line 214, in incidencias_MySQL
    await update_incidencia(writer, reader)
  File "c:\Users\nzjha\Desktop\Clon_Github\python_serve\Async\sv.py", line 92, in update_incidencia
    crs.execute(
    ~~~~~~~~~~~^
        f"UPDATE {TABLE_MySQL_2} SET solucionada = %s, fecha_solucion = %s, WHERE id = %s",
        ^^^^^^^^^^^^^^^^^^^^^^^^^^^^^^^^^^^^^^^^^^^^^^^^^^^^^^^^^^^^^^^^^^^^^^^^^^^^^^^^^^^
        (solucionada, fecha_solucion, incidencia_id)
        ^^^^^^^^^^^^^^^^^^^^^^^^^^^^^^^^^^^^^^^^^^^^
    )
    ^
  File "C:\Users\nzjha\AppData\Local\Packages\PythonSoftwareFoundation.Python.3.13_qbz5n2kfra8p0\LocalCache\local-packages\Python313\site-packages\mysql\connector\cursor.py", line 418, in execute
    self._connection.cmd_query(
    ~~~~~~~~~~~~~~~~~~~~~~~~~~^
        self._stmt_partition["mappable_stmt"],
        ^^^^^^^^^^^^^^^^^^^^^^^^^^^^^^^^^^^^^^
        read_timeout=self._read_timeout,
        ^^^^^^^^^^^^^^^^^^^^^^^^^^^^^^^^
        write_timeout=self._write_timeout,
        ^^^^^^^^^^^^^^^^^^^^^^^^^^^^^^^^^^
    )
    ^
  File "C:\Users\nzjha\AppData\Local\Packages\PythonSoftwareFoundation.Python.3.13_qbz5n2kfra8p0\LocalCache\local-packages\Python313\site-packages\mysql\connector\opentelemetry\context_propagation.py", line 97, in wrapper
    return method(cnx, *args, **kwargs)
  File "C:\Users\nzjha\AppData\Local\Packages\PythonSoftwareFoundation.Python.3.13_qbz5n2kfra8p0\LocalCache\local-packages\Python313\site-packages\mysql\connector\_decorating.py", line 89, in handle_cnx_method
    raise err
  File "C:\Users\nzjha\AppData\Local\Packages\PythonSoftwareFoundation.Python.3.13_qbz5n2kfra8p0\LocalCache\local-packages\Python313\site-packages\mysql\connector\_decorating.py", line 85, in handle_cnx_method
    return cnx_method(cnx, *args, **kwargs)
  File "C:\Users\nzjha\AppData\Local\Packages\PythonSoftwareFoundation.Python.3.13_qbz5n2kfra8p0\LocalCache\local-packages\Python313\site-packages\mysql\connector\connection.py", line 984, in cmd_query
    result = self._handle_result(
        self._send_cmd(
    ...<6 lines>...
        write_timeout,
    )
  File "C:\Users\nzjha\AppData\Local\Packages\PythonSoftwareFoundation.Python.3.13_qbz5n2kfra8p0\LocalCache\local-packages\Python313\site-packages\mysql\connector\_decorating.py", line 89, in handle_cnx_method
    raise err
  File "C:\Users\nzjha\AppData\Local\Packages\PythonSoftwareFoundation.Python.3.13_qbz5n2kfra8p0\LocalCache\local-packages\Python313\site-packages\mysql\connector\_decorating.py", line 85, in handle_cnx_method
    return cnx_method(cnx, *args, **kwargs)
  File "C:\Users\nzjha\AppData\Local\Packages\PythonSoftwareFoundation.Python.3.13_qbz5n2kfra8p0\LocalCache\local-packages\Python313\site-packages\mysql\connector\connection.py", line 745, in _handle_result
    raise get_exception(packet)
mysql.connector.errors.ProgrammingError: 1064 (42000): You have an error in your SQL syntax; check the manual that corresponds to your MySQL server version for the right syntax to use near 'WHERE id = '5'' at line 1
2025-06-12 15:02:43 - INFO - [SERVIDOR INFO]: Conexión desde ('127.0.0.1', 57826)
2025-06-12 15:02:48 - WARNING - [SERVIDOR WARNING]: == ESPERA AUTOMÁTICA DE 5 SEGUNDOS ==
2025-06-12 15:02:49 - INFO - [SERVIDOR INFO]: Consultando datos de Incidencias...
2025-06-12 15:02:57 - INFO - [SERVIDOR INFO]: ID de incidencia recibido: 5
2025-06-12 15:03:16 - INFO - [SERVIDOR INFO]: Fecha de solución recibida: 2025-06-12 13:09:02
2025-06-12 15:03:16 - ERROR - Unhandled exception in client_connected_cb
transport: <_ProactorSocketTransport fd=764 read=<_OverlappedFuture pending cb=[_ProactorReadPipeTransport._loop_reading()]>>
Traceback (most recent call last):
  File "c:\Users\nzjha\Desktop\Clon_Github\python_serve\Async\sv.py", line 714, in server_on
    elif option == "4":
        ^^^^^^^^^^^^^^^
  File "c:\Users\nzjha\Desktop\Clon_Github\python_serve\Async\sv.py", line 214, in incidencias_MySQL
    elif message == "4":
        ^^^^^^^^^^^^^^^^
  File "c:\Users\nzjha\Desktop\Clon_Github\python_serve\Async\sv.py", line 92, in update_incidencia
        f"UPDATE {TABLE_MySQL_2} SET solucionada = %s, fecha_solucion = %s, WHERE id = %s",
        ^^^^^^^^^^^^^^^^^^^^^^^^^^^^^^^^^^^^^^^^^^^^^^^^^^^^^^^^^^^^^^^^^^^^^^^^^^^^^^^^^^^
    ...<2 lines>...
    conn.commit()
    ^
  File "C:\Users\nzjha\AppData\Local\Packages\PythonSoftwareFoundation.Python.3.13_qbz5n2kfra8p0\LocalCache\local-packages\Python313\site-packages\mysql\connector\cursor.py", line 418, in execute
    self._connection.cmd_query(
    ~~~~~~~~~~~~~~~~~~~~~~~~~~^
        self._stmt_partition["mappable_stmt"],
        ^^^^^^^^^^^^^^^^^^^^^^^^^^^^^^^^^^^^^^
        read_timeout=self._read_timeout,
        ^^^^^^^^^^^^^^^^^^^^^^^^^^^^^^^^
        write_timeout=self._write_timeout,
        ^^^^^^^^^^^^^^^^^^^^^^^^^^^^^^^^^^
    )
    ^
  File "C:\Users\nzjha\AppData\Local\Packages\PythonSoftwareFoundation.Python.3.13_qbz5n2kfra8p0\LocalCache\local-packages\Python313\site-packages\mysql\connector\opentelemetry\context_propagation.py", line 97, in wrapper
    return method(cnx, *args, **kwargs)
  File "C:\Users\nzjha\AppData\Local\Packages\PythonSoftwareFoundation.Python.3.13_qbz5n2kfra8p0\LocalCache\local-packages\Python313\site-packages\mysql\connector\_decorating.py", line 89, in handle_cnx_method
    raise err
  File "C:\Users\nzjha\AppData\Local\Packages\PythonSoftwareFoundation.Python.3.13_qbz5n2kfra8p0\LocalCache\local-packages\Python313\site-packages\mysql\connector\_decorating.py", line 85, in handle_cnx_method
    return cnx_method(cnx, *args, **kwargs)
  File "C:\Users\nzjha\AppData\Local\Packages\PythonSoftwareFoundation.Python.3.13_qbz5n2kfra8p0\LocalCache\local-packages\Python313\site-packages\mysql\connector\connection.py", line 984, in cmd_query
    result = self._handle_result(
        self._send_cmd(
    ...<6 lines>...
        write_timeout,
    )
  File "C:\Users\nzjha\AppData\Local\Packages\PythonSoftwareFoundation.Python.3.13_qbz5n2kfra8p0\LocalCache\local-packages\Python313\site-packages\mysql\connector\_decorating.py", line 89, in handle_cnx_method
    raise err
  File "C:\Users\nzjha\AppData\Local\Packages\PythonSoftwareFoundation.Python.3.13_qbz5n2kfra8p0\LocalCache\local-packages\Python313\site-packages\mysql\connector\_decorating.py", line 85, in handle_cnx_method
    return cnx_method(cnx, *args, **kwargs)
  File "C:\Users\nzjha\AppData\Local\Packages\PythonSoftwareFoundation.Python.3.13_qbz5n2kfra8p0\LocalCache\local-packages\Python313\site-packages\mysql\connector\connection.py", line 745, in _handle_result
    raise get_exception(packet)
mysql.connector.errors.ProgrammingError: 1064 (42000): You have an error in your SQL syntax; check the manual that corresponds to your MySQL server version for the right syntax to use near 'WHERE id = '5'' at line 1
2025-06-12 15:03:46 - INFO - [SERVIDOR INFO]: Servidor escuchando en localhost:8083
2025-06-12 15:03:48 - INFO - [SERVIDOR INFO]: Conexión desde ('127.0.0.1', 57851)
2025-06-12 15:03:53 - WARNING - [SERVIDOR WARNING]: == ESPERA AUTOMÁTICA DE 5 SEGUNDOS ==
2025-06-12 15:03:56 - INFO - [SERVIDOR INFO]: Consultando datos de Incidencias...
2025-06-12 15:03:59 - INFO - package: mysql.connector.plugins
2025-06-12 15:03:59 - INFO - plugin_name: caching_sha2_password
2025-06-12 15:03:59 - INFO - AUTHENTICATION_PLUGIN_CLASS: MySQLCachingSHA2PasswordAuthPlugin
2025-06-12 15:04:02 - INFO - [SERVIDOR INFO]: ID de incidencia recibido: 5
2025-06-12 15:04:27 - INFO - [SERVIDOR INFO]: Fecha de solución recibida: 2025-06-18 07:17:09
2025-06-12 15:04:27 - INFO - [SERVIDOR INFO]: Incidencia 5 actualizada correctamente.
2025-06-12 15:14:34 - INFO - [SERVIDOR INFO]: Servidor escuchando en localhost:8083
2025-06-12 15:14:41 - INFO - [SERVIDOR INFO]: Conexión desde ('127.0.0.1', 58228)
2025-06-12 15:14:46 - WARNING - [SERVIDOR WARNING]: == ESPERA AUTOMÁTICA DE 5 SEGUNDOS ==
2025-06-12 15:15:18 - INFO - [SERVIDOR INFO]: Consultando datos de Incidencias...
2025-06-12 15:15:29 - INFO - package: mysql.connector.plugins
2025-06-12 15:15:29 - INFO - plugin_name: caching_sha2_password
2025-06-12 15:15:29 - INFO - AUTHENTICATION_PLUGIN_CLASS: MySQLCachingSHA2PasswordAuthPlugin
2025-06-12 15:15:39 - INFO - [SERVIDOR INFO]: ID de incidencia recibido: 4
2025-06-12 15:15:58 - INFO - [SERVIDOR INFO]: Fecha de solución recibida: 2025-07-12 09:00:03
2025-06-12 15:15:58 - INFO - [SERVIDOR INFO]: Incidencia 4 actualizada correctamente.
