2025-06-11 11:22:46 - ERROR - [SERVIDOR ERROR]: Error al iniciar el servidor: cannot access local variable 'server' where it is not associated with a value
2025-06-11 11:22:46 - CRITICAL - [SERVIDOR CRITICAL]: Servidor cerrado.
2025-06-11 11:23:09 - INFO - [SERVIDOR INFO]: Servidor escuchando en localhost:8083
2025-06-11 11:23:13 - INFO - [SERVIDOR INFO]: Conexión establecida desde ('127.0.0.1', 58155)
2025-06-11 11:23:14 - WARNING - [SERVIDOR WARNING]: == ESPERA AUTOMÁTICA DE O.1 SEGUNDOS ==
2025-06-11 11:23:55 - ERROR - Unhandled exception in client_connected_cb
transport: <_ProactorSocketTransport closed>
Traceback (most recent call last):
  File "C:\Program Files\WindowsApps\PythonSoftwareFoundation.Python.3.13_3.13.1008.0_x64__qbz5n2kfra8p0\Lib\asyncio\windows_events.py", line 463, in finish_socket_func
    return ov.getresult()
           ~~~~~~~~~~~~^^
OSError: [WinError 64] El nombre de red especificado ya no está disponible

During handling of the above exception, another exception occurred:

Traceback (most recent call last):
  File "c:\Users\nzjha\Desktop\Clon_Github\python_serve\Async\Server.py", line 210, in server
    data = await reader.readline()
           ^^^^^^^^^^^^^^^^^^^^^^^
  File "C:\Program Files\WindowsApps\PythonSoftwareFoundation.Python.3.13_3.13.1008.0_x64__qbz5n2kfra8p0\Lib\asyncio\streams.py", line 562, in readline
    line = await self.readuntil(sep)
           ^^^^^^^^^^^^^^^^^^^^^^^^^
  File "C:\Program Files\WindowsApps\PythonSoftwareFoundation.Python.3.13_3.13.1008.0_x64__qbz5n2kfra8p0\Lib\asyncio\streams.py", line 677, in readuntil
    await self._wait_for_data('readuntil')
  File "C:\Program Files\WindowsApps\PythonSoftwareFoundation.Python.3.13_3.13.1008.0_x64__qbz5n2kfra8p0\Lib\asyncio\streams.py", line 539, in _wait_for_data
    await self._waiter
  File "C:\Program Files\WindowsApps\PythonSoftwareFoundation.Python.3.13_3.13.1008.0_x64__qbz5n2kfra8p0\Lib\asyncio\proactor_events.py", line 286, in _loop_reading
    length = fut.result()
  File "C:\Program Files\WindowsApps\PythonSoftwareFoundation.Python.3.13_3.13.1008.0_x64__qbz5n2kfra8p0\Lib\asyncio\windows_events.py", line 804, in _poll
    value = callback(transferred, key, ov)
  File "C:\Program Files\WindowsApps\PythonSoftwareFoundation.Python.3.13_3.13.1008.0_x64__qbz5n2kfra8p0\Lib\asyncio\windows_events.py", line 467, in finish_socket_func
    raise ConnectionResetError(*exc.args)
ConnectionResetError: [WinError 64] El nombre de red especificado ya no está disponible
2025-06-11 11:24:10 - INFO - [SERVIDOR INFO]: Servidor escuchando en localhost:8083
2025-06-11 11:24:10 - INFO - [SERVIDOR INFO]: Conexión establecida desde ('127.0.0.1', 58172)
2025-06-11 11:24:16 - WARNING - [SERVIDOR WARNING]: == ESPERA AUTOMÁTICA DE 5 SEGUNDOS ==
2025-06-11 11:25:41 - INFO - [SERVIDOR INFO]: Servidor escuchando en localhost:8083
2025-06-11 11:25:42 - INFO - [SERVIDOR INFO]: Conexión establecida desde ('127.0.0.1', 58210)
2025-06-11 11:25:47 - WARNING - [SERVIDOR WARNING]: == ESPERA AUTOMÁTICA DE 5 SEGUNDOS ==
2025-06-11 11:27:48 - ERROR - Unhandled exception in client_connected_cb
transport: <_ProactorSocketTransport closed>
Traceback (most recent call last):
  File "C:\Program Files\WindowsApps\PythonSoftwareFoundation.Python.3.13_3.13.1008.0_x64__qbz5n2kfra8p0\Lib\asyncio\windows_events.py", line 463, in finish_socket_func
    return ov.getresult()
           ~~~~~~~~~~~~^^
OSError: [WinError 64] El nombre de red especificado ya no está disponible

During handling of the above exception, another exception occurred:

Traceback (most recent call last):
  File "c:\Users\nzjha\Desktop\Clon_Github\python_serve\Async\Server.py", line 210, in server
    message = (await reader.readline()).decode().strip()
               ^^^^^^^^^^^^^^^^^^^^^^^
  File "C:\Program Files\WindowsApps\PythonSoftwareFoundation.Python.3.13_3.13.1008.0_x64__qbz5n2kfra8p0\Lib\asyncio\streams.py", line 562, in readline
    line = await self.readuntil(sep)
           ^^^^^^^^^^^^^^^^^^^^^^^^^
  File "C:\Program Files\WindowsApps\PythonSoftwareFoundation.Python.3.13_3.13.1008.0_x64__qbz5n2kfra8p0\Lib\asyncio\streams.py", line 677, in readuntil
    await self._wait_for_data('readuntil')
  File "C:\Program Files\WindowsApps\PythonSoftwareFoundation.Python.3.13_3.13.1008.0_x64__qbz5n2kfra8p0\Lib\asyncio\streams.py", line 539, in _wait_for_data
    await self._waiter
  File "C:\Program Files\WindowsApps\PythonSoftwareFoundation.Python.3.13_3.13.1008.0_x64__qbz5n2kfra8p0\Lib\asyncio\proactor_events.py", line 286, in _loop_reading
    length = fut.result()
  File "C:\Program Files\WindowsApps\PythonSoftwareFoundation.Python.3.13_3.13.1008.0_x64__qbz5n2kfra8p0\Lib\asyncio\windows_events.py", line 804, in _poll
    value = callback(transferred, key, ov)
  File "C:\Program Files\WindowsApps\PythonSoftwareFoundation.Python.3.13_3.13.1008.0_x64__qbz5n2kfra8p0\Lib\asyncio\windows_events.py", line 467, in finish_socket_func
    raise ConnectionResetError(*exc.args)
ConnectionResetError: [WinError 64] El nombre de red especificado ya no está disponible
2025-06-11 11:30:41 - INFO - [SERVIDOR INFO]: Servidor escuchando en localhost:8083
2025-06-11 11:30:42 - INFO - [SERVIDOR INFO]: Conexión establecida desde ('127.0.0.1', 58293)
2025-06-11 11:30:47 - WARNING - [SERVIDOR WARNING]: == ESPERA AUTOMÁTICA DE 5 SEGUNDOS ==
2025-06-11 11:31:46 - ERROR - Unhandled exception in client_connected_cb
transport: <_ProactorSocketTransport closed>
Traceback (most recent call last):
  File "C:\Program Files\WindowsApps\PythonSoftwareFoundation.Python.3.13_3.13.1008.0_x64__qbz5n2kfra8p0\Lib\asyncio\windows_events.py", line 463, in finish_socket_func
    return ov.getresult()
           ~~~~~~~~~~~~^^
OSError: [WinError 64] El nombre de red especificado ya no está disponible

During handling of the above exception, another exception occurred:

Traceback (most recent call last):
  File "c:\Users\nzjha\Desktop\Clon_Github\python_serve\Async\Server.py", line 210, in server
    message = (await reader.readline()).decode().strip()
               ^^^^^^^^^^^^^^^^^^^^^^^
  File "C:\Program Files\WindowsApps\PythonSoftwareFoundation.Python.3.13_3.13.1008.0_x64__qbz5n2kfra8p0\Lib\asyncio\streams.py", line 562, in readline
    line = await self.readuntil(sep)
           ^^^^^^^^^^^^^^^^^^^^^^^^^
  File "C:\Program Files\WindowsApps\PythonSoftwareFoundation.Python.3.13_3.13.1008.0_x64__qbz5n2kfra8p0\Lib\asyncio\streams.py", line 677, in readuntil
    await self._wait_for_data('readuntil')
  File "C:\Program Files\WindowsApps\PythonSoftwareFoundation.Python.3.13_3.13.1008.0_x64__qbz5n2kfra8p0\Lib\asyncio\streams.py", line 539, in _wait_for_data
    await self._waiter
  File "C:\Program Files\WindowsApps\PythonSoftwareFoundation.Python.3.13_3.13.1008.0_x64__qbz5n2kfra8p0\Lib\asyncio\proactor_events.py", line 286, in _loop_reading
    length = fut.result()
  File "C:\Program Files\WindowsApps\PythonSoftwareFoundation.Python.3.13_3.13.1008.0_x64__qbz5n2kfra8p0\Lib\asyncio\windows_events.py", line 804, in _poll
    value = callback(transferred, key, ov)
  File "C:\Program Files\WindowsApps\PythonSoftwareFoundation.Python.3.13_3.13.1008.0_x64__qbz5n2kfra8p0\Lib\asyncio\windows_events.py", line 467, in finish_socket_func
    raise ConnectionResetError(*exc.args)
ConnectionResetError: [WinError 64] El nombre de red especificado ya no está disponible
2025-06-11 11:33:24 - INFO - [SERVIDOR INFO]: Servidor escuchando en localhost:8083
2025-06-11 11:33:32 - INFO - [SERVIDOR INFO]: Conexión establecida desde ('127.0.0.1', 58331)
2025-06-11 11:33:37 - WARNING - [SERVIDOR WARNING]: == ESPERA AUTOMÁTICA DE 5 SEGUNDOS ==
2025-06-11 11:34:32 - ERROR - Unhandled exception in client_connected_cb
transport: <_ProactorSocketTransport closed>
Traceback (most recent call last):
  File "C:\Program Files\WindowsApps\PythonSoftwareFoundation.Python.3.13_3.13.1008.0_x64__qbz5n2kfra8p0\Lib\asyncio\windows_events.py", line 463, in finish_socket_func
    return ov.getresult()
           ~~~~~~~~~~~~^^
OSError: [WinError 64] El nombre de red especificado ya no está disponible

During handling of the above exception, another exception occurred:

Traceback (most recent call last):
  File "c:\Users\nzjha\Desktop\Clon_Github\python_serve\Async\Server.py", line 210, in server
    message = (await reader.readline()).decode().strip()
               ^^^^^^^^^^^^^^^^^^^^^^^
  File "C:\Program Files\WindowsApps\PythonSoftwareFoundation.Python.3.13_3.13.1008.0_x64__qbz5n2kfra8p0\Lib\asyncio\streams.py", line 562, in readline
    line = await self.readuntil(sep)
           ^^^^^^^^^^^^^^^^^^^^^^^^^
  File "C:\Program Files\WindowsApps\PythonSoftwareFoundation.Python.3.13_3.13.1008.0_x64__qbz5n2kfra8p0\Lib\asyncio\streams.py", line 677, in readuntil
    await self._wait_for_data('readuntil')
  File "C:\Program Files\WindowsApps\PythonSoftwareFoundation.Python.3.13_3.13.1008.0_x64__qbz5n2kfra8p0\Lib\asyncio\streams.py", line 539, in _wait_for_data
    await self._waiter
  File "C:\Program Files\WindowsApps\PythonSoftwareFoundation.Python.3.13_3.13.1008.0_x64__qbz5n2kfra8p0\Lib\asyncio\proactor_events.py", line 286, in _loop_reading
    length = fut.result()
  File "C:\Program Files\WindowsApps\PythonSoftwareFoundation.Python.3.13_3.13.1008.0_x64__qbz5n2kfra8p0\Lib\asyncio\windows_events.py", line 804, in _poll
    value = callback(transferred, key, ov)
  File "C:\Program Files\WindowsApps\PythonSoftwareFoundation.Python.3.13_3.13.1008.0_x64__qbz5n2kfra8p0\Lib\asyncio\windows_events.py", line 467, in finish_socket_func
    raise ConnectionResetError(*exc.args)
ConnectionResetError: [WinError 64] El nombre de red especificado ya no está disponible
2025-06-11 11:35:15 - INFO - [SERVIDOR INFO]: Servidor escuchando en localhost:8083
2025-06-11 11:35:16 - INFO - [SERVIDOR INFO]: Conexión establecida desde ('127.0.0.1', 58360)
2025-06-11 11:35:51 - ERROR - Unhandled exception in client_connected_cb
transport: <_ProactorSocketTransport closed>
Traceback (most recent call last):
  File "C:\Program Files\WindowsApps\PythonSoftwareFoundation.Python.3.13_3.13.1008.0_x64__qbz5n2kfra8p0\Lib\asyncio\windows_events.py", line 463, in finish_socket_func
    return ov.getresult()
           ~~~~~~~~~~~~^^
OSError: [WinError 64] El nombre de red especificado ya no está disponible

During handling of the above exception, another exception occurred:

Traceback (most recent call last):
  File "c:\Users\nzjha\Desktop\Clon_Github\python_serve\Async\d.py", line 127, in server
    (await reader.readline())  # Espera ENTER
     ^^^^^^^^^^^^^^^^^^^^^^^
  File "C:\Program Files\WindowsApps\PythonSoftwareFoundation.Python.3.13_3.13.1008.0_x64__qbz5n2kfra8p0\Lib\asyncio\streams.py", line 562, in readline
    line = await self.readuntil(sep)
           ^^^^^^^^^^^^^^^^^^^^^^^^^
  File "C:\Program Files\WindowsApps\PythonSoftwareFoundation.Python.3.13_3.13.1008.0_x64__qbz5n2kfra8p0\Lib\asyncio\streams.py", line 677, in readuntil
    await self._wait_for_data('readuntil')
  File "C:\Program Files\WindowsApps\PythonSoftwareFoundation.Python.3.13_3.13.1008.0_x64__qbz5n2kfra8p0\Lib\asyncio\streams.py", line 539, in _wait_for_data
    await self._waiter
  File "C:\Program Files\WindowsApps\PythonSoftwareFoundation.Python.3.13_3.13.1008.0_x64__qbz5n2kfra8p0\Lib\asyncio\proactor_events.py", line 286, in _loop_reading
    length = fut.result()
  File "C:\Program Files\WindowsApps\PythonSoftwareFoundation.Python.3.13_3.13.1008.0_x64__qbz5n2kfra8p0\Lib\asyncio\windows_events.py", line 804, in _poll
    value = callback(transferred, key, ov)
  File "C:\Program Files\WindowsApps\PythonSoftwareFoundation.Python.3.13_3.13.1008.0_x64__qbz5n2kfra8p0\Lib\asyncio\windows_events.py", line 467, in finish_socket_func
    raise ConnectionResetError(*exc.args)
ConnectionResetError: [WinError 64] El nombre de red especificado ya no está disponible
2025-06-11 11:36:02 - INFO - [SERVIDOR INFO]: Servidor escuchando en localhost:8083
2025-06-11 11:36:12 - INFO - [SERVIDOR INFO]: Conexión establecida desde ('127.0.0.1', 58422)
2025-06-11 11:36:34 - ERROR - Unhandled exception in client_connected_cb
transport: <_ProactorSocketTransport closed>
Traceback (most recent call last):
  File "C:\Program Files\WindowsApps\PythonSoftwareFoundation.Python.3.13_3.13.1008.0_x64__qbz5n2kfra8p0\Lib\asyncio\windows_events.py", line 463, in finish_socket_func
    return ov.getresult()
           ~~~~~~~~~~~~^^
OSError: [WinError 64] El nombre de red especificado ya no está disponible

During handling of the above exception, another exception occurred:

Traceback (most recent call last):
  File "c:\Users\nzjha\Desktop\Clon_Github\python_serve\Async\d.py", line 127, in server
    (await reader.readline())  # Espera ENTER
     ^^^^^^^^^^^^^^^^^^^^^^^
  File "C:\Program Files\WindowsApps\PythonSoftwareFoundation.Python.3.13_3.13.1008.0_x64__qbz5n2kfra8p0\Lib\asyncio\streams.py", line 562, in readline
    line = await self.readuntil(sep)
           ^^^^^^^^^^^^^^^^^^^^^^^^^
  File "C:\Program Files\WindowsApps\PythonSoftwareFoundation.Python.3.13_3.13.1008.0_x64__qbz5n2kfra8p0\Lib\asyncio\streams.py", line 677, in readuntil
    await self._wait_for_data('readuntil')
  File "C:\Program Files\WindowsApps\PythonSoftwareFoundation.Python.3.13_3.13.1008.0_x64__qbz5n2kfra8p0\Lib\asyncio\streams.py", line 539, in _wait_for_data
    await self._waiter
  File "C:\Program Files\WindowsApps\PythonSoftwareFoundation.Python.3.13_3.13.1008.0_x64__qbz5n2kfra8p0\Lib\asyncio\proactor_events.py", line 286, in _loop_reading
    length = fut.result()
  File "C:\Program Files\WindowsApps\PythonSoftwareFoundation.Python.3.13_3.13.1008.0_x64__qbz5n2kfra8p0\Lib\asyncio\windows_events.py", line 804, in _poll
    value = callback(transferred, key, ov)
  File "C:\Program Files\WindowsApps\PythonSoftwareFoundation.Python.3.13_3.13.1008.0_x64__qbz5n2kfra8p0\Lib\asyncio\windows_events.py", line 467, in finish_socket_func
    raise ConnectionResetError(*exc.args)
ConnectionResetError: [WinError 64] El nombre de red especificado ya no está disponible
2025-06-11 11:36:54 - INFO - [SERVIDOR INFO]: Servidor escuchando en localhost:8083
2025-06-11 11:36:58 - INFO - [SERVIDOR INFO]: Conexión establecida desde ('127.0.0.1', 58437)
2025-06-11 11:38:17 - ERROR - Unhandled exception in client_connected_cb
transport: <_ProactorSocketTransport closed>
Traceback (most recent call last):
  File "C:\Program Files\WindowsApps\PythonSoftwareFoundation.Python.3.13_3.13.1008.0_x64__qbz5n2kfra8p0\Lib\asyncio\windows_events.py", line 463, in finish_socket_func
    return ov.getresult()
           ~~~~~~~~~~~~^^
OSError: [WinError 64] El nombre de red especificado ya no está disponible

During handling of the above exception, another exception occurred:

Traceback (most recent call last):
  File "c:\Users\nzjha\Desktop\Clon_Github\python_serve\Async\d.py", line 133, in server
    message = (await reader.readline()).decode().strip()
               ^^^^^^^^^^^^^^^^^^^^^^^
  File "C:\Program Files\WindowsApps\PythonSoftwareFoundation.Python.3.13_3.13.1008.0_x64__qbz5n2kfra8p0\Lib\asyncio\streams.py", line 562, in readline
    line = await self.readuntil(sep)
           ^^^^^^^^^^^^^^^^^^^^^^^^^
  File "C:\Program Files\WindowsApps\PythonSoftwareFoundation.Python.3.13_3.13.1008.0_x64__qbz5n2kfra8p0\Lib\asyncio\streams.py", line 677, in readuntil
    await self._wait_for_data('readuntil')
  File "C:\Program Files\WindowsApps\PythonSoftwareFoundation.Python.3.13_3.13.1008.0_x64__qbz5n2kfra8p0\Lib\asyncio\streams.py", line 539, in _wait_for_data
    await self._waiter
  File "C:\Program Files\WindowsApps\PythonSoftwareFoundation.Python.3.13_3.13.1008.0_x64__qbz5n2kfra8p0\Lib\asyncio\proactor_events.py", line 286, in _loop_reading
    length = fut.result()
  File "C:\Program Files\WindowsApps\PythonSoftwareFoundation.Python.3.13_3.13.1008.0_x64__qbz5n2kfra8p0\Lib\asyncio\windows_events.py", line 804, in _poll
    value = callback(transferred, key, ov)
  File "C:\Program Files\WindowsApps\PythonSoftwareFoundation.Python.3.13_3.13.1008.0_x64__qbz5n2kfra8p0\Lib\asyncio\windows_events.py", line 467, in finish_socket_func
    raise ConnectionResetError(*exc.args)
ConnectionResetError: [WinError 64] El nombre de red especificado ya no está disponible
2025-06-11 11:38:21 - INFO - [SERVIDOR INFO]: Conexión establecida desde ('127.0.0.1', 58459)
2025-06-11 11:38:25 - INFO - [SERVIDOR INFO]: Servidor escuchando en localhost:8083
2025-06-11 11:38:26 - INFO - [SERVIDOR INFO]: Conexión establecida desde ('127.0.0.1', 58463)
2025-06-11 11:38:43 - ERROR - Unhandled exception in client_connected_cb
transport: <_ProactorSocketTransport closed>
Traceback (most recent call last):
  File "C:\Program Files\WindowsApps\PythonSoftwareFoundation.Python.3.13_3.13.1008.0_x64__qbz5n2kfra8p0\Lib\asyncio\windows_events.py", line 463, in finish_socket_func
    return ov.getresult()
           ~~~~~~~~~~~~^^
OSError: [WinError 64] El nombre de red especificado ya no está disponible

During handling of the above exception, another exception occurred:

Traceback (most recent call last):
  File "c:\Users\nzjha\Desktop\Clon_Github\python_serve\Async\d.py", line 133, in server
    message = (await reader.readline()).decode().strip()
               ^^^^^^^^^^^^^^^^^^^^^^^
  File "C:\Program Files\WindowsApps\PythonSoftwareFoundation.Python.3.13_3.13.1008.0_x64__qbz5n2kfra8p0\Lib\asyncio\streams.py", line 562, in readline
    line = await self.readuntil(sep)
           ^^^^^^^^^^^^^^^^^^^^^^^^^
  File "C:\Program Files\WindowsApps\PythonSoftwareFoundation.Python.3.13_3.13.1008.0_x64__qbz5n2kfra8p0\Lib\asyncio\streams.py", line 677, in readuntil
    await self._wait_for_data('readuntil')
  File "C:\Program Files\WindowsApps\PythonSoftwareFoundation.Python.3.13_3.13.1008.0_x64__qbz5n2kfra8p0\Lib\asyncio\streams.py", line 539, in _wait_for_data
    await self._waiter
  File "C:\Program Files\WindowsApps\PythonSoftwareFoundation.Python.3.13_3.13.1008.0_x64__qbz5n2kfra8p0\Lib\asyncio\proactor_events.py", line 286, in _loop_reading
    length = fut.result()
  File "C:\Program Files\WindowsApps\PythonSoftwareFoundation.Python.3.13_3.13.1008.0_x64__qbz5n2kfra8p0\Lib\asyncio\windows_events.py", line 804, in _poll
    value = callback(transferred, key, ov)
  File "C:\Program Files\WindowsApps\PythonSoftwareFoundation.Python.3.13_3.13.1008.0_x64__qbz5n2kfra8p0\Lib\asyncio\windows_events.py", line 467, in finish_socket_func
    raise ConnectionResetError(*exc.args)
ConnectionResetError: [WinError 64] El nombre de red especificado ya no está disponible
2025-06-11 11:51:06 - INFO - [SERVIDOR INFO]: Servidor escuchando en localhost:8083
2025-06-11 11:51:11 - INFO - [SERVIDOR INFO]: Conexión desde ('127.0.0.1', 58694)
2025-06-11 11:51:16 - WARNING - [SERVIDOR WARNING]: == ESPERA AUTOMÁTICA DE 5 SEGUNDOS ==
2025-06-11 11:51:20 - INFO - [SERVIDOR INFO]: Consultando datos de teleoperador...
2025-06-11 11:51:20 - ERROR - Unhandled exception in client_connected_cb
transport: <_ProactorSocketTransport fd=1088 read=<_OverlappedFuture pending cb=[_ProactorReadPipeTransport._loop_reading()]>>
Traceback (most recent call last):
  File "c:\Users\nzjha\Desktop\Clon_Github\python_serve\Async\sv.py", line 170, in server_on
    await teleoperador_MySQL(writer, reader)
  File "c:\Users\nzjha\Desktop\Clon_Github\python_serve\Async\sv.py", line 100, in teleoperador_MySQL
    writer("Has seleccionado la opción de TELEOPERADOR con MySQL. Selecciona la consulta que quieras hacer: "\
    ~~~~~~^^^^^^^^^^^^^^^^^^^^^^^^^^^^^^^^^^^^^^^^^^^^^^^^^^^^^^^^^^^^^^^^^^^^^^^^^^^^^^^^^^^^^^^^^^^^^^^^^^^^
    "\n"\
    ^^^^^
    ...<2 lines>...
    "3. Eliminar un teleoperador \n"\
    ^^^^^^^^^^^^^^^^^^^^^^^^^^^^^^^^^
    "4. Consultar teleoperadores y sus horarios \n".encode())
    ^^^^^^^^^^^^^^^^^^^^^^^^^^^^^^^^^^^^^^^^^^^^^^^^^^^^^^^^^
TypeError: 'StreamWriter' object is not callable
2025-06-11 11:53:13 - INFO - [SERVIDOR INFO]: Servidor escuchando en localhost:8083
2025-06-11 11:53:16 - INFO - [SERVIDOR INFO]: Conexión desde ('127.0.0.1', 58746)
2025-06-11 11:53:21 - WARNING - [SERVIDOR WARNING]: == ESPERA AUTOMÁTICA DE 5 SEGUNDOS ==
2025-06-11 11:53:23 - INFO - [SERVIDOR INFO]: Consultando datos de teleoperador...
2025-06-11 11:53:23 - ERROR - Unhandled exception in client_connected_cb
transport: <_ProactorSocketTransport fd=1088 read=<_OverlappedFuture pending cb=[_ProactorReadPipeTransport._loop_reading()]>>
Traceback (most recent call last):
  File "c:\Users\nzjha\Desktop\Clon_Github\python_serve\Async\sv.py", line 171, in server_on
    await teleoperador_MySQL(writer, reader)
  File "c:\Users\nzjha\Desktop\Clon_Github\python_serve\Async\sv.py", line 106, in teleoperador_MySQL
    writer.write(menu.endcode())
                 ^^^^^^^^^^^^
AttributeError: 'bytes' object has no attribute 'endcode'
2025-06-11 11:54:35 - INFO - [SERVIDOR INFO]: Servidor escuchando en localhost:8083
2025-06-11 11:54:36 - INFO - [SERVIDOR INFO]: Conexión desde ('127.0.0.1', 58776)
2025-06-11 11:54:41 - WARNING - [SERVIDOR WARNING]: == ESPERA AUTOMÁTICA DE 5 SEGUNDOS ==
2025-06-11 11:54:44 - INFO - [SERVIDOR INFO]: Consultando datos de teleoperador...
2025-06-11 11:54:47 - INFO - package: mysql.connector.plugins
2025-06-11 11:54:47 - INFO - plugin_name: caching_sha2_password
2025-06-11 11:54:47 - INFO - AUTHENTICATION_PLUGIN_CLASS: MySQLCachingSHA2PasswordAuthPlugin
2025-06-11 11:55:13 - INFO - [SERVIDOR INFO]: Nombre recibido: Rina
2025-06-11 11:55:20 - INFO - [SERVIDOR INFO]: Apellido recibido: Psicopata
2025-06-11 11:55:24 - INFO - [SERVIDOR INFO]: Telefono recibido: 09876545678932
2025-06-11 11:55:31 - INFO - [SERVIDOR INFO]: Email recibido: rina@zzz.com
2025-06-11 11:55:41 - ERROR - Unhandled exception in client_connected_cb
transport: <_ProactorSocketTransport closed>
Traceback (most recent call last):
  File "C:\Program Files\WindowsApps\PythonSoftwareFoundation.Python.3.13_3.13.1008.0_x64__qbz5n2kfra8p0\Lib\asyncio\windows_events.py", line 463, in finish_socket_func
    return ov.getresult()
           ~~~~~~~~~~~~^^
OSError: [WinError 64] El nombre de red especificado ya no está disponible

During handling of the above exception, another exception occurred:

Traceback (most recent call last):
  File "c:\Users\nzjha\Desktop\Clon_Github\python_serve\Async\sv.py", line 171, in server_on
    await teleoperador_MySQL(writer, reader)
  File "c:\Users\nzjha\Desktop\Clon_Github\python_serve\Async\sv.py", line 112, in teleoperador_MySQL
    await add_teleoperador(writer, reader)
  File "c:\Users\nzjha\Desktop\Clon_Github\python_serve\Async\sv.py", line 73, in add_teleoperador
    ub_id = (await reader.read(1024)).decode().strip()
             ^^^^^^^^^^^^^^^^^^^^^^^
  File "C:\Program Files\WindowsApps\PythonSoftwareFoundation.Python.3.13_3.13.1008.0_x64__qbz5n2kfra8p0\Lib\asyncio\streams.py", line 730, in read
    await self._wait_for_data('read')
  File "C:\Program Files\WindowsApps\PythonSoftwareFoundation.Python.3.13_3.13.1008.0_x64__qbz5n2kfra8p0\Lib\asyncio\streams.py", line 539, in _wait_for_data
    await self._waiter
  File "C:\Program Files\WindowsApps\PythonSoftwareFoundation.Python.3.13_3.13.1008.0_x64__qbz5n2kfra8p0\Lib\asyncio\proactor_events.py", line 286, in _loop_reading
    length = fut.result()
  File "C:\Program Files\WindowsApps\PythonSoftwareFoundation.Python.3.13_3.13.1008.0_x64__qbz5n2kfra8p0\Lib\asyncio\windows_events.py", line 804, in _poll
    value = callback(transferred, key, ov)
  File "C:\Program Files\WindowsApps\PythonSoftwareFoundation.Python.3.13_3.13.1008.0_x64__qbz5n2kfra8p0\Lib\asyncio\windows_events.py", line 467, in finish_socket_func
    raise ConnectionResetError(*exc.args)
ConnectionResetError: [WinError 64] El nombre de red especificado ya no está disponible
2025-06-11 12:00:17 - INFO - [SERVIDOR INFO]: Servidor escuchando en localhost:8083
2025-06-11 12:00:17 - INFO - [SERVIDOR INFO]: Conexión desde ('127.0.0.1', 58906)
2025-06-11 12:00:22 - WARNING - [SERVIDOR WARNING]: == ESPERA AUTOMÁTICA DE 5 SEGUNDOS ==
2025-06-11 12:00:36 - INFO - [SERVIDOR INFO]: Consultando datos de teleoperador...
2025-06-11 12:00:41 - INFO - package: mysql.connector.plugins
2025-06-11 12:00:41 - INFO - plugin_name: caching_sha2_password
2025-06-11 12:00:41 - INFO - AUTHENTICATION_PLUGIN_CLASS: MySQLCachingSHA2PasswordAuthPlugin
2025-06-11 12:00:44 - INFO - [SERVIDOR INFO]: Nombre recibido: Ei
2025-06-11 12:00:52 - INFO - [SERVIDOR INFO]: Apellido recibido: Eternidad
2025-06-11 12:00:57 - INFO - [SERVIDOR INFO]: Telefono recibido: 764796707898
2025-06-11 12:01:06 - INFO - [SERVIDOR INFO]: Email recibido: ei@inazuma.com
2025-06-11 12:01:13 - INFO - [SERVIDOR INFO]: Ubicacion recibida: 17
2025-06-11 12:01:14 - INFO - [SERVIDOR INFO]: Teleoperador Ei Eternidad insertado correctamente en la base de datos.
2025-06-11 12:01:23 - ERROR - Unhandled exception in client_connected_cb
transport: <_ProactorSocketTransport closed>
Traceback (most recent call last):
  File "C:\Program Files\WindowsApps\PythonSoftwareFoundation.Python.3.13_3.13.1008.0_x64__qbz5n2kfra8p0\Lib\asyncio\windows_events.py", line 463, in finish_socket_func
    return ov.getresult()
           ~~~~~~~~~~~~^^
OSError: [WinError 64] El nombre de red especificado ya no está disponible

During handling of the above exception, another exception occurred:

Traceback (most recent call last):
  File "c:\Users\nzjha\Desktop\Clon_Github\python_serve\Async\sv.py", line 171, in server_on
    await teleoperador_MySQL(writer, reader)
  File "c:\Users\nzjha\Desktop\Clon_Github\python_serve\Async\sv.py", line 112, in teleoperador_MySQL
    await add_teleoperador(writer, reader)
  File "c:\Users\nzjha\Desktop\Clon_Github\python_serve\Async\sv.py", line 44, in add_teleoperador
    nombre = (await reader.read(1024)).decode().strip()
              ^^^^^^^^^^^^^^^^^^^^^^^
  File "C:\Program Files\WindowsApps\PythonSoftwareFoundation.Python.3.13_3.13.1008.0_x64__qbz5n2kfra8p0\Lib\asyncio\streams.py", line 730, in read
    await self._wait_for_data('read')
  File "C:\Program Files\WindowsApps\PythonSoftwareFoundation.Python.3.13_3.13.1008.0_x64__qbz5n2kfra8p0\Lib\asyncio\streams.py", line 539, in _wait_for_data
    await self._waiter
  File "C:\Program Files\WindowsApps\PythonSoftwareFoundation.Python.3.13_3.13.1008.0_x64__qbz5n2kfra8p0\Lib\asyncio\proactor_events.py", line 286, in _loop_reading
    length = fut.result()
  File "C:\Program Files\WindowsApps\PythonSoftwareFoundation.Python.3.13_3.13.1008.0_x64__qbz5n2kfra8p0\Lib\asyncio\windows_events.py", line 804, in _poll
    value = callback(transferred, key, ov)
  File "C:\Program Files\WindowsApps\PythonSoftwareFoundation.Python.3.13_3.13.1008.0_x64__qbz5n2kfra8p0\Lib\asyncio\windows_events.py", line 467, in finish_socket_func
    raise ConnectionResetError(*exc.args)
ConnectionResetError: [WinError 64] El nombre de red especificado ya no está disponible
2025-06-11 12:05:28 - INFO - [SERVIDOR INFO]: Servidor escuchando en localhost:8083
2025-06-11 12:05:28 - INFO - [SERVIDOR INFO]: Conexión desde ('127.0.0.1', 58979)
2025-06-11 12:05:33 - WARNING - [SERVIDOR WARNING]: == ESPERA AUTOMÁTICA DE 5 SEGUNDOS ==
2025-06-11 12:05:37 - INFO - [SERVIDOR INFO]: Consultando datos de teleoperador...
2025-06-11 12:05:40 - INFO - package: mysql.connector.plugins
2025-06-11 12:05:40 - INFO - plugin_name: caching_sha2_password
2025-06-11 12:05:40 - INFO - AUTHENTICATION_PLUGIN_CLASS: MySQLCachingSHA2PasswordAuthPlugin
2025-06-11 12:05:45 - INFO - [SERVIDOR INFO]: Nombre recibido: Kiara
2025-06-11 12:05:48 - INFO - [SERVIDOR INFO]: Apellido recibido: Gata
2025-06-11 12:05:51 - INFO - [SERVIDOR INFO]: Telefono recibido: 3123nya
2025-06-11 12:06:00 - INFO - [SERVIDOR INFO]: Email recibido: nya@inazuma.com
2025-06-11 12:06:04 - INFO - [SERVIDOR INFO]: Ubicacion recibida: 17
2025-06-11 12:06:04 - INFO - [SERVIDOR INFO]: Teleoperador Kiara Gata insertado correctamente en la base de datos.
2025-06-11 12:07:33 - INFO - [SERVIDOR INFO]: Servidor escuchando en localhost:8083
2025-06-11 12:07:33 - INFO - [SERVIDOR INFO]: Conexión desde ('127.0.0.1', 59046)
2025-06-11 12:07:38 - WARNING - [SERVIDOR WARNING]: == ESPERA AUTOMÁTICA DE 5 SEGUNDOS ==
2025-06-11 12:07:46 - INFO - [SERVIDOR INFO]: Consultando datos de teleoperador...
2025-06-11 12:07:48 - INFO - package: mysql.connector.plugins
2025-06-11 12:07:48 - INFO - plugin_name: caching_sha2_password
2025-06-11 12:07:48 - INFO - AUTHENTICATION_PLUGIN_CLASS: MySQLCachingSHA2PasswordAuthPlugin
2025-06-11 12:08:26 - INFO - [SERVIDOR INFO]: Nombre recibido: No se
2025-06-11 12:08:29 - INFO - [SERVIDOR INFO]: Apellido recibido: Ni idea
2025-06-11 12:08:34 - INFO - [SERVIDOR INFO]: Telefono recibido: Niideadadi9732
2025-06-11 12:08:41 - INFO - [SERVIDOR INFO]: Email recibido: ni@idea.com
2025-06-11 12:09:15 - ERROR - Unhandled exception in client_connected_cb
transport: <_ProactorSocketTransport closed>
Traceback (most recent call last):
  File "C:\Program Files\WindowsApps\PythonSoftwareFoundation.Python.3.13_3.13.1008.0_x64__qbz5n2kfra8p0\Lib\asyncio\windows_events.py", line 463, in finish_socket_func
    return ov.getresult()
           ~~~~~~~~~~~~^^
OSError: [WinError 64] El nombre de red especificado ya no está disponible

During handling of the above exception, another exception occurred:

Traceback (most recent call last):
  File "c:\Users\nzjha\Desktop\Clon_Github\python_serve\Async\sv.py", line 171, in server_on
    await teleoperador_MySQL(writer, reader)
  File "c:\Users\nzjha\Desktop\Clon_Github\python_serve\Async\sv.py", line 112, in teleoperador_MySQL
    await add_teleoperador(writer, reader)
  File "c:\Users\nzjha\Desktop\Clon_Github\python_serve\Async\sv.py", line 73, in add_teleoperador
    ub_id = (await reader.read(1024)).decode().strip()
             ^^^^^^^^^^^^^^^^^^^^^^^
  File "C:\Program Files\WindowsApps\PythonSoftwareFoundation.Python.3.13_3.13.1008.0_x64__qbz5n2kfra8p0\Lib\asyncio\streams.py", line 730, in read
    await self._wait_for_data('read')
  File "C:\Program Files\WindowsApps\PythonSoftwareFoundation.Python.3.13_3.13.1008.0_x64__qbz5n2kfra8p0\Lib\asyncio\streams.py", line 539, in _wait_for_data
    await self._waiter
  File "C:\Program Files\WindowsApps\PythonSoftwareFoundation.Python.3.13_3.13.1008.0_x64__qbz5n2kfra8p0\Lib\asyncio\proactor_events.py", line 286, in _loop_reading
    length = fut.result()
  File "C:\Program Files\WindowsApps\PythonSoftwareFoundation.Python.3.13_3.13.1008.0_x64__qbz5n2kfra8p0\Lib\asyncio\windows_events.py", line 804, in _poll
    value = callback(transferred, key, ov)
  File "C:\Program Files\WindowsApps\PythonSoftwareFoundation.Python.3.13_3.13.1008.0_x64__qbz5n2kfra8p0\Lib\asyncio\windows_events.py", line 467, in finish_socket_func
    raise ConnectionResetError(*exc.args)
ConnectionResetError: [WinError 64] El nombre de red especificado ya no está disponible
2025-06-11 12:26:18 - INFO - [SERVIDOR INFO]: Servidor escuchando en localhost:8083
2025-06-11 12:26:18 - INFO - [SERVIDOR INFO]: Conexión desde ('127.0.0.1', 59374)
2025-06-11 12:26:24 - WARNING - [SERVIDOR WARNING]: == ESPERA AUTOMÁTICA DE 5 SEGUNDOS ==
2025-06-11 12:26:26 - INFO - [SERVIDOR INFO]: Consultando datos de teleoperador...
2025-06-11 12:26:29 - INFO - package: mysql.connector.plugins
2025-06-11 12:26:29 - INFO - plugin_name: caching_sha2_password
2025-06-11 12:26:29 - INFO - AUTHENTICATION_PLUGIN_CLASS: MySQLCachingSHA2PasswordAuthPlugin
2025-06-11 12:26:31 - INFO - [SERVIDOR INFO]: Nombre recibido: l
2025-06-11 12:26:32 - INFO - [SERVIDOR INFO]: Apellido recibido: L
2025-06-11 12:26:32 - INFO - [SERVIDOR INFO]: Telefono recibido: L
2025-06-11 12:26:34 - INFO - [SERVIDOR INFO]: Email recibido: l
2025-06-11 12:26:40 - INFO - [SERVIDOR INFO]: Ubicacion recibida: 7
2025-06-11 12:26:40 - INFO - [SERVIDOR INFO]: Teleoperador l L insertado correctamente en la base de datos.
2025-06-11 12:48:25 - INFO - [SERVIDOR INFO]: Servidor escuchando en localhost:8083
2025-06-11 12:48:30 - INFO - [SERVIDOR INFO]: Conexión desde ('127.0.0.1', 59898)
2025-06-11 12:48:35 - WARNING - [SERVIDOR WARNING]: == ESPERA AUTOMÁTICA DE 5 SEGUNDOS ==
2025-06-11 12:48:38 - INFO - [SERVIDOR INFO]: Consultando datos de teleoperador...
2025-06-11 12:48:43 - INFO - package: mysql.connector.plugins
2025-06-11 12:48:43 - INFO - plugin_name: caching_sha2_password
2025-06-11 12:48:43 - INFO - AUTHENTICATION_PLUGIN_CLASS: MySQLCachingSHA2PasswordAuthPlugin
2025-06-11 12:48:59 - INFO - [SERVIDOR INFO]: Teleoperador recibido: 6
2025-06-11 12:49:15 - INFO - [SERVIDOR INFO]: Semana recibida: semana 5 de septiembre
2025-06-11 12:49:34 - INFO - [SERVIDOR INFO]: Inicio de jornada recibido: 05:00:00
2025-06-11 12:49:43 - INFO - [SERVIDOR INFO]: Fin de jornada recibido: 13:00:00
2025-06-11 12:49:43 - ERROR - Unhandled exception in client_connected_cb
transport: <_ProactorSocketTransport fd=1092 read=<_OverlappedFuture pending cb=[_ProactorReadPipeTransport._loop_reading()]>>
Traceback (most recent call last):
  File "c:\Users\nzjha\Desktop\Clon_Github\python_serve\Async\sv.py", line 238, in server_on
    await teleoperador_MySQL(writer, reader)
  File "c:\Users\nzjha\Desktop\Clon_Github\python_serve\Async\sv.py", line 182, in teleoperador_MySQL
    await add_horario_teleoperador(writer, reader)
  File "c:\Users\nzjha\Desktop\Clon_Github\python_serve\Async\sv.py", line 83, in add_horario_teleoperador
    crs.execute(query, values)
    ~~~~~~~~~~~^^^^^^^^^^^^^^^
  File "C:\Users\nzjha\AppData\Local\Packages\PythonSoftwareFoundation.Python.3.13_qbz5n2kfra8p0\LocalCache\local-packages\Python313\site-packages\mysql\connector\cursor.py", line 418, in execute
    self._connection.cmd_query(
    ~~~~~~~~~~~~~~~~~~~~~~~~~~^
        self._stmt_partition["mappable_stmt"],
        ^^^^^^^^^^^^^^^^^^^^^^^^^^^^^^^^^^^^^^
        read_timeout=self._read_timeout,
        ^^^^^^^^^^^^^^^^^^^^^^^^^^^^^^^^
        write_timeout=self._write_timeout,
        ^^^^^^^^^^^^^^^^^^^^^^^^^^^^^^^^^^
    )
    ^
  File "C:\Users\nzjha\AppData\Local\Packages\PythonSoftwareFoundation.Python.3.13_qbz5n2kfra8p0\LocalCache\local-packages\Python313\site-packages\mysql\connector\opentelemetry\context_propagation.py", line 97, in wrapper
    return method(cnx, *args, **kwargs)
  File "C:\Users\nzjha\AppData\Local\Packages\PythonSoftwareFoundation.Python.3.13_qbz5n2kfra8p0\LocalCache\local-packages\Python313\site-packages\mysql\connector\_decorating.py", line 89, in handle_cnx_method
    raise err
  File "C:\Users\nzjha\AppData\Local\Packages\PythonSoftwareFoundation.Python.3.13_qbz5n2kfra8p0\LocalCache\local-packages\Python313\site-packages\mysql\connector\_decorating.py", line 85, in handle_cnx_method
    return cnx_method(cnx, *args, **kwargs)
  File "C:\Users\nzjha\AppData\Local\Packages\PythonSoftwareFoundation.Python.3.13_qbz5n2kfra8p0\LocalCache\local-packages\Python313\site-packages\mysql\connector\connection.py", line 984, in cmd_query
    result = self._handle_result(
        self._send_cmd(
    ...<6 lines>...
        write_timeout,
    )
  File "C:\Users\nzjha\AppData\Local\Packages\PythonSoftwareFoundation.Python.3.13_qbz5n2kfra8p0\LocalCache\local-packages\Python313\site-packages\mysql\connector\_decorating.py", line 89, in handle_cnx_method
    raise err
  File "C:\Users\nzjha\AppData\Local\Packages\PythonSoftwareFoundation.Python.3.13_qbz5n2kfra8p0\LocalCache\local-packages\Python313\site-packages\mysql\connector\_decorating.py", line 85, in handle_cnx_method
    return cnx_method(cnx, *args, **kwargs)
  File "C:\Users\nzjha\AppData\Local\Packages\PythonSoftwareFoundation.Python.3.13_qbz5n2kfra8p0\LocalCache\local-packages\Python313\site-packages\mysql\connector\connection.py", line 745, in _handle_result
    raise get_exception(packet)
mysql.connector.errors.ProgrammingError: 1054 (42S22): Unknown column 'inicio_jornada' in 'field list'
2025-06-11 12:53:10 - INFO - [SERVIDOR INFO]: Servidor escuchando en localhost:8083
2025-06-11 12:53:10 - INFO - [SERVIDOR INFO]: Conexión desde ('127.0.0.1', 60008)
2025-06-11 12:53:15 - WARNING - [SERVIDOR WARNING]: == ESPERA AUTOMÁTICA DE 5 SEGUNDOS ==
2025-06-11 12:53:19 - INFO - [SERVIDOR INFO]: Consultando datos de teleoperador...
2025-06-11 12:53:26 - INFO - package: mysql.connector.plugins
2025-06-11 12:53:26 - INFO - plugin_name: caching_sha2_password
2025-06-11 12:53:26 - INFO - AUTHENTICATION_PLUGIN_CLASS: MySQLCachingSHA2PasswordAuthPlugin
2025-06-11 12:53:38 - INFO - [SERVIDOR INFO]: Teleoperador recibido: 3
2025-06-11 12:53:49 - INFO - [SERVIDOR INFO]: Semana recibida: Semana 5 de septiembre
2025-06-11 12:53:57 - INFO - [SERVIDOR INFO]: Inicio de jornada recibido: 09:30:00
2025-06-11 12:54:07 - INFO - [SERVIDOR INFO]: Fin de jornada recibido: 17:30:00
2025-06-11 12:54:07 - ERROR - Unhandled exception in client_connected_cb
transport: <_ProactorSocketTransport fd=1088 read=<_OverlappedFuture pending cb=[_ProactorReadPipeTransport._loop_reading()]>>
Traceback (most recent call last):
  File "c:\Users\nzjha\Desktop\Clon_Github\python_serve\Async\sv.py", line 241, in server_on
    await teleoperador_MySQL(writer, reader)
  File "c:\Users\nzjha\Desktop\Clon_Github\python_serve\Async\sv.py", line 185, in teleoperador_MySQL
    await add_horario_teleoperador(writer, reader)
  File "c:\Users\nzjha\Desktop\Clon_Github\python_serve\Async\sv.py", line 83, in add_horario_teleoperador
    crs.execute(query, values)
    ~~~~~~~~~~~^^^^^^^^^^^^^^^
  File "C:\Users\nzjha\AppData\Local\Packages\PythonSoftwareFoundation.Python.3.13_qbz5n2kfra8p0\LocalCache\local-packages\Python313\site-packages\mysql\connector\cursor.py", line 418, in execute
    self._connection.cmd_query(
    ~~~~~~~~~~~~~~~~~~~~~~~~~~^
        self._stmt_partition["mappable_stmt"],
        ^^^^^^^^^^^^^^^^^^^^^^^^^^^^^^^^^^^^^^
        read_timeout=self._read_timeout,
        ^^^^^^^^^^^^^^^^^^^^^^^^^^^^^^^^
        write_timeout=self._write_timeout,
        ^^^^^^^^^^^^^^^^^^^^^^^^^^^^^^^^^^
    )
    ^
  File "C:\Users\nzjha\AppData\Local\Packages\PythonSoftwareFoundation.Python.3.13_qbz5n2kfra8p0\LocalCache\local-packages\Python313\site-packages\mysql\connector\opentelemetry\context_propagation.py", line 97, in wrapper
    return method(cnx, *args, **kwargs)
  File "C:\Users\nzjha\AppData\Local\Packages\PythonSoftwareFoundation.Python.3.13_qbz5n2kfra8p0\LocalCache\local-packages\Python313\site-packages\mysql\connector\_decorating.py", line 89, in handle_cnx_method
    raise err
  File "C:\Users\nzjha\AppData\Local\Packages\PythonSoftwareFoundation.Python.3.13_qbz5n2kfra8p0\LocalCache\local-packages\Python313\site-packages\mysql\connector\_decorating.py", line 85, in handle_cnx_method
    return cnx_method(cnx, *args, **kwargs)
  File "C:\Users\nzjha\AppData\Local\Packages\PythonSoftwareFoundation.Python.3.13_qbz5n2kfra8p0\LocalCache\local-packages\Python313\site-packages\mysql\connector\connection.py", line 984, in cmd_query
    result = self._handle_result(
        self._send_cmd(
    ...<6 lines>...
        write_timeout,
    )
  File "C:\Users\nzjha\AppData\Local\Packages\PythonSoftwareFoundation.Python.3.13_qbz5n2kfra8p0\LocalCache\local-packages\Python313\site-packages\mysql\connector\_decorating.py", line 89, in handle_cnx_method
    raise err
  File "C:\Users\nzjha\AppData\Local\Packages\PythonSoftwareFoundation.Python.3.13_qbz5n2kfra8p0\LocalCache\local-packages\Python313\site-packages\mysql\connector\_decorating.py", line 85, in handle_cnx_method
    return cnx_method(cnx, *args, **kwargs)
  File "C:\Users\nzjha\AppData\Local\Packages\PythonSoftwareFoundation.Python.3.13_qbz5n2kfra8p0\LocalCache\local-packages\Python313\site-packages\mysql\connector\connection.py", line 745, in _handle_result
    raise get_exception(packet)
mysql.connector.errors.ProgrammingError: 1054 (42S22): Unknown column 'inicio_jornada' in 'field list'
